Workbook

Sheet 00_Паспорт
A1: Symbiosis V7 — реестр предметов для Windows-приложения
A2: Версия 1.6 · актуализировано 2026-08-01 · Rules v1.7 | Character-Skills-Symbionts v1.2 | Items v1.6_with_icons | Bestiary v1.4 | Sentient v1.2 · исходные каталоги, баланс, формулы и 64 иконки не изменены; синхронизированы только границы группового генератора.
A4: Контрольный показатель | B4: Значение | D4: Нормативная модель выдачи готового предмета
A5: Канонические предметы (A) | B5: 49 | D5: 1 | E5: Игрок выбирает оружие только при создании собственного персонажа. | F5: Не-Чистое оружие: редактируются только формульно выводимые поля; оружие Чистых отображается только для чтения.
A6: Явные предметные сущности (B) | B6: 15 | D6: 2 | E6: Приложение не бросает производственные дайсы и не создаёт предмет. | F6: Валидатор ищет единый witness по L/Lw/Ls и независимым дайсам для всего заявленного профиля.
A7: Всего строк основного каталога | B7: 64 | D7: 3 | E7: Успешная заявка создаёт неизменяемую WeaponProfileVersion. | F7: Сохраняются formulaId, formulaVersion и validationWitness; statSource=PLAYER_FORMULA_VALIDATED.
A8: Оружие/щиты/комплекты | B8: 27 | D8: 4 | E8: Мастер выдаёт или изменяет конкретный экземпляр оружия игрока либо НПС. | F8: Разрешено всё оружие, включая шесть шаблонов Чистых; глобальный шаблон и другие экземпляры не меняются.
A9: Броня | B9: 8 | D9: 5 | E9: MASTER_OVERRIDE обходит формульную область, но не структурную валидацию. | F9: Закрытая грамматика дайсов, положительность значений, actor/reason/time и неизменяемые before/after обязательны.
A10: Фармацевтика | B10: 14 | D10: 6 | E10: Изменение профиля атомарно и версионируется. | F10: Новая версия действует со следующей отдельно разрешаемой атаки; уже начатая атака использует прежний снимок.
A11: Формульные типы оружия | B11: 21 | D11: 7 | E11: Боевые DAMAGE/PENETRATION читаются из снимка активной версии. | F11: PER_ATTACK_ROLL означает новый бросок на каждую отдельно разрешаемую атаку; ItemInstance не получает результат.
A12: Профили формул с учётом 2 хватов | B12: 22 | D12: 8 | E12: Неполные и нарративные сущности не получают выдуманную механику. | F12: Их оформляет мастер как story/custom item.
A13: Автоматизация создания предметов | B13: НЕТ
A14: Формулы изготовления в приложении | B14: Только VALIDATION_ONLY
A15: Player request | B15: Только создание персонажа: FORMULA_VALIDATED или PURE TEMPLATE_FIXED
A16: Master override | B16: Все 27 видов оружия; instance-level patch без formula bounds
A17: Нормализованные боевые значения | B17: 65
A18: Runtime-результаты в экземпляре | B18: НЕ СОХРАНЯЮТСЯ
A19: Ключевые границы применения
A20: Область | B20: Решение | C20: Область | D20: Решение | E20: Область | F20: Решение | G20: Область | H20: Решение
A21: Крафт | B21: Не исполняется | C21: Цены | D21: Не заданы | E21: Масса | F21: Nullable/мастер | G21: Вместимость | H21: Не автоматизировать
A22: Стек | B22: UI-группа по stackKey; перед состоянием расщепить | C22: Броня | D22: 6 зон, слои | E22: Щиты | F22: Отдельный HP | G22: Нэйт | H22: Бинарная герметичность
A23: Боеприпас | B23: Расходуется при атаке | C23: Магазин | D23: Статус неполный | E23: Ремонт | F23: Manual only | G23: Горение | H23: Не по каждому предмету
A24: Описательный предмет | B24: Без механики | C24: Custom item | D24: 1 положительный бонус | E24: Владение | F24: Ровно один owner/scene | G24: Лут | H24: Частичный стек q
A25: Pure-only препарат | B25: Можно хранить/передать | C25: Применение | D25: Блок другой расе | E25: Качество | F25: Рекомендация мастеру | G25: Экипировка | H25: Не автоматическая
A26: Игрок | B26: Только создание; formula outputs | C26: Мастер | D26: Все оружие; patch экземпляра | E26: Оружие Чистых | F26: Игрок read-only, мастер override | G26: Формульный шаблон | H26: Exact joint validator
A27: Приоритет | B27: Rules v1.7 > v1.6 > v1.5 > v1.4 > v1.3 > v1.2 > tombstone/base | C27: Источник | D27: Источник | E27: Rules Registry v1.7 + Character Registry v1.2 + Bestiary v1.4 + PDF Atlas v1.1 | F27: MONSTER_ATTACK и naturalArmor не являются ItemType | G27: Аудит | H27: Профиль + AttackResolution + clone provenance
A28: Иконки | B28: 64 PNG 96×96; только 64 выбираемых ItemTypeID | C28: Паутина Паука | D28: CustomMonster не создаёт ItemInstance или MapObject | E28: Лут монстра | F28: NOT_LOOTABLE проверяется до контейнера | G28: Системный SentientEnemy | H28: Системный SentientEnemy: NO_XP_PROGRESSION; независимый item graph без новых ItemType/иконок

Sheet 01_Каталог
A1: Основной каталог предметов
A2: Каталог задаёт канонический шаблон. Эффективный профиль оружия читается из активной WeaponProfileVersion: TEMPLATE_FIXED блокирует изменение только игроку, но мастер вправе patch-ить любой конкретный экземпляр по CORE-187/188.
A4: ItemTypeID | B4: Rule ID | C4: Название | D4: Категория | E4: Подкатегория | F4: Класс каталога | G4: Полнота механики | H4: Можно в инвентарь | I4: Физически взаимозаменяем | J4: UI-группировка по stackKey | K4: Единица | L4: Экипируется | M4: Составной | N4: Источник готовых параметров экземпляра | O4: Политика заявки игрока | P4: Master profile override allowed | Q4: Formula ID | R4: Generation enabled | S4: Источник | T4: Примечание | U4: ID уникален
A5: ITM-WPN-001 | B5: CORE-021 | C5: Лёгкий арбалет | D5: Оружие | E5: Арбалет | F5: A_CANONICAL | G5: FULL | H5: =TRUE() -> TRUE | I5: =FALSE() -> FALSE | J5: =TRUE() -> TRUE | K5: экземпляр | L5: =TRUE() -> TRUE | M5: =FALSE() -> FALSE | N5: INSTANCE_RESOLVED | O5: EXACT_JOINT_FORMULA | P5: =TRUE() -> TRUE | Q5: F-WPN-001 | R5: =FALSE() -> FALSE | S5: PDF §4, с. 68; CORE-021 | U5: =IF(COUNTIF($A$5:$A$68,A5)=1,"PASS","DUPLICATE") -> PASS
A6: ITM-WPN-002 | B6: CORE-022 | C6: Тяжёлый арбалет | D6: Оружие | E6: Арбалет | F6: A_CANONICAL | G6: FULL | H6: =TRUE() -> TRUE | I6: =FALSE() -> FALSE | J6: =TRUE() -> TRUE | K6: экземпляр | L6: =TRUE() -> TRUE | M6: =FALSE() -> FALSE | N6: INSTANCE_RESOLVED | O6: EXACT_JOINT_FORMULA | P6: =TRUE() -> TRUE | Q6: F-WPN-002 | R6: =FALSE() -> FALSE | S6: PDF §4, с. 69; CORE-022 | U6: =IF(COUNTIF($A$5:$A$68,A6)=1,"PASS","DUPLICATE") -> PASS
A7: ITM-WPN-003 | B7: CORE-023 | C7: Кенси | D7: Оружие | E7: Арбалет | F7: A_CANONICAL | G7: FULL | H7: =TRUE() -> TRUE | I7: =FALSE() -> FALSE | J7: =TRUE() -> TRUE | K7: экземпляр | L7: =TRUE() -> TRUE | M7: =FALSE() -> FALSE | N7: TEMPLATE_FIXED | O7: TEMPLATE_FIXED | P7: =TRUE() -> TRUE | R7: =FALSE() -> FALSE | S7: PDF §4, с. 69; CORE-023 | U7: =IF(COUNTIF($A$5:$A$68,A7)=1,"PASS","DUPLICATE") -> PASS
A8: ITM-WPN-004 | B8: CORE-024 | C8: Эривел | D8: Оружие | E8: Арбалет | F8: A_CANONICAL | G8: FULL | H8: =TRUE() -> TRUE | I8: =FALSE() -> FALSE | J8: =TRUE() -> TRUE | K8: экземпляр | L8: =TRUE() -> TRUE | M8: =FALSE() -> FALSE | N8: TEMPLATE_FIXED | O8: TEMPLATE_FIXED | P8: =TRUE() -> TRUE | R8: =FALSE() -> FALSE | S8: PDF §4, с. 69; CORE-024 | U8: =IF(COUNTIF($A$5:$A$68,A8)=1,"PASS","DUPLICATE") -> PASS
A9: ITM-WPN-005 | B9: CORE-025 | C9: Эстрефорд | D9: Оружие | E9: Арбалет | F9: A_CANONICAL | G9: FULL | H9: =TRUE() -> TRUE | I9: =FALSE() -> FALSE | J9: =TRUE() -> TRUE | K9: экземпляр | L9: =TRUE() -> TRUE | M9: =FALSE() -> FALSE | N9: TEMPLATE_FIXED | O9: TEMPLATE_FIXED | P9: =TRUE() -> TRUE | R9: =FALSE() -> FALSE | S9: PDF §4, с. 70; CORE-025 | U9: =IF(COUNTIF($A$5:$A$68,A9)=1,"PASS","DUPLICATE") -> PASS
A10: ITM-WPN-006 | B10: CORE-026 | C10: Айнцберн | D10: Оружие | E10: Арбалет | F10: A_CANONICAL | G10: FULL | H10: =TRUE() -> TRUE | I10: =FALSE() -> FALSE | J10: =TRUE() -> TRUE | K10: экземпляр | L10: =TRUE() -> TRUE | M10: =FALSE() -> FALSE | N10: TEMPLATE_FIXED | O10: TEMPLATE_FIXED | P10: =TRUE() -> TRUE | R10: =FALSE() -> FALSE | S10: PDF §4, с. 70; CORE-026 | U10: =IF(COUNTIF($A$5:$A$68,A10)=1,"PASS","DUPLICATE") -> PASS
A11: ITM-WPN-007 | B11: CORE-027 | C11: Лёгкий лук | D11: Оружие | E11: Лук | F11: A_CANONICAL | G11: FULL | H11: =TRUE() -> TRUE | I11: =FALSE() -> FALSE | J11: =TRUE() -> TRUE | K11: экземпляр | L11: =TRUE() -> TRUE | M11: =FALSE() -> FALSE | N11: INSTANCE_RESOLVED | O11: EXACT_JOINT_FORMULA | P11: =TRUE() -> TRUE | Q11: F-WPN-003 | R11: =FALSE() -> FALSE | S11: PDF §4, с. 71; CORE-027 | U11: =IF(COUNTIF($A$5:$A$68,A11)=1,"PASS","DUPLICATE") -> PASS
A12: ITM-WPN-008 | B12: CORE-028 | C12: Тяжёлый лук | D12: Оружие | E12: Лук | F12: A_CANONICAL | G12: FULL | H12: =TRUE() -> TRUE | I12: =FALSE() -> FALSE | J12: =TRUE() -> TRUE | K12: экземпляр | L12: =TRUE() -> TRUE | M12: =FALSE() -> FALSE | N12: INSTANCE_RESOLVED | O12: EXACT_JOINT_FORMULA | P12: =TRUE() -> TRUE | Q12: F-WPN-004 | R12: =FALSE() -> FALSE | S12: PDF §4, с. 71; CORE-028 | U12: =IF(COUNTIF($A$5:$A$68,A12)=1,"PASS","DUPLICATE") -> PASS
A13: ITM-WPN-009 | B13: CORE-029 | C13: Длинный лук | D13: Оружие | E13: Лук | F13: A_CANONICAL | G13: FULL | H13: =TRUE() -> TRUE | I13: =FALSE() -> FALSE | J13: =TRUE() -> TRUE | K13: экземпляр | L13: =TRUE() -> TRUE | M13: =FALSE() -> FALSE | N13: INSTANCE_RESOLVED | O13: EXACT_JOINT_FORMULA | P13: =TRUE() -> TRUE | Q13: F-WPN-005 | R13: =FALSE() -> FALSE | S13: PDF §4, с. 72; CORE-029 | U13: =IF(COUNTIF($A$5:$A$68,A13)=1,"PASS","DUPLICATE") -> PASS
A14: ITM-WPN-010 | B14: CORE-031 | C14: Грубое оружие | D14: Оружие | E14: Ближнее оружие | F14: A_CANONICAL | G14: FULL | H14: =TRUE() -> TRUE | I14: =FALSE() -> FALSE | J14: =TRUE() -> TRUE | K14: экземпляр | L14: =TRUE() -> TRUE | M14: =FALSE() -> FALSE | N14: INSTANCE_RESOLVED | O14: EXACT_JOINT_FORMULA | P14: =TRUE() -> TRUE | Q14: F-WPN-006 | R14: =FALSE() -> FALSE | S14: PDF §4, с. 73; CORE-031 | T14: Примеры: дубина, дрын, булава, кистень, молот. | U14: =IF(COUNTIF($A$5:$A$68,A14)=1,"PASS","DUPLICATE") -> PASS
A15: ITM-WPN-011 | B15: CORE-032 | C15: Одноручный меч | D15: Оружие | E15: Ближнее оружие | F15: A_CANONICAL | G15: FULL | H15: =TRUE() -> TRUE | I15: =FALSE() -> FALSE | J15: =TRUE() -> TRUE | K15: экземпляр | L15: =TRUE() -> TRUE | M15: =FALSE() -> FALSE | N15: INSTANCE_RESOLVED | O15: EXACT_JOINT_FORMULA | P15: =TRUE() -> TRUE | Q15: F-WPN-007 | R15: =FALSE() -> FALSE | S15: PDF §4, с. 73; CORE-032 | U15: =IF(COUNTIF($A$5:$A$68,A15)=1,"PASS","DUPLICATE") -> PASS
A16: ITM-WPN-012 | B16: CORE-033 | C16: Полуторный меч | D16: Оружие | E16: Ближнее оружие | F16: A_CANONICAL | G16: FULL | H16: =TRUE() -> TRUE | I16: =FALSE() -> FALSE | J16: =TRUE() -> TRUE | K16: экземпляр | L16: =TRUE() -> TRUE | M16: =FALSE() -> FALSE | N16: INSTANCE_RESOLVED | O16: EXACT_JOINT_FORMULA | P16: =TRUE() -> TRUE | Q16: F-WPN-008A; F-WPN-008B | R16: =FALSE() -> FALSE | S16: PDF §4, с. 73; CORE-033 | T16: Хват 1/2 руки фиксируется при заявке или выдаче; позднее не переключается. | U16: =IF(COUNTIF($A$5:$A$68,A16)=1,"PASS","DUPLICATE") -> PASS
A17: ITM-WPN-013 | B17: CORE-034 | C17: Двуручный меч | D17: Оружие | E17: Ближнее оружие | F17: A_CANONICAL | G17: FULL | H17: =TRUE() -> TRUE | I17: =FALSE() -> FALSE | J17: =TRUE() -> TRUE | K17: экземпляр | L17: =TRUE() -> TRUE | M17: =FALSE() -> FALSE | N17: INSTANCE_RESOLVED | O17: EXACT_JOINT_FORMULA | P17: =TRUE() -> TRUE | Q17: F-WPN-009 | R17: =FALSE() -> FALSE | S17: PDF §4, с. 74; CORE-034 | U17: =IF(COUNTIF($A$5:$A$68,A17)=1,"PASS","DUPLICATE") -> PASS
A18: ITM-WPN-014 | B18: CORE-035 | C18: Шпага | D18: Оружие | E18: Ближнее оружие | F18: A_CANONICAL | G18: FULL | H18: =TRUE() -> TRUE | I18: =FALSE() -> FALSE | J18: =TRUE() -> TRUE | K18: экземпляр | L18: =TRUE() -> TRUE | M18: =FALSE() -> FALSE | N18: INSTANCE_RESOLVED | O18: EXACT_JOINT_FORMULA | P18: =TRUE() -> TRUE | Q18: F-WPN-010 | R18: =FALSE() -> FALSE | S18: PDF §4, с. 74; CORE-035 | U18: =IF(COUNTIF($A$5:$A$68,A18)=1,"PASS","DUPLICATE") -> PASS
A19: ITM-WPN-015 | B19: CORE-036 | C19: Копьё | D19: Оружие | E19: Ближнее оружие | F19: A_CANONICAL | G19: FULL | H19: =TRUE() -> TRUE | I19: =FALSE() -> FALSE | J19: =TRUE() -> TRUE | K19: экземпляр | L19: =TRUE() -> TRUE | M19: =FALSE() -> FALSE | N19: INSTANCE_RESOLVED | O19: EXACT_JOINT_FORMULA | P19: =TRUE() -> TRUE | Q19: F-WPN-011 | R19: =FALSE() -> FALSE | S19: PDF §4, с. 74; CORE-036 | U19: =IF(COUNTIF($A$5:$A$68,A19)=1,"PASS","DUPLICATE") -> PASS
A20: ITM-WPN-016 | B20: CORE-037 | C20: Кинжал | D20: Оружие | E20: Ближнее оружие | F20: A_CANONICAL | G20: FULL | H20: =TRUE() -> TRUE | I20: =FALSE() -> FALSE | J20: =TRUE() -> TRUE | K20: экземпляр | L20: =TRUE() -> TRUE | M20: =FALSE() -> FALSE | N20: INSTANCE_RESOLVED | O20: EXACT_JOINT_FORMULA | P20: =TRUE() -> TRUE | Q20: F-WPN-012 | R20: =FALSE() -> FALSE | S20: PDF §4, с. 74; CORE-037 | U20: =IF(COUNTIF($A$5:$A$68,A20)=1,"PASS","DUPLICATE") -> PASS
A21: ITM-WPN-017 | B21: CORE-038 | C21: Мизерикордия | D21: Оружие | E21: Ближнее оружие | F21: A_CANONICAL | G21: FULL | H21: =TRUE() -> TRUE | I21: =FALSE() -> FALSE | J21: =TRUE() -> TRUE | K21: экземпляр | L21: =TRUE() -> TRUE | M21: =FALSE() -> FALSE | N21: INSTANCE_RESOLVED | O21: EXACT_JOINT_FORMULA | P21: =TRUE() -> TRUE | Q21: F-WPN-013 | R21: =FALSE() -> FALSE | S21: PDF §4, с. 75; CORE-038 | U21: =IF(COUNTIF($A$5:$A$68,A21)=1,"PASS","DUPLICATE") -> PASS
A22: ITM-WPN-018 | B22: CORE-039 | C22: Одноручный топор | D22: Оружие | E22: Ближнее оружие | F22: A_CANONICAL | G22: FULL | H22: =TRUE() -> TRUE | I22: =FALSE() -> FALSE | J22: =TRUE() -> TRUE | K22: экземпляр | L22: =TRUE() -> TRUE | M22: =FALSE() -> FALSE | N22: INSTANCE_RESOLVED | O22: EXACT_JOINT_FORMULA | P22: =TRUE() -> TRUE | Q22: F-WPN-014 | R22: =FALSE() -> FALSE | S22: PDF §4, с. 75; CORE-039 | U22: =IF(COUNTIF($A$5:$A$68,A22)=1,"PASS","DUPLICATE") -> PASS
A23: ITM-WPN-019 | B23: CORE-040 | C23: Клевец | D23: Оружие | E23: Ближнее оружие | F23: A_CANONICAL | G23: FULL | H23: =TRUE() -> TRUE | I23: =FALSE() -> FALSE | J23: =TRUE() -> TRUE | K23: экземпляр | L23: =TRUE() -> TRUE | M23: =FALSE() -> FALSE | N23: INSTANCE_RESOLVED | O23: EXACT_JOINT_FORMULA | P23: =TRUE() -> TRUE | Q23: F-WPN-015 | R23: =FALSE() -> FALSE | S23: PDF §4, с. 75; CORE-040 | U23: =IF(COUNTIF($A$5:$A$68,A23)=1,"PASS","DUPLICATE") -> PASS
A24: ITM-WPN-020 | B24: CORE-041 | C24: Двуручный топор | D24: Оружие | E24: Ближнее оружие | F24: A_CANONICAL | G24: FULL | H24: =TRUE() -> TRUE | I24: =FALSE() -> FALSE | J24: =TRUE() -> TRUE | K24: экземпляр | L24: =TRUE() -> TRUE | M24: =FALSE() -> FALSE | N24: INSTANCE_RESOLVED | O24: EXACT_JOINT_FORMULA | P24: =TRUE() -> TRUE | Q24: F-WPN-016 | R24: =FALSE() -> FALSE | S24: PDF §4, с. 75; CORE-041 | U24: =IF(COUNTIF($A$5:$A$68,A24)=1,"PASS","DUPLICATE") -> PASS
A25: ITM-WPN-021 | B25: CORE-042 | C25: Кастет | D25: Оружие | E25: Ближнее оружие | F25: A_CANONICAL | G25: FULL | H25: =TRUE() -> TRUE | I25: =FALSE() -> FALSE | J25: =TRUE() -> TRUE | K25: экземпляр | L25: =TRUE() -> TRUE | M25: =FALSE() -> FALSE | N25: INSTANCE_RESOLVED | O25: EXACT_JOINT_FORMULA | P25: =TRUE() -> TRUE | Q25: F-WPN-017 | R25: =FALSE() -> FALSE | S25: PDF §4, с. 76; CORE-042 | U25: =IF(COUNTIF($A$5:$A$68,A25)=1,"PASS","DUPLICATE") -> PASS
A26: ITM-WPN-022 | B26: CORE-043 | C26: Деревянный круглый щит | D26: Оружие | E26: Щит | F26: A_CANONICAL | G26: FULL | H26: =TRUE() -> TRUE | I26: =FALSE() -> FALSE | J26: =TRUE() -> TRUE | K26: экземпляр | L26: =TRUE() -> TRUE | M26: =FALSE() -> FALSE | N26: INSTANCE_RESOLVED | O26: EXACT_JOINT_FORMULA | P26: =TRUE() -> TRUE | Q26: F-WPN-018 | R26: =FALSE() -> FALSE | S26: PDF §4, с. 77; CORE-043 | U26: =IF(COUNTIF($A$5:$A$68,A26)=1,"PASS","DUPLICATE") -> PASS
A27: ITM-WPN-023 | B27: CORE-044 | C27: Железный круглый щит | D27: Оружие | E27: Щит | F27: A_CANONICAL | G27: FULL | H27: =TRUE() -> TRUE | I27: =FALSE() -> FALSE | J27: =TRUE() -> TRUE | K27: экземпляр | L27: =TRUE() -> TRUE | M27: =FALSE() -> FALSE | N27: INSTANCE_RESOLVED | O27: EXACT_JOINT_FORMULA | P27: =TRUE() -> TRUE | Q27: F-WPN-019 | R27: =FALSE() -> FALSE | S27: PDF §4, с. 77; CORE-044 | U27: =IF(COUNTIF($A$5:$A$68,A27)=1,"PASS","DUPLICATE") -> PASS
A28: ITM-WPN-024 | B28: CORE-045 | C28: Деревянный треугольный щит | D28: Оружие | E28: Щит | F28: A_CANONICAL | G28: FULL | H28: =TRUE() -> TRUE | I28: =FALSE() -> FALSE | J28: =TRUE() -> TRUE | K28: экземпляр | L28: =TRUE() -> TRUE | M28: =FALSE() -> FALSE | N28: INSTANCE_RESOLVED | O28: EXACT_JOINT_FORMULA | P28: =TRUE() -> TRUE | Q28: F-WPN-020 | R28: =FALSE() -> FALSE | S28: PDF §4, с. 78; CORE-045 | U28: =IF(COUNTIF($A$5:$A$68,A28)=1,"PASS","DUPLICATE") -> PASS
A29: ITM-WPN-025 | B29: CORE-046 | C29: Железный треугольный щит | D29: Оружие | E29: Щит | F29: A_CANONICAL | G29: FULL | H29: =TRUE() -> TRUE | I29: =FALSE() -> FALSE | J29: =TRUE() -> TRUE | K29: экземпляр | L29: =TRUE() -> TRUE | M29: =FALSE() -> FALSE | N29: INSTANCE_RESOLVED | O29: EXACT_JOINT_FORMULA | P29: =TRUE() -> TRUE | Q29: F-WPN-021 | R29: =FALSE() -> FALSE | S29: PDF §4, с. 78; CORE-046 | U29: =IF(COUNTIF($A$5:$A$68,A29)=1,"PASS","DUPLICATE") -> PASS
A30: ITM-WPN-026 | B30: CORE-047 | C30: Корнадора | D30: Оружие | E30: Составной комплект | F30: A_CANONICAL | G30: FULL | H30: =TRUE() -> TRUE | I30: =FALSE() -> FALSE | J30: =TRUE() -> TRUE | K30: экземпляр | L30: =TRUE() -> TRUE | M30: =TRUE() -> TRUE | N30: TEMPLATE_FIXED | O30: TEMPLATE_FIXED | P30: =TRUE() -> TRUE | R30: =FALSE() -> FALSE | S30: PDF §4, с. 79; CORE-047 | T30: Комплект из меча и щита; компоненты имеют самостоятельные runtime-состояния. | U30: =IF(COUNTIF($A$5:$A$68,A30)=1,"PASS","DUPLICATE") -> PASS
A31: ITM-WPN-027 | B31: CORE-048 | C31: Бларадэ | D31: Оружие | E31: Составной комплект | F31: A_CANONICAL | G31: FULL | H31: =TRUE() -> TRUE | I31: =FALSE() -> FALSE | J31: =TRUE() -> TRUE | K31: экземпляр | L31: =TRUE() -> TRUE | M31: =TRUE() -> TRUE | N31: TEMPLATE_FIXED | O31: TEMPLATE_FIXED | P31: =TRUE() -> TRUE | R31: =FALSE() -> FALSE | S31: PDF §4, с. 80; CORE-048 | T31: Комплект из шпаги и щита; компоненты имеют самостоятельные runtime-состояния. | U31: =IF(COUNTIF($A$5:$A$68,A31)=1,"PASS","DUPLICATE") -> PASS
A32: ITM-ARM-001 | B32: CORE-049 | C32: Кожаный доспех | D32: Броня | E32: Зональный элемент | F32: A_CANONICAL | G32: FULL | H32: =TRUE() -> TRUE | I32: =FALSE() -> FALSE | J32: =TRUE() -> TRUE | K32: экземпляр | L32: =TRUE() -> TRUE | M32: =FALSE() -> FALSE | N32: INSTANCE_ZONE | O32: TEMPLATE_FIXED | P32: =FALSE() -> FALSE | R32: =FALSE() -> FALSE | S32: PDF §4, с. 81; CORE-049 | U32: =IF(COUNTIF($A$5:$A$68,A32)=1,"PASS","DUPLICATE") -> PASS
A33: ITM-ARM-002 | B33: CORE-050 | C33: Бригантина | D33: Броня | E33: Зональный элемент | F33: A_CANONICAL | G33: FULL | H33: =TRUE() -> TRUE | I33: =FALSE() -> FALSE | J33: =TRUE() -> TRUE | K33: экземпляр | L33: =TRUE() -> TRUE | M33: =FALSE() -> FALSE | N33: INSTANCE_ZONE | O33: TEMPLATE_FIXED | P33: =FALSE() -> FALSE | R33: =FALSE() -> FALSE | S33: PDF §4, с. 81; CORE-050 | U33: =IF(COUNTIF($A$5:$A$68,A33)=1,"PASS","DUPLICATE") -> PASS
A34: ITM-ARM-003 | B34: CORE-051 | C34: Кольчуга | D34: Броня | E34: Зональный элемент | F34: A_CANONICAL | G34: FULL | H34: =TRUE() -> TRUE | I34: =FALSE() -> FALSE | J34: =TRUE() -> TRUE | K34: экземпляр | L34: =TRUE() -> TRUE | M34: =FALSE() -> FALSE | N34: INSTANCE_ZONE | O34: TEMPLATE_FIXED | P34: =FALSE() -> FALSE | R34: =FALSE() -> FALSE | S34: PDF §4, с. 81; CORE-051 | U34: =IF(COUNTIF($A$5:$A$68,A34)=1,"PASS","DUPLICATE") -> PASS
A35: ITM-ARM-004 | B35: CORE-052 | C35: Латы | D35: Броня | E35: Зональный элемент | F35: A_CANONICAL | G35: FULL | H35: =TRUE() -> TRUE | I35: =FALSE() -> FALSE | J35: =TRUE() -> TRUE | K35: экземпляр | L35: =TRUE() -> TRUE | M35: =FALSE() -> FALSE | N35: INSTANCE_ZONE | O35: TEMPLATE_FIXED | P35: =FALSE() -> FALSE | R35: =FALSE() -> FALSE | S35: PDF §4, с. 82; CORE-052 | U35: =IF(COUNTIF($A$5:$A$68,A35)=1,"PASS","DUPLICATE") -> PASS
A36: ITM-ARM-005 | B36: CORE-053 | C36: Нэйт | D36: Броня | E36: Цельный костюм | F36: A_CANONICAL | G36: FULL | H36: =TRUE() -> TRUE | I36: =FALSE() -> FALSE | J36: =TRUE() -> TRUE | K36: экземпляр | L36: =TRUE() -> TRUE | M36: =FALSE() -> FALSE | N36: TEMPLATE_FIXED | O36: TEMPLATE_FIXED | P36: =FALSE() -> FALSE | R36: =FALSE() -> FALSE | S36: PDF §4, с. 82; CORE-053 | U36: =IF(COUNTIF($A$5:$A$68,A36)=1,"PASS","DUPLICATE") -> PASS
A37: ITM-ARM-006 | B37: CORE-054 | C37: Кастелькросс | D37: Броня | E37: Цельный доспех | F37: A_CANONICAL | G37: FULL | H37: =TRUE() -> TRUE | I37: =FALSE() -> FALSE | J37: =TRUE() -> TRUE | K37: экземпляр | L37: =TRUE() -> TRUE | M37: =FALSE() -> FALSE | N37: TEMPLATE_FIXED | O37: TEMPLATE_FIXED | P37: =FALSE() -> FALSE | R37: =FALSE() -> FALSE | S37: PDF §4, с. 82; CORE-054 | U37: =IF(COUNTIF($A$5:$A$68,A37)=1,"PASS","DUPLICATE") -> PASS
A38: ITM-ARM-007 | B38: CORE-055 | C38: Цесмор | D38: Броня | E38: Цельный доспех | F38: A_CANONICAL | G38: FULL | H38: =TRUE() -> TRUE | I38: =FALSE() -> FALSE | J38: =TRUE() -> TRUE | K38: экземпляр | L38: =TRUE() -> TRUE | M38: =FALSE() -> FALSE | N38: TEMPLATE_FIXED | O38: TEMPLATE_FIXED | P38: =FALSE() -> FALSE | R38: =FALSE() -> FALSE | S38: PDF §4, с. 82; CORE-055 | U38: =IF(COUNTIF($A$5:$A$68,A38)=1,"PASS","DUPLICATE") -> PASS
A39: ITM-ARM-008 | B39: CORE-056 | C39: Гленхейм | D39: Броня | E39: Цельный доспех | F39: A_CANONICAL | G39: FULL | H39: =TRUE() -> TRUE | I39: =FALSE() -> FALSE | J39: =TRUE() -> TRUE | K39: экземпляр | L39: =TRUE() -> TRUE | M39: =FALSE() -> FALSE | N39: TEMPLATE_FIXED | O39: TEMPLATE_FIXED | P39: =FALSE() -> FALSE | R39: =FALSE() -> FALSE | S39: PDF §4, с. 83; CORE-056 | U39: =IF(COUNTIF($A$5:$A$68,A39)=1,"PASS","DUPLICATE") -> PASS
A40: ITM-PHA-001 | B40: CORE-059 | C40: Антисептик | D40: Фармацевтика | E40: Отвар/средство | F40: A_CANONICAL | G40: FULL | H40: =TRUE() -> TRUE | I40: =TRUE() -> TRUE | J40: =TRUE() -> TRUE | K40: доза | L40: =FALSE() -> FALSE | M40: =FALSE() -> FALSE | N40: TEMPLATE_FIXED | O40: TEMPLATE_FIXED | P40: =FALSE() -> FALSE | R40: =FALSE() -> FALSE | S40: PDF §4, с. 83; CORE-059 | U40: =IF(COUNTIF($A$5:$A$68,A40)=1,"PASS","DUPLICATE") -> PASS
A41: ITM-PHA-002 | B41: CORE-060 | C41: Отвар, приводящий в сознание | D41: Фармацевтика | E41: Отвар/средство | F41: A_CANONICAL | G41: FULL | H41: =TRUE() -> TRUE | I41: =TRUE() -> TRUE | J41: =TRUE() -> TRUE | K41: доза | L41: =FALSE() -> FALSE | M41: =FALSE() -> FALSE | N41: TEMPLATE_FIXED | O41: TEMPLATE_FIXED | P41: =FALSE() -> FALSE | R41: =FALSE() -> FALSE | S41: PDF §4, с. 83; CORE-060 | U41: =IF(COUNTIF($A$5:$A$68,A41)=1,"PASS","DUPLICATE") -> PASS
...

Sheet 02_Профили_оружия
A1: Профили оружия и щитов — исходные выражения
A2: Столбцы I–J сохраняют канонический шаблон. Исполняемая база и модификатор характеристики разделены на 02A. При MASTER_OVERRIDE damage/penetration, statRequirements, rangeMeters и accuracyBonus берутся из активной WeaponProfileVersion; навыки, ёмкость, перезарядка, HP и особые правила остаются шаблонными.
A4: ItemTypeID | B4: Rule ID | C4: Название | D4: Руки | E4: Требования | F4: Стат точности | G4: Навык/класс | H4: Штраф без навыка/класса | I4: Урон: исходное выражение | J4: Пробитие: исходное выражение | K4: Дальность, м | L4: Боеприпас | M4: Ёмкость | N4: Перезарядка, действий | O4: Перезарядка атомарна | P4: Блок | Q4: Парирование | R4: Shield max HP | S4: Можно метать | T4: Штраф метания | U4: Особое правило | V4: PDF, с.
A5: ITM-WPN-001 | B5: CORE-021 | C5: Лёгкий арбалет | D5: 2 | E5: PROFILE: statRequirements{S:Rs,D:Rd}; instanceDamage=Dm; rangeMeters=Rn | F5: D | G5: Стрельба или Сталкер/Солдат ПР | H5: −5 | I5: Dm | J5: R12 | K5: Rn | L5: Арбалетный болт | N5: 1 | O5: =FALSE() -> FALSE | S5: =FALSE() -> FALSE | U5: Формульная допустимость по F-WPN-001; ёмкость не задана; боеприпас при объявлении расходуется. | V5: 68
A6: ITM-WPN-002 | B6: CORE-022 | C6: Тяжёлый арбалет | D6: 2 | E6: PROFILE: statRequirements{S:Rs,D:Rd}; instanceDamage=Dm; rangeMeters=Rn | F6: D | G6: Стрельба или Сталкер/Солдат ПР | H6: −5 | I6: Dm | J6: R20 | K6: Rn | L6: Арбалетный болт | N6: 1 | O6: =FALSE() -> FALSE | S6: =FALSE() -> FALSE | U6: Формульная допустимость по F-WPN-002; ёмкость не задана. | V6: 69
A7: ITM-WPN-003 | B7: CORE-023 | C7: Кенси | D7: 1 | E7: S8; D19 | F7: D | G7: Стрельба; класс Сталкер/Солдат ПР | H7: −15 без класса | I7: 10 | J7: R12 | K7: 20 | L7: Арбалетный болт | M7: 8 | N7: 1 | O7: =FALSE() -> FALSE | S7: =FALSE() -> FALSE | U7: Высокая Стрельба: один раз за личный ход за 1 действие особая атака двумя Кенси; каждый выстрел разрешается отдельно. Совершенная: можно назначить отдельные цели. | V7: 69
A8: ITM-WPN-004 | B8: CORE-024 | C8: Эривел | D8: 2 | E8: S16; D12 | F8: D | G8: Стрельба; класс Сталкер/Солдат ПР | H8: −15 без класса | I8: 2×R20 (один бросок) | J8: R20 (независимый) | K8: 30 | L8: Арбалетный болт | M8: 4 | N8: 1 | O8: =FALSE() -> FALSE | S8: =FALSE() -> FALSE | V8: 69
A9: ITM-WPN-005 | B9: CORE-025 | C9: Эстрефорд | D9: 2 | E9: S19; D14 | F9: D | G9: Стрельба; класс Сталкер/Солдат ПР | H9: −15 без класса | I9: 30 | J9: 16 | K9: 30 | L9: Арбалетный болт | N9: 1 | O9: =FALSE() -> FALSE | S9: =FALSE() -> FALSE | U9: Ёмкость не задана. | V9: 70
A10: ITM-WPN-006 | B10: CORE-026 | C10: Айнцберн | D10: 2 | E10: S22; D22; I12; Стрельба ≥ средняя | F10: D | G10: Стрельба; класс Сталкер/Солдат ПР | H10: −15 без класса | I10: R20+30 | J10: R20+20 (независимый) | K10: 100 | L10: Арбалетный болт | N10: 2 | O10: =TRUE() -> TRUE | S10: =FALSE() -> FALSE | U10: Ёмкость не задана. Абсолютная Стрельба: R6>2 — точная заявленная зона. | V10: 70
A11: ITM-WPN-007 | B11: CORE-027 | C11: Лёгкий лук | D11: 2 | E11: PROFILE: statRequirements{S:Rs,D:Rd}; instanceDamage=Dm; rangeMeters=Rn | F11: D | G11: Стрельба из лука | H11: −5 | I11: Dm | J11: R12 | K11: Rn | L11: Стрела | M11: 1 | N11: 1 | O11: =FALSE() -> FALSE | S11: =FALSE() -> FALSE | U11: Высокий навык: перезарядка 0; абсолютный: R6>2 — точная зона. | V11: 71
A12: ITM-WPN-008 | B12: CORE-028 | C12: Тяжёлый лук | D12: 2 | E12: PROFILE: statRequirements{S:Rs,D:Rd}; instanceDamage=Dm; rangeMeters=Rn | F12: D | G12: Стрельба из лука | H12: −5 | I12: Dm | J12: R20 | K12: Rn | L12: Стрела | M12: 1 | N12: 1 | O12: =FALSE() -> FALSE | S12: =FALSE() -> FALSE | U12: Высокий навык: перезарядка 0; абсолютный: R6>2 — точная зона. | V12: 71
A13: ITM-WPN-009 | B13: CORE-029 | C13: Длинный лук | D13: 2 | E13: PROFILE: statRequirements{S:Rs,D:Rd}; instanceDamage=Dm; rangeMeters=Rn | F13: D | G13: Стрельба из лука | H13: −5 | I13: Dm | J13: R12 | K13: Rn | L13: Стрела | M13: 1 | N13: 1 | O13: =FALSE() -> FALSE | S13: =FALSE() -> FALSE | U13: Дальность может иметь шаг 0,5. Высокий навык: перезарядка 0; абсолютный: R6>2 — точная зона. | V13: 72
A14: ITM-WPN-010 | B14: CORE-031 | C14: Грубое оружие | D14: 1 | E14: PROFILE: statRequirements{S:Rs,D:Rd} | F14: D | G14: Владение грубым оружием | H14: −3 | I14: +S к R12 | J14: R12 | O14: =FALSE() -> FALSE | S14: =TRUE() -> TRUE | U14: При непробитии проходит половина финального урона; урон ≥3×Z: D20<10 — пропуск 3 раундов. | V14: 73
A15: ITM-WPN-011 | B15: CORE-032 | C15: Одноручный меч | D15: 1 | E15: PROFILE: statRequirements{S:Rs,D:Rd} | F15: D | G15: Фехтование | H15: −5 | I15: R20+S | J15: R12 | O15: =FALSE() -> FALSE | S15: =TRUE() -> TRUE | V15: 73
A16: ITM-WPN-012 | B16: CORE-033 | C16: Полуторный меч | D16: 1 или 2, фиксировано | E16: PROFILE: statRequirements{S:Rs(хват),D:Rd}; gripMode фиксирован | F16: D | G16: Фехтование | H16: −5 | I16: R20+S | J16: R20 | O16: =FALSE() -> FALSE | S16: =TRUE() -> TRUE | U16: Хват задаётся в заявке/выдаче и не меняется. | V16: 73
A17: ITM-WPN-013 | B17: CORE-034 | C17: Двуручный меч | D17: 2 | E17: PROFILE: statRequirements{S:Rs,D:Rd} | F17: D | G17: Фехтование | H17: −5 | I17: R20+5+S | J17: R20+5 | O17: =FALSE() -> FALSE | S17: =TRUE() -> TRUE | T17: −10 | V17: 74
A18: ITM-WPN-014 | B18: CORE-035 | C18: Шпага | D18: 1 | E18: PROFILE: statRequirements{S:Rs,D:Rd} | F18: D | G18: Фехтование | H18: −5 | I18: R12+D | J18: R12 | O18: =FALSE() -> FALSE | Q18: 5 | S18: =TRUE() -> TRUE | T18: −10 | V18: 74
A19: ITM-WPN-015 | B19: CORE-036 | C19: Копьё | D19: 2 | E19: PROFILE: statRequirements{S:Rs,D:Rd} | F19: D | G19: Владение копьём | H19: −2 | I19: R12+S | J19: R12 | O19: =FALSE() -> FALSE | S19: =TRUE() -> TRUE | U19: +3 к упреждающему удару. | V19: 74
A20: ITM-WPN-016 | B20: CORE-037 | C20: Кинжал | D20: 1 | E20: PROFILE: statRequirements{S:Rs,D:Rd} | F20: D | G20: Владение коротким оружием | H20: −5 | I20: R12+D; proc: 20+D | J20: R6 | O20: =FALSE() -> FALSE | S20: =TRUE() -> TRUE | U20: Итог меткости ≥40 и пробитие: база урона 20; высокий навык с двумя кинжалами — 2 атаки 1/ход. | V20: 74
A21: ITM-WPN-017 | B21: CORE-038 | C21: Мизерикордия | D21: 1 | E21: PROFILE: statRequirements{S:Rs,D:Rd} | F21: D | G21: Владение коротким оружием | H21: −5 | I21: R6+D; proc: 20+D | J21: R20 | O21: =FALSE() -> FALSE | S21: =TRUE() -> TRUE | U21: Итог меткости ≥40: игнорировать броню, база урона 20. | V21: 75
A22: ITM-WPN-018 | B22: CORE-039 | C22: Одноручный топор | D22: 1 | E22: PROFILE: statRequirements{S:Rs,D:Rd} | F22: D | G22: Владение топорами | H22: −5 | I22: R12+S; proc: 20+S | J22: R20 | O22: =FALSE() -> FALSE | S22: =TRUE() -> TRUE | U22: Итог меткости ≥41: игнорировать броню, база урона 20. | V22: 75
A23: ITM-WPN-019 | B23: CORE-040 | C23: Клевец | D23: 1 | E23: PROFILE: statRequirements{S:Rs,D:Rd} | F23: D | G23: Владение топорами | H23: −5 | I23: R6+S; proc: 20+S | J23: R20+5 | O23: =FALSE() -> FALSE | S23: =TRUE() -> TRUE | U23: Итог меткости ≥35: игнорировать броню, база урона 20. | V23: 75
A24: ITM-WPN-020 | B24: CORE-041 | C24: Двуручный топор | D24: 2 | E24: PROFILE: statRequirements{S:Rs,D:Rd} | F24: D | G24: Владение топорами | H24: −5 | I24: R20+S; proc: 20+S | J24: R20+10 | O24: =FALSE() -> FALSE | S24: =TRUE() -> TRUE | T24: −10 | U24: Итог меткости ≥37: игнорировать броню, база урона 20. | V24: 75
A25: ITM-WPN-021 | B25: CORE-042 | C25: Кастет | D25: 1 | E25: PROFILE: statRequirements{S:Rs,D:Rd} | F25: D | G25: Рукопашный бой; Солдат | H25: −5 без обоих; Солдат +3 к точности | I25: R6+S | J25: R6 | O25: =FALSE() -> FALSE | S25: =TRUE() -> TRUE | T25: −10 | U25: Высокий+: два отдельно разрешаемых удара за действие не чаще 1 раза за личный ход; абсолютный: также удар ногой без пробития. | V25: 76
A26: ITM-WPN-022 | B26: CORE-043 | C26: Деревянный круглый щит | D26: 1 | E26: PROFILE: statRequirements{S:Rs,D:Rd} | F26: D | G26: Владение щитом | H26: −5 | I26: R6+S | J26: R6 | O26: =FALSE() -> FALSE | P26: 3 | R26: 60 | S26: =TRUE() -> TRUE | U26: Меткость ≥30: −1 к следующей серии цели. | V26: 77
A27: ITM-WPN-023 | B27: CORE-044 | C27: Железный круглый щит | D27: 1 | E27: PROFILE: statRequirements{S:Rs,D:Rd} | F27: D | G27: Владение щитом | H27: −5 | I27: R6+S | J27: R6 | O27: =FALSE() -> FALSE | P27: 3 | R27: 100 | S27: =TRUE() -> TRUE | U27: Меткость ≥30: −1 к следующей серии цели. | V27: 77
A28: ITM-WPN-024 | B28: CORE-045 | C28: Деревянный треугольный щит | D28: 1 | E28: PROFILE: statRequirements{S:Rs,D:Rd} | F28: D | G28: Владение щитом | H28: −5 | I28: R6+3+S | J28: R6 | O28: =FALSE() -> FALSE | P28: 3 | R28: 80 | S28: =TRUE() -> TRUE | U28: Меткость ≥30: −1 к следующей серии цели. | V28: 78
A29: ITM-WPN-025 | B29: CORE-046 | C29: Железный треугольный щит | D29: 1 | E29: PROFILE: statRequirements{S:Rs,D:Rd} | F29: D | G29: Владение щитом | H29: −5 | I29: R6+3+S | J29: R6 | O29: =FALSE() -> FALSE | P29: 3 | R29: 130 | S29: =TRUE() -> TRUE | U29: Меткость ≥30: −1 к следующей серии цели. | V29: 78
A30: ITM-WPN-026 | B30: CORE-047 | C30: Корнадора | D30: 2 | E30: S22; D16 | F30: D | G30: Солдат ПР; Фехтование; Владение щитом | H30: −15 ко всем ролам без класса | I30: меч R20+S | J30: меч R20 | O30: =FALSE() -> FALSE | P30: 3 | R30: 400 | S30: =TRUE() -> TRUE | U30: Защита ≥40: немедленная контратака; меч/щит можно метать отдельно. | V30: 79
A31: ITM-WPN-027 | B31: CORE-048 | C31: Бларадэ | D31: 2 | E31: S15; D22 | F31: D | G31: Солдат ПР; Фехтование; Владение щитом | H31: −15 ко всем ролам без класса | I31: щит R12+S; шпага R12+D | J31: щит R12; шпага R20 | O31: =FALSE() -> FALSE | P31: 3 | Q31: 5 | R31: 200 | S31: =TRUE() -> TRUE | U31: Щит при меткости ≥30: −1 к следующей серии цели. После разрешения атаки щитом независимо от попадания следующая атака шпагой той же Бларадэ в этом личном ходу получает +5 к меткости/урону/пробитию; бонус расходуется атакой или сгорает в конце хода. | V31: 80

Sheet 03_Профили_брони
A1: Профили брони — исходные выражения
A2: Столбец G сохраняет каноническую запись правил. Машинооднозначная семантика находится на листе 02A_Семантика_Runtime: каждый дайс брони вычисляется заново для каждой отдельно разрешаемой атаки; результат не сохраняется в экземпляре брони.
A4: ItemTypeID | B4: Rule ID | C4: Название | D4: Модель покрытия | E4: Зоны | F4: Требование S | G4: Броня: исходное выражение | H4: Физическая броня | I4: Допускает слои | J4: Герметичен | K4: Твёрдая шея | L4: Бег | M4: Акробатика | N4: Уклонение | O4: M | P4: Защиты/иммунитеты | Q4: Условие/ограничение | R4: PDF, с.
A5: ITM-ARM-001 | B5: CORE-049 | C5: Кожаный доспех | D5: ZONE_ELEMENT | E5: Одна из 6 | F5: 2 за элемент | G5: R6 | H5: =TRUE() -> TRUE | I5: =TRUE() -> TRUE | J5: =FALSE() -> FALSE | K5: =FALSE() -> FALSE | P5: Шлем не закрывает лицо. | R5: 81
A6: ITM-ARM-002 | B6: CORE-050 | C6: Бригантина | D6: ZONE_ELEMENT | E6: Одна из 6 | F6: 3 за элемент | G6: R12 | H6: =TRUE() -> TRUE | I6: =TRUE() -> TRUE | J6: =FALSE() -> FALSE | K6: =TRUE() -> TRUE | L6: −1 за элемент | M6: −1 за элемент | O6: −3 при >2 | P6: Голова+корпус: твёрдая защита шеи; иммунитет удушению. | R6: 81
A7: ITM-ARM-003 | B7: CORE-051 | C7: Кольчуга | D7: ZONE_ELEMENT | E7: Одна из 6 | F7: 3 за элемент | G7: R12 | H7: =TRUE() -> TRUE | I7: =TRUE() -> TRUE | J7: =FALSE() -> FALSE | K7: =FALSE() -> FALSE | L7: −1 за элемент | M7: −1 за элемент | O7: −3 при >2 | P7: Каждый релевантный слой отдельно уменьшает электрический урон на R12; результаты слоёв складываются. | R7: 81
A8: ITM-ARM-004 | B8: CORE-052 | C8: Латы | D8: ZONE_ELEMENT | E8: Одна из 6 | F8: 4 за элемент | G8: R20 | H8: =TRUE() -> TRUE | I8: =TRUE() -> TRUE | J8: =FALSE() -> FALSE | K8: =TRUE() -> TRUE | L8: −2 за элемент | M8: −2 за элемент | O8: −5 при >2 | P8: Голова+корпус: твёрдая защита шеи. | R8: 82
A9: ITM-ARM-005 | B9: CORE-053 | C9: Нэйт | D9: FULL_SUIT | E9: Все 6 | F9: 6 | G9: — | H9: =FALSE() -> FALSE | I9: =FALSE() -> FALSE | J9: =TRUE() -> TRUE | K9: =FALSE() -> FALSE | P9: Пока герметичен: +20 к проверкам против заражения симбионтом, болезни, внешней химии и ядовитых испарений; −20 от каждой порции электрического, ментального, химического урона или урона от ядовитых испарений; +20 во встречных проверках против недамажащего электрического/пси-контроля; полностью блокирует вдыхаемые феромоны и заражённые испарения. | Q9: При потере ≥1 HP носителем или отдельном режущем/колющем/огненном/разъедающем повреждении костюма теряет все свойства; не защищает от проглоченного/введённого/внутреннего яда и не снимает прежний эффект; ремонт не формализован. | R9: 82
A10: ITM-ARM-006 | B10: CORE-054 | C10: Кастелькросс | D10: FULL_SUIT | E10: Все 6 | F10: 20 | G10: R20 | H10: =TRUE() -> TRUE | I10: =TRUE() -> TRUE | J10: =FALSE() -> FALSE | K10: =TRUE() -> TRUE | L10: −6 | M10: −6 | O10: −3 | P10: Ментальный урон −5/порция; +5 против пси-контроля; твёрдая защита шеи. | Q10: Слои разрешены CORE-151, физическая совместимость подтверждается мастером. Без Солдата ПР −15 к перемещениям; не защищает от химических феромонов. | R10: 82
A11: ITM-ARM-007 | B11: CORE-055 | C11: Цесмор | D11: FULL_SUIT | E11: Все 6 | F11: 14 | G11: R20 | H11: =TRUE() -> TRUE | I11: =TRUE() -> TRUE | J11: =FALSE() -> FALSE | K11: =FALSE() -> FALSE | Q11: Слои разрешены CORE-151, физическая совместимость подтверждается мастером. Без Сталкера/Солдата ПР −15 к перемещениям. | R11: 82
A12: ITM-ARM-008 | B12: CORE-056 | C12: Гленхейм | D12: FULL_SUIT | E12: Все 6 | F12: 24 | G12: 2×R20+5 (тот же бросок) | H12: =TRUE() -> TRUE | I12: =TRUE() -> TRUE | J12: =FALSE() -> FALSE | K12: =TRUE() -> TRUE | L12: −12 | M12: −12 | N12: −6 | O12: −5 | P12: Иммунитет травмирующим и удушающим приёмам. | Q12: Слои разрешены CORE-151, физическая совместимость подтверждается мастером. Без Солдата ПР −15 к перемещениям. | R12: 83

Sheet 04_Фармацевтика
A1: Профили фармацевтики
A2: Хранение и передача Pure-only препаратов разрешены любой расе; блокируется только применение к недопустимой расе. Лимиты считаются по скользящим 24 часам. Одноимённые продолжающиеся эффекты не складываются: повтор обновляет срок/условие, но не усиливает значение.
A4: ItemTypeID | B4: Rule ID | C4: Название | D4: Ограничение расы | E4: Макс. доз/24ч | F4: Эффект | G4: Длительность | H4: Стоимость в бою | I4: Политика отказа | J4: Примечание
A5: ITM-PHA-001 | B5: CORE-059 | C5: Антисептик | D5: Любая | E5: не задан | F5: Следующая попытка болезни через обработанную рану: −10; затем эффект заканчивается. | G5: До срабатывания | H5: 1 действие | I5: NOT_DEFINED | J5: Одна доза на одну рану по поздней нормализации.
A6: ITM-PHA-002 | B6: CORE-060 | C6: Отвар, приводящий в сознание | D6: Любая | E6: 3 | F6: Снять тяжёлое ранение; HP=1; отменить сон/паралич; остановить таймер смерти. | G6: Мгновенно | H6: 1 действие | I6: BLOCK_AT_LIMIT | J6: Не отменяет окончательную смерть.
A7: ITM-PHA-003 | B7: CORE-061 | C7: Снотворное | D7: Любая | E7: 3 | F7: (R20_effect+5)×K должно строго превысить R20_target+Z+модификаторы цели; дайсы независимы, равенство = провал; при успехе сон. | G7: 1 час; любой урон или отвар завершает | H7: 1 действие | I7: BLOCK_AT_LIMIT | J7: K доз одновременно; каждая считается в лимит.
A8: ITM-PHA-004 | B8: CORE-062 | C8: Отвар-паралитик | D8: Любая | E8: 3 | F8: (R20_effect+5)×K должно строго превысить R20_target+Z+модификаторы цели; дайсы независимы, равенство = провал; при успехе паралич. | G8: 1 час или до отвара; урон не завершает | H8: 1 действие | I8: BLOCK_AT_LIMIT | J8: K доз одновременно; жизненные процессы не прекращаются.
A9: ITM-PHA-005 | B9: CORE-063 | C9: Кровоостанавливающий отвар | D9: Любая | E9: 5 | F9: Остановить все текущие кровотечения. | G9: Мгновенно | H9: 1 действие | I9: BLOCK_AT_LIMIT
A10: ITM-PHA-006 | B10: CORE-064 | C10: Восстанавливающий отвар | D10: Любая | E10: 2 | F10: Восстановить 25 HP, не выше максимума. | G10: Мгновенно | H10: 1 действие | I10: BLOCK_AT_LIMIT | J10: Не выводит из тяжёлого ранения/окончательной смерти.
A11: ITM-PHA-007 | B11: CORE-065 | C11: Симбиотический отвар | D11: Любая | E11: 4 | F11: Восстановить 50 ОЭ одному выбранному симбионту, не выше максимума. | G11: Мгновенно | H11: 1 действие | I11: BLOCK_AT_LIMIT
A12: ITM-PHA-008 | B12: CORE-066 | C12: Таблетка ночного зрения | D12: Только Чистые | E12: 2 | F12: Видеть в темноте как днём. | G12: 2 часа | H12: 1 действие | I12: BLOCK_WRONG_RACE_OR_LIMIT | J12: Хранить/передавать может любая раса.
A13: ITM-PHA-009 | B13: CORE-067 | C13: Таблетка бритвенных рефлексов | D13: Только Чистые | E13: 3 | F13: +3 к уклонению и парированию. | G13: max(1, round(R20/3)) личных ходов | H13: 1 действие | I13: BLOCK_WRONG_RACE_OR_LIMIT | J13: Повтор не складывается; обновляет срок.
A14: ITM-PHA-010 | B14: CORE-068 | C14: Таблетка ледяного спокойствия | D14: Только Чистые | E14: 3 | F14: +3 к меткости; безэмоциональность — нарративно. | G14: max(1, round(R20/3)) личных ходов | H14: 1 действие | I14: BLOCK_WRONG_RACE_OR_LIMIT | J14: Повтор не складывается; обновляет срок.
A15: ITM-PHA-011 | B15: CORE-069 | C15: Таблетка взрывной мощи | D15: Только Чистые | E15: 2 | F15: Следующая проверка S: +6; сохраняет дееспособность при тяжёлом ранении до конца боя. | G15: До следующей проверки S / до конца боя | H15: 1 действие | I15: BLOCK_WRONG_RACE_OR_LIMIT | J15: Обычное добивание сохраняется.
A16: ITM-PHA-012 | B16: CORE-070 | C16: Таблетка куража | D16: Только Чистые | E16: 4 | F16: +1 к серии/числу действий до конца боя. | G16: До конца боя | H16: 1 действие | I16: BLOCK_WRONG_RACE_OR_LIMIT | J16: Первая доза в текущем ходу сразу добавляет 1 оставшееся действие.
A17: ITM-PHA-013 | B17: CORE-071 | C17: Восстанавливающая таблетка | D17: Только Чистые | E17: 5 | F17: В конце каждого личного хода цели +5 HP, не выше максимума. | G17: До конца боя | H17: 1 действие | I17: BLOCK_WRONG_RACE_OR_LIMIT | J17: Не действует в тяжёлом ранении.
A18: ITM-PHA-014 | B18: CORE-072 | C18: Таблетка неудержимости | D18: Только Чистые | E18: 3 | F18: +5 к сопротивлению/освобождению от эффектов с тегом контроля. | G18: До конца боя | H18: 1 действие | I18: BLOCK_WRONG_RACE_OR_LIMIT

Sheet 05_Формулы_валидации
A1: Формулы допустимости заявки игрока
A2: executionMode=VALIDATION_ONLY. Производственные дайсы относятся только к validationWitness. По CORE-185 переменные L/Lw/Ls — целые неотрицательные; Lw>0 там, где является делителем. Игрок вводит только выходы формулы; runtime-выражения и специальные свойства не меняются.
A4: FormulaID | B4: ItemTypeID | C4: Вариант | D4: Dm | E4: Rn | F4: Rs | G4: Rd | H4: Независимые дайсы | I4: Общие переменные | J4: Порядок/заметка | K4: Домен | L4: Execution mode | M4: Generation enabled | N4: GM override | O4: Контракт проверки | P4: ID уникален
A5: F-WPN-001 | B5: ITM-WPN-001 | C5: DEFAULT | D5: Dm = R12_DMG+L | E5: Rn = R12_RANGE+Dm+L | F5: Rs = MAX(1,CEIL(Dm×Rn/(R20_RS+3×Lw))) | G5: Rd = MAX(1,CEIL(2×Rn/Lw)) | H5: R12_DMG,R12_RANGE,R20_RS | I5: L,Lw | J5: Dm→Rn→Rs→Rd | K5: L,Lw,Ls∈Z≥0; Lw>0 там, где является делителем; каждое вхождение R4/R6/R12/R20 независимо; вычисленные поля переиспользуются по порядку формулы | L5: VALIDATION_ONLY | M5: =FALSE() -> FALSE | N5: BYPASS_FORMULA_BOUNDS; CORE-187/188 | O5: EXISTS one joint witness; сохранить formulaId, formulaVersion=ITEM_FORMULAS_V1.2 и весь witness | P5: =IF(COUNTIF($A$5:$A$26,A5)=1,"PASS","DUPLICATE") -> PASS
A6: F-WPN-002 | B6: ITM-WPN-002 | C6: DEFAULT | D6: Dm = R20_DMG+L | E6: Rn = R12_RANGE+Dm+L | F6: Rs = MAX(1,CEIL(Dm×Rn/(R20_RS+2×Lw))) | G6: Rd = MAX(1,CEIL(2×Rn/Lw)) | H6: R20_DMG,R12_RANGE,R20_RS | I6: L,Lw | J6: Dm→Rn→Rs→Rd | K6: L,Lw,Ls∈Z≥0; Lw>0 там, где является делителем; каждое вхождение R4/R6/R12/R20 независимо; вычисленные поля переиспользуются по порядку формулы | L6: VALIDATION_ONLY | M6: =FALSE() -> FALSE | N6: BYPASS_FORMULA_BOUNDS; CORE-187/188 | O6: EXISTS one joint witness; сохранить formulaId, formulaVersion=ITEM_FORMULAS_V1.2 и весь witness | P6: =IF(COUNTIF($A$5:$A$26,A6)=1,"PASS","DUPLICATE") -> PASS
A7: F-WPN-003 | B7: ITM-WPN-007 | C7: DEFAULT | D7: Dm = R6_DMG+L | E7: Rn = R12_RANGE+Dm+L | F7: Rs = MAX(5,CEIL(Dm×Rn/(R20_RS+2.5×Lw))) | G7: Rd = MAX(5,CEIL(3×Rn/(Lw+R6_RD))) | H7: R6_DMG,R12_RANGE,R20_RS,R6_RD | I7: L,Lw | J7: Dm→Rn→Rs→Rd | K7: L,Lw,Ls∈Z≥0; Lw>0 там, где является делителем; каждое вхождение R4/R6/R12/R20 независимо; вычисленные поля переиспользуются по порядку формулы | L7: VALIDATION_ONLY | M7: =FALSE() -> FALSE | N7: BYPASS_FORMULA_BOUNDS; CORE-187/188 | O7: EXISTS one joint witness; сохранить formulaId, formulaVersion=ITEM_FORMULAS_V1.2 и весь witness | P7: =IF(COUNTIF($A$5:$A$26,A7)=1,"PASS","DUPLICATE") -> PASS
A8: F-WPN-004 | B8: ITM-WPN-008 | C8: DEFAULT | D8: Dm = R12_DMG+L | E8: Rn = R12_RANGE+Dm+L | F8: Rs = MAX(6,CEIL(Dm×Rn/(R20_RS+2×Lw))) | G8: Rd = MAX(7,CEIL(4×Rn/(Lw+R6_RD))) | H8: R12_DMG,R12_RANGE,R20_RS,R6_RD | I8: L,Lw | J8: Dm→Rn→Rs→Rd | K8: L,Lw,Ls∈Z≥0; Lw>0 там, где является делителем; каждое вхождение R4/R6/R12/R20 независимо; вычисленные поля переиспользуются по порядку формулы | L8: VALIDATION_ONLY | M8: =FALSE() -> FALSE | N8: BYPASS_FORMULA_BOUNDS; CORE-187/188 | O8: EXISTS one joint witness; сохранить formulaId, formulaVersion=ITEM_FORMULAS_V1.2 и весь witness | P8: =IF(COUNTIF($A$5:$A$26,A8)=1,"PASS","DUPLICATE") -> PASS
A9: F-WPN-005 | B9: ITM-WPN-009 | C9: DEFAULT | D9: Dm = R20_DMG+L | E9: Rn = R20_RANGE+Dm+1.5×L | F9: Rs = MAX(8,CEIL(Dm×Rn/(R20_RS+1.5×Lw))) | G9: Rd = MAX(9,CEIL(5×Rn/(Lw+R6_RD))) | H9: R20_DMG,R20_RANGE,R20_RS,R6_RD | I9: L,Lw | J9: Dm→Rn→Rs→Rd | K9: L,Lw,Ls∈Z≥0; Lw>0 там, где является делителем; каждое вхождение R4/R6/R12/R20 независимо; вычисленные поля переиспользуются по порядку формулы | L9: VALIDATION_ONLY | M9: =FALSE() -> FALSE | N9: BYPASS_FORMULA_BOUNDS; CORE-187/188 | O9: EXISTS one joint witness; сохранить formulaId, formulaVersion=ITEM_FORMULAS_V1.2 и весь witness | P9: =IF(COUNTIF($A$5:$A$26,A9)=1,"PASS","DUPLICATE") -> PASS
A10: F-WPN-006 | B10: ITM-WPN-010 | C10: DEFAULT | F10: Rs = MAX(11,CEIL((80−Lw)/(R4_RS+L))) | G10: Rd = MAX(6,CEIL((40−Lw)/(R4_RD+L))) | H10: R4_RS,R4_RD | I10: L,Lw | J10: Rs,Rd независимо по дайсам | K10: L,Lw,Ls∈Z≥0; Lw>0 там, где является делителем; каждое вхождение R4/R6/R12/R20 независимо; вычисленные поля переиспользуются по порядку формулы | L10: VALIDATION_ONLY | M10: =FALSE() -> FALSE | N10: BYPASS_FORMULA_BOUNDS; CORE-187/188 | O10: EXISTS one joint witness; сохранить formulaId, formulaVersion=ITEM_FORMULAS_V1.2 и весь witness | P10: =IF(COUNTIF($A$5:$A$26,A10)=1,"PASS","DUPLICATE") -> PASS
A11: F-WPN-007 | B11: ITM-WPN-011 | C11: DEFAULT | F11: Rs = MAX(9,CEIL((80−(Lw+Ls)/2)/(R6_RS+L))) | G11: Rd = MAX(9,CEIL((80−(Lw+Ls)/2)/(R6_RD+L))) | H11: R6_RS,R6_RD | I11: L,Lw,Ls | J11: Rs,Rd независимо по дайсам | K11: L,Lw,Ls∈Z≥0; Lw>0 там, где является делителем; каждое вхождение R4/R6/R12/R20 независимо; вычисленные поля переиспользуются по порядку формулы | L11: VALIDATION_ONLY | M11: =FALSE() -> FALSE | N11: BYPASS_FORMULA_BOUNDS; CORE-187/188 | O11: EXISTS one joint witness; сохранить formulaId, formulaVersion=ITEM_FORMULAS_V1.2 и весь witness | P11: =IF(COUNTIF($A$5:$A$26,A11)=1,"PASS","DUPLICATE") -> PASS
A12: F-WPN-008A | B12: ITM-WPN-012 | C12: ONE_HAND | F12: Rs = MAX(13,CEIL((100−(Lw+Ls)/2)/(R4_RS+L))) | G12: Rd = MAX(9,CEIL((50−(Lw+Ls)/2)/(R4_RD+L))) | H12: R4_RS,R4_RD | I12: L,Lw,Ls | J12: Хват фиксируется | K12: L,Lw,Ls∈Z≥0; Lw>0 там, где является делителем; каждое вхождение R4/R6/R12/R20 независимо; вычисленные поля переиспользуются по порядку формулы | L12: VALIDATION_ONLY | M12: =FALSE() -> FALSE | N12: BYPASS_FORMULA_BOUNDS; CORE-187/188 | O12: EXISTS one joint witness; сохранить formulaId, formulaVersion=ITEM_FORMULAS_V1.2 и весь witness | P12: =IF(COUNTIF($A$5:$A$26,A12)=1,"PASS","DUPLICATE") -> PASS
A13: F-WPN-008B | B13: ITM-WPN-012 | C13: TWO_HAND | F13: Rs = MAX(9,CEIL((60−(Lw+Ls)/2)/(R4_RS+L))) | G13: Rd = MAX(9,CEIL((50−(Lw+Ls)/2)/(R4_RD+L))) | H13: R4_RS,R4_RD | I13: L,Lw,Ls | J13: Хват фиксируется | K13: L,Lw,Ls∈Z≥0; Lw>0 там, где является делителем; каждое вхождение R4/R6/R12/R20 независимо; вычисленные поля переиспользуются по порядку формулы | L13: VALIDATION_ONLY | M13: =FALSE() -> FALSE | N13: BYPASS_FORMULA_BOUNDS; CORE-187/188 | O13: EXISTS one joint witness; сохранить formulaId, formulaVersion=ITEM_FORMULAS_V1.2 и весь witness | P13: =IF(COUNTIF($A$5:$A$26,A13)=1,"PASS","DUPLICATE") -> PASS
A14: F-WPN-009 | B14: ITM-WPN-013 | C14: DEFAULT | F14: Rs = MAX(12,CEIL((100−(Lw+Ls)/2)/(R4_RS+L))) | G14: Rd = MAX(9,CEIL((80−(Lw+Ls)/2)/(R6_RD+L))) | H14: R4_RS,R6_RD | I14: L,Lw,Ls | K14: L,Lw,Ls∈Z≥0; Lw>0 там, где является делителем; каждое вхождение R4/R6/R12/R20 независимо; вычисленные поля переиспользуются по порядку формулы | L14: VALIDATION_ONLY | M14: =FALSE() -> FALSE | N14: BYPASS_FORMULA_BOUNDS; CORE-187/188 | O14: EXISTS one joint witness; сохранить formulaId, formulaVersion=ITEM_FORMULAS_V1.2 и весь witness | P14: =IF(COUNTIF($A$5:$A$26,A14)=1,"PASS","DUPLICATE") -> PASS
A15: F-WPN-010 | B15: ITM-WPN-014 | C15: DEFAULT | F15: Rs = MAX(5,CEIL((50−(Lw+Ls)/2)/(R6_RS+L))) | G15: Rd = MAX(12,CEIL((100−(Lw+Ls)/2)/(R4_RD+L))) | H15: R6_RS,R4_RD | I15: L,Lw,Ls | K15: L,Lw,Ls∈Z≥0; Lw>0 там, где является делителем; каждое вхождение R4/R6/R12/R20 независимо; вычисленные поля переиспользуются по порядку формулы | L15: VALIDATION_ONLY | M15: =FALSE() -> FALSE | N15: BYPASS_FORMULA_BOUNDS; CORE-187/188 | O15: EXISTS one joint witness; сохранить formulaId, formulaVersion=ITEM_FORMULAS_V1.2 и весь witness | P15: =IF(COUNTIF($A$5:$A$26,A15)=1,"PASS","DUPLICATE") -> PASS
A16: F-WPN-011 | B16: ITM-WPN-015 | C16: DEFAULT | F16: Rs = MAX(7,CEIL((70−(Lw+Ls)/2)/(R6_RS+L))) | G16: Rd = MAX(6,CEIL((70−(Lw+Ls)/2)/(R6_RD+L))) | H16: R6_RS,R6_RD | I16: L,Lw,Ls | K16: L,Lw,Ls∈Z≥0; Lw>0 там, где является делителем; каждое вхождение R4/R6/R12/R20 независимо; вычисленные поля переиспользуются по порядку формулы | L16: VALIDATION_ONLY | M16: =FALSE() -> FALSE | N16: BYPASS_FORMULA_BOUNDS; CORE-187/188 | O16: EXISTS one joint witness; сохранить formulaId, formulaVersion=ITEM_FORMULAS_V1.2 и весь witness | P16: =IF(COUNTIF($A$5:$A$26,A16)=1,"PASS","DUPLICATE") -> PASS
A17: F-WPN-012 | B17: ITM-WPN-016 | C17: DEFAULT | F17: Rs = MAX(6,CEIL((50−(Lw+Ls)/2)/(R6_RS+L))) | G17: Rd = MAX(11,CEIL((80−(Lw+Ls)/2)/(R4_RD+L))) | H17: R6_RS,R4_RD | I17: L,Lw,Ls | K17: L,Lw,Ls∈Z≥0; Lw>0 там, где является делителем; каждое вхождение R4/R6/R12/R20 независимо; вычисленные поля переиспользуются по порядку формулы | L17: VALIDATION_ONLY | M17: =FALSE() -> FALSE | N17: BYPASS_FORMULA_BOUNDS; CORE-187/188 | O17: EXISTS one joint witness; сохранить formulaId, formulaVersion=ITEM_FORMULAS_V1.2 и весь witness | P17: =IF(COUNTIF($A$5:$A$26,A17)=1,"PASS","DUPLICATE") -> PASS
A18: F-WPN-013 | B18: ITM-WPN-017 | C18: DEFAULT | F18: Rs = MAX(7,CEIL((60−(Lw+Ls)/2)/(R6_RS+L))) | G18: Rd = MAX(11,CEIL((80−(Lw+Ls)/2)/(R4_RD+L))) | H18: R6_RS,R4_RD | I18: L,Lw,Ls | K18: L,Lw,Ls∈Z≥0; Lw>0 там, где является делителем; каждое вхождение R4/R6/R12/R20 независимо; вычисленные поля переиспользуются по порядку формулы | L18: VALIDATION_ONLY | M18: =FALSE() -> FALSE | N18: BYPASS_FORMULA_BOUNDS; CORE-187/188 | O18: EXISTS one joint witness; сохранить formulaId, formulaVersion=ITEM_FORMULAS_V1.2 и весь witness | P18: =IF(COUNTIF($A$5:$A$26,A18)=1,"PASS","DUPLICATE") -> PASS
A19: F-WPN-014 | B19: ITM-WPN-018 | C19: DEFAULT | F19: Rs = MAX(10,CEIL((90−(Lw+Ls)/2)/(R6_RS+L))) | G19: Rd = MAX(9,CEIL((80−(Lw+Ls)/2)/(R6_RD+L))) | H19: R6_RS,R6_RD | I19: L,Lw,Ls | K19: L,Lw,Ls∈Z≥0; Lw>0 там, где является делителем; каждое вхождение R4/R6/R12/R20 независимо; вычисленные поля переиспользуются по порядку формулы | L19: VALIDATION_ONLY | M19: =FALSE() -> FALSE | N19: BYPASS_FORMULA_BOUNDS; CORE-187/188 | O19: EXISTS one joint witness; сохранить formulaId, formulaVersion=ITEM_FORMULAS_V1.2 и весь witness | P19: =IF(COUNTIF($A$5:$A$26,A19)=1,"PASS","DUPLICATE") -> PASS
A20: F-WPN-015 | B20: ITM-WPN-019 | C20: DEFAULT | F20: Rs = MAX(12,CEIL((100−(Lw+Ls)/2)/(R6_RS+L))) | G20: Rd = MAX(9,CEIL((90−(Lw+Ls)/2)/(R6_RD+L))) | H20: R6_RS,R6_RD | I20: L,Lw,Ls | K20: L,Lw,Ls∈Z≥0; Lw>0 там, где является делителем; каждое вхождение R4/R6/R12/R20 независимо; вычисленные поля переиспользуются по порядку формулы | L20: VALIDATION_ONLY | M20: =FALSE() -> FALSE | N20: BYPASS_FORMULA_BOUNDS; CORE-187/188 | O20: EXISTS one joint witness; сохранить formulaId, formulaVersion=ITEM_FORMULAS_V1.2 и весь witness | P20: =IF(COUNTIF($A$5:$A$26,A20)=1,"PASS","DUPLICATE") -> PASS
A21: F-WPN-016 | B21: ITM-WPN-020 | C21: DEFAULT | F21: Rs = MAX(14,CEIL((100−(Lw+Ls)/2)/(R4_RS+L))) | G21: Rd = MAX(9,CEIL((80−(Lw+Ls)/2)/(R4_RD+L))) | H21: R4_RS,R4_RD | I21: L,Lw,Ls | K21: L,Lw,Ls∈Z≥0; Lw>0 там, где является делителем; каждое вхождение R4/R6/R12/R20 независимо; вычисленные поля переиспользуются по порядку формулы | L21: VALIDATION_ONLY | M21: =FALSE() -> FALSE | N21: BYPASS_FORMULA_BOUNDS; CORE-187/188 | O21: EXISTS one joint witness; сохранить formulaId, formulaVersion=ITEM_FORMULAS_V1.2 и весь witness | P21: =IF(COUNTIF($A$5:$A$26,A21)=1,"PASS","DUPLICATE") -> PASS
A22: F-WPN-017 | B22: ITM-WPN-021 | C22: DEFAULT | F22: Rs = MAX(9,CEIL((60−(Lw+Ls)/2)/(R4_RS+L))) | G22: Rd = MAX(12,CEIL((80−(Lw+Ls)/2)/(R4_RD+L))) | H22: R4_RS,R4_RD | I22: L,Lw,Ls | K22: L,Lw,Ls∈Z≥0; Lw>0 там, где является делителем; каждое вхождение R4/R6/R12/R20 независимо; вычисленные поля переиспользуются по порядку формулы | L22: VALIDATION_ONLY | M22: =FALSE() -> FALSE | N22: BYPASS_FORMULA_BOUNDS; CORE-187/188 | O22: EXISTS one joint witness; сохранить formulaId, formulaVersion=ITEM_FORMULAS_V1.2 и весь witness | P22: =IF(COUNTIF($A$5:$A$26,A22)=1,"PASS","DUPLICATE") -> PASS
A23: F-WPN-018 | B23: ITM-WPN-022 | C23: DEFAULT | F23: Rs = MAX(10,CEIL((90−Lw)/(R6_RS+L))) | G23: Rd = MAX(9,CEIL((80−Lw)/(R6_RD+L))) | H23: R6_RS,R6_RD | I23: L,Lw | K23: L,Lw,Ls∈Z≥0; Lw>0 там, где является делителем; каждое вхождение R4/R6/R12/R20 независимо; вычисленные поля переиспользуются по порядку формулы | L23: VALIDATION_ONLY | M23: =FALSE() -> FALSE | N23: BYPASS_FORMULA_BOUNDS; CORE-187/188 | O23: EXISTS one joint witness; сохранить formulaId, formulaVersion=ITEM_FORMULAS_V1.2 и весь witness | P23: =IF(COUNTIF($A$5:$A$26,A23)=1,"PASS","DUPLICATE") -> PASS
A24: F-WPN-019 | B24: ITM-WPN-023 | C24: DEFAULT | F24: Rs = MAX(12,CEIL((100−(Lw+Ls)/2)/(R4_RS+L))) | G24: Rd = MAX(9,CEIL((80−(Lw+Ls)/2)/(R6_RD+L))) | H24: R4_RS,R6_RD | I24: L,Lw,Ls | K24: L,Lw,Ls∈Z≥0; Lw>0 там, где является делителем; каждое вхождение R4/R6/R12/R20 независимо; вычисленные поля переиспользуются по порядку формулы | L24: VALIDATION_ONLY | M24: =FALSE() -> FALSE | N24: BYPASS_FORMULA_BOUNDS; CORE-187/188 | O24: EXISTS one joint witness; сохранить formulaId, formulaVersion=ITEM_FORMULAS_V1.2 и весь witness | P24: =IF(COUNTIF($A$5:$A$26,A24)=1,"PASS","DUPLICATE") -> PASS
A25: F-WPN-020 | B25: ITM-WPN-024 | C25: DEFAULT | F25: Rs = MAX(11,CEIL((100−Lw)/(R4_RS+L))) | G25: Rd = MAX(9,CEIL((80−Lw)/(R6_RD+L))) | H25: R4_RS,R6_RD | I25: L,Lw | K25: L,Lw,Ls∈Z≥0; Lw>0 там, где является делителем; каждое вхождение R4/R6/R12/R20 независимо; вычисленные поля переиспользуются по порядку формулы | L25: VALIDATION_ONLY | M25: =FALSE() -> FALSE | N25: BYPASS_FORMULA_BOUNDS; CORE-187/188 | O25: EXISTS one joint witness; сохранить formulaId, formulaVersion=ITEM_FORMULAS_V1.2 и весь witness | P25: =IF(COUNTIF($A$5:$A$26,A25)=1,"PASS","DUPLICATE") -> PASS
A26: F-WPN-021 | B26: ITM-WPN-025 | C26: DEFAULT | F26: Rs = MAX(14,CEIL((120−Lw)/(R4_RS+L))) | G26: Rd = MAX(9,CEIL((80−Lw)/(R6_RD+L))) | H26: R4_RS,R6_RD | I26: L,Lw | K26: L,Lw,Ls∈Z≥0; Lw>0 там, где является делителем; каждое вхождение R4/R6/R12/R20 независимо; вычисленные поля переиспользуются по порядку формулы | L26: VALIDATION_ONLY | M26: =FALSE() -> FALSE | N26: BYPASS_FORMULA_BOUNDS; CORE-187/188 | O26: EXISTS one joint witness; сохранить formulaId, formulaVersion=ITEM_FORMULAS_V1.2 и весь witness | P26: =IF(COUNTIF($A$5:$A$26,A26)=1,"PASS","DUPLICATE") -> PASS

Sheet 06_Диапазоны
A1: Необходимые диапазоны для быстрого pre-check
A2: Только быстрый отсев для PLAYER_FORMULA_VALIDATED. PASS по min/max не заменяет joint witness. Границы рассчитаны для L/Lw/Ls∈Z≥0 и Lw>0 при делении; MASTER_OVERRIDE полностью их обходит.
A4: FormulaID | B4: ItemTypeID | C4: Вариант | D4: Dm min | E4: Dm max | F4: Rn min | G4: Rn max | H4: Rs min | I4: Rs max | J4: Rd min | K4: Rd max | L4: Шаг Rn | M4: Интерпретация
A5: F-WPN-001 | B5: ITM-WPN-001 | C5: DEFAULT | D5: 1 | E5: ∞ | F5: 2 | G5: ∞ | H5: 1 | I5: ∞ | J5: 1 | K5: ∞ | L5: 1 | M5: Необходимые границы при CORE-185; joint witness обязателен
A6: F-WPN-002 | B6: ITM-WPN-002 | C6: DEFAULT | D6: 1 | E6: ∞ | F6: 2 | G6: ∞ | H6: 1 | I6: ∞ | J6: 1 | K6: ∞ | L6: 1 | M6: Необходимые границы при CORE-185; joint witness обязателен
A7: F-WPN-003 | B7: ITM-WPN-007 | C7: DEFAULT | D7: 1 | E7: ∞ | F7: 2 | G7: ∞ | H7: 5 | I7: ∞ | J7: 5 | K7: ∞ | L7: 1 | M7: Необходимые границы при CORE-185; joint witness обязателен
A8: F-WPN-004 | B8: ITM-WPN-008 | C8: DEFAULT | D8: 1 | E8: ∞ | F8: 2 | G8: ∞ | H8: 6 | I8: ∞ | J8: 7 | K8: ∞ | L8: 1 | M8: Необходимые границы при CORE-185; joint witness обязателен
A9: F-WPN-005 | B9: ITM-WPN-009 | C9: DEFAULT | D9: 1 | E9: ∞ | F9: 2 | G9: ∞ | H9: 8 | I9: ∞ | J9: 9 | K9: ∞ | L9: 0.5 | M9: Необходимые границы при CORE-185; Rn имеет шаг 0,5; joint witness обязателен
A10: F-WPN-006 | B10: ITM-WPN-010 | C10: DEFAULT | H10: 11 | I10: 80 | J10: 6 | K10: 40 | L10: 1 | M10: Необходимый прямоугольник при CORE-185; пара Rs/Rd проверяется одной формулой
A11: F-WPN-007 | B11: ITM-WPN-011 | C11: DEFAULT | H11: 9 | I11: 80 | J11: 9 | K11: 80 | L11: 1 | M11: Необходимый прямоугольник при CORE-185; пара Rs/Rd проверяется одной формулой
A12: F-WPN-008A | B12: ITM-WPN-012 | C12: ONE_HAND | H12: 13 | I12: 100 | J12: 9 | K12: 50 | L12: 1 | M12: Необходимый прямоугольник при CORE-185; пара Rs/Rd проверяется одной формулой
A13: F-WPN-008B | B13: ITM-WPN-012 | C13: TWO_HAND | H13: 9 | I13: 60 | J13: 9 | K13: 50 | L13: 1 | M13: Необходимый прямоугольник при CORE-185; пара Rs/Rd проверяется одной формулой
A14: F-WPN-009 | B14: ITM-WPN-013 | C14: DEFAULT | H14: 12 | I14: 100 | J14: 9 | K14: 80 | L14: 1 | M14: Необходимый прямоугольник при CORE-185; пара Rs/Rd проверяется одной формулой
A15: F-WPN-010 | B15: ITM-WPN-014 | C15: DEFAULT | H15: 5 | I15: 50 | J15: 12 | K15: 100 | L15: 1 | M15: Необходимый прямоугольник при CORE-185; пара Rs/Rd проверяется одной формулой
A16: F-WPN-011 | B16: ITM-WPN-015 | C16: DEFAULT | H16: 7 | I16: 70 | J16: 6 | K16: 70 | L16: 1 | M16: Необходимый прямоугольник при CORE-185; пара Rs/Rd проверяется одной формулой
A17: F-WPN-012 | B17: ITM-WPN-016 | C17: DEFAULT | H17: 6 | I17: 50 | J17: 11 | K17: 80 | L17: 1 | M17: Необходимый прямоугольник при CORE-185; пара Rs/Rd проверяется одной формулой
A18: F-WPN-013 | B18: ITM-WPN-017 | C18: DEFAULT | H18: 7 | I18: 60 | J18: 11 | K18: 80 | L18: 1 | M18: Необходимый прямоугольник при CORE-185; пара Rs/Rd проверяется одной формулой
A19: F-WPN-014 | B19: ITM-WPN-018 | C19: DEFAULT | H19: 10 | I19: 90 | J19: 9 | K19: 80 | L19: 1 | M19: Необходимый прямоугольник при CORE-185; пара Rs/Rd проверяется одной формулой
A20: F-WPN-015 | B20: ITM-WPN-019 | C20: DEFAULT | H20: 12 | I20: 100 | J20: 9 | K20: 90 | L20: 1 | M20: Необходимый прямоугольник при CORE-185; пара Rs/Rd проверяется одной формулой
A21: F-WPN-016 | B21: ITM-WPN-020 | C21: DEFAULT | H21: 14 | I21: 100 | J21: 9 | K21: 80 | L21: 1 | M21: Необходимый прямоугольник при CORE-185; пара Rs/Rd проверяется одной формулой
... A26: F-WPN-021 | B26: ITM-WPN-025 | C26: DEFAULT | H26: 14 | I26: 120 | J26: 9 | K26: 80 | L26: 1 | M26: Необходимый прямоугольник при CORE-185; пара Rs/Rd проверяется одной формулой

Sheet 07_Модель_экземпляра
A1: Контракт физического экземпляра предмета
A2: ItemInstance хранит владение и физическое состояние. Числовой профиль оружия вынесен в неизменяемые WeaponProfileVersion на 07B; instanceDamage не является результатом боевого броска, instancePenetration не существует.
A4: Field | B4: Scope | C4: Data type | D4: Required | E4: Default | F4: Validation / constraint | G4: Purpose
A5: itemInstanceId | B5: ITEM_INSTANCE | C5: UUID | D5: =TRUE() -> TRUE | E5: — | F5: Уникален; неизменяем | G5: Идентичность физического экземпляра
A6: itemTypeId | B6: ITEM_INSTANCE | C6: ID | D6: =TRUE() -> TRUE | E6: — | F6: FK → 01_Каталог.ItemTypeID; после создания экземпляра не изменяется | G6: Канонический механический тип
A7: activeWeaponProfileVersionIdByVariant | B7: ITEM_INSTANCE | C7: MAP<ATTACK_VARIANT,UUID> | D7: CONDITIONAL | E7: {} | F7: Обязательно для оружия; DEFAULT для обычного, ONE_HAND/TWO_HAND для полуторного, SWORD/SHIELD/RAPIER для составного; FK → 07B | G7: Активные версии эффективного профиля
A8: massKg | B8: TEMPLATE_OR_INSTANCE | C8: DECIMAL | D8: =FALSE() -> FALSE | F8: Конечное число ≥0; если не задано в PDF — ввод мастера | G8: Метание, переносимый груз и будущая нагрузка
A9: heldSizeClass | B9: TEMPLATE_OR_INSTANCE | C9: ENUM | D9: =FALSE() -> FALSE | E9: UNKNOWN | F9: FITS_IN_FIST | LARGE | UNKNOWN | G9: Взаимодействия удержания
A10: armorWeightClass | B10: TEMPLATE | C10: ENUM | D10: =FALSE() -> FALSE | E10: UNKNOWN | F10: LIGHT | OTHER | UNKNOWN | G10: Эффекты лёгкой брони
A11: flammability | B11: TEMPLATE_OR_INSTANCE | C11: ENUM | D11: =FALSE() -> FALSE | E11: UNKNOWN | F11: COMBUSTIBLE | NONCOMBUSTIBLE | UNKNOWN | G11: Явные эффекты; предметное горение не автоматизируется
A12: isIgnitionSource | B12: TEMPLATE | C12: BOOLEAN | D12: =FALSE() -> FALSE | E12: =FALSE() -> FALSE | F12: Огниво=true; custom item — по решению мастера | G12: Воспламенение покрытия
