Workbook

Sheet 00_Паспорт
A1: SYMBIOSIS V7 — Character, Skills & Symbionts Registry v1.2
A2: Дополняющий нормативный реестр персонажей, навыков, симбионтов, обычного XP и неизменяемого мастерского GM_DIRECT. Frozen runtime pack v1.2 принимается по version+SHA через forward compatibility.
A5: Метрика | B5: Значение | C5: Проверка | D5: Примечание | F5: Source priority и scope
A6: Версия | B6: 1.2 | C6: PASS | D6: SYMBIOSIS_CHARACTER_SKILLS_SYMBIONTS_V1.2 | F6: Приоритет: решения 2026-08-01 > v1.2 extension > v1.1 builtAgainst. Current tuple: Rules v1.7 | Character-Skills-Symbionts v1.2 | Items v1.6_with_icons | Bestiary v1.4 | Sentient v1.2.
A7: Дата выпуска | B7: 2026-08-01 | C7: PASS | D7: Europe/Berlin
A8: Характеристики | B8: =COUNTA('01_Характеристики'!$A$6:$A$12) -> 7 | C8: =IF(B8=7,"PASS","FAIL") -> PASS | D8: Ожидается 7
A9: Расы | B9: =COUNTA('02_Расы'!$A$6:$A$8) -> 3 | C9: =IF(B9=3,"PASS","FAIL") -> PASS | D9: Ожидается 3
A10: Классы | B10: =COUNTA('03_Классы'!$A$6:$A$8) -> 3 | C10: =IF(B10=3,"PASS","FAIL") -> PASS | D10: Ожидается 3
A11: Навыки | B11: =COUNTA('04_Навыки'!$B$6:$B$50) -> 45 | C11: =IF(B11=45,"PASS","FAIL") -> PASS | D11: Ожидается 45
A12: Симбионты | B12: =COUNTA('07_Симбионты'!$A$6:$A$28) -> 23 | C12: =IF(B12=23,"PASS","FAIL") -> PASS | D12: Ожидается 23
A13: Узлы развития | B13: =COUNTA('09_Узлы_развития'!$A$6:$A$187) -> 182 | C13: =IF(B13=182,"PASS","FAIL") -> PASS | D13: Ожидается 182 | F13: Manifest integration
A14: Автоматизируемые способности | B14: =COUNTA('10_Способности'!$A$6:$A$172) -> 167 | C14: =IF(B14=167,"PASS","FAIL") -> PASS | D14: Ожидается 167 | F14: Реестр является пятым нормативным артефактом Development Baseline Manifest v1.1. Все payload обязаны содержать точный dependencyTuple v1.1.
A15: Контексты | B15: =COUNTA('11_Контексты_способностей'!$A$6:$A$339) -> 334 | C15: =IF(B15=334,"PASS","FAIL") -> PASS | D15: Ожидается 334
A16: Manual-only узлы | B16: =COUNTIF('09_Узлы_развития'!$K$6:$K$187,"NODE_ONLY_MANUAL") -> 15 | C16: =IF(B16=15,"PASS","FAIL") -> PASS | D16: Ожидается 15; без поведения
A17: GeneratedObjectType | B17: =COUNTA('13_Генерируемые_объекты'!$A$6) -> 1 | C17: =IF(B17=1,"PASS","FAIL") -> PASS | D17: Ожидается 1: WEB_ITEM
A18: QA сценарии | B18: =COUNTA('21_QA_совместимость'!$A$6:$A$56) -> 51 | C18: =IF(B18=51,"PASS","FAIL") -> PASS | D18: Ожидается 51: сохранены 42 + 8 GM_DIRECT + 1 group generator
A19: Программные проверки | B19: 60 | C19: =IF(B19=60,"PASS","FAIL") -> PASS | D19: Builder semantic and structural gate
A20: Payload | B20: 1144 | C20: =IF(B20=1144,"PASS","FAIL") -> PASS | D20: 1 142 builtAgainst payload + 2 forward-compatible operation payload
A21: Release gate | B21: =IF(COUNTIF('21_QA_совместимость'!$G$6:$G$56,"FAIL")+COUNTIF('22_Контроль'!$D$6:$D$53,"FAIL")=0,"PASS","FAIL") -> PASS | C21: =IF(B21="PASS","PASS","FAIL") -> PASS | D21: PASS только при нуле FAIL
A22: Связи SpeciesKey ↔ LinkedStatCode | B22: =COUNTA('07_Симбионты'!$A$35:$A$82) -> 48 | C22: =IF(B22=48,"PASS","FAIL") -> PASS | D22: 23 вида, 48 отношений, дословно извлечённых из профильных карточек Rules v1.6
A23: XP policy rows | B23: 36 | C23: =IF(B23=36,"PASS","FAIL") -> PASS | D23: 3 route + 7 points + 11 roll kinds + 8 never + 3 race + 3 suppression + 1 GM_DIRECT = 36
A24: SymbiontXpEvent fields | B24: 19 | C24: =IF(B24=19,"PASS","FAIL") -> PASS | D24: Все обязательные поля события
A25: GM direct award policy | B25: 1 | C25: =IF(B25=1,"PASS","FAIL") -> PASS | D25: GM_DIRECT_SYMBIONT_XP | F25: Q-GM-XP-001
A26: MasterSymbiontXpAward fields | B26: 11 | C26: =IF(B26=11,"PASS","FAIL") -> PASS | D26: Полный immutable receipt contract | F26: CORE-234

Sheet 01_Характеристики
A1: Канонические характеристики персонажа
A2: Семь кодов без aliases. Для Z/W используются специфичные исполняемые карточки Rules v1.5; M канонически означает «Метаболизм».
A5: StatCode | B5: Название | C5: Порядок | D5: Domain | E5: BaseMin | F5: BaseMax игрока | G5: EffectiveMin | H5: Cap35Scope | I5: Описание | J5: Rule IDs | K5: Источник | L5: ID unique
A6: S | B6: Сила | C6: 1 | D6: BASE_CHARACTERISTIC | E6: 1 | F6: 20 | G6: 1 | H6: SENTIENT_BASE_ONLY | I6: Игрок: базовое значение 1..20. Мыслящий противник: базовое значение 1..35. Постоянные и временные изменения применяются послойно; итог не ниже 1. | J6: CORE-073; CORE-078; CORE-079; CORE-160; CORE-197 | K6: Rules v1.5; при внутреннем конфликте — более специфичная карточка правила | L6: =COUNTIF($A$6:$A$12,A6) -> 1
A7: D | B7: Ловкость | C7: 2 | D7: BASE_CHARACTERISTIC | E7: 1 | F7: 20 | G7: 1 | H7: SENTIENT_BASE_ONLY | I7: Игрок: базовое значение 1..20. Мыслящий противник: базовое значение 1..35. Постоянные и временные изменения применяются послойно; итог не ниже 1. | J7: CORE-073; CORE-078; CORE-079; CORE-160; CORE-197 | K7: Rules v1.5; при внутреннем конфликте — более специфичная карточка правила | L7: =COUNTIF($A$6:$A$12,A7) -> 1
A8: M | B8: Метаболизм | C8: 3 | D8: BASE_CHARACTERISTIC | E8: 1 | F8: 20 | G8: 1 | H8: SENTIENT_BASE_ONLY | I8: Игрок: базовое значение 1..20. Мыслящий противник: базовое значение 1..35. Постоянные и временные изменения применяются послойно; итог не ниже 1. The higher-priority Rules!Справочники C140 explicitly says «Метаболизм». The lower-priority fallback PDF uses «Выносливость (M)», so the Rules value prevails under the user's stated source-priority rule. | J8: CORE-073; CORE-078; CORE-079; CORE-160; CORE-197 | K8: Rules v1.5; при внутреннем конфликте — более специфичная карточка правила | L8: =COUNTIF($A$6:$A$12,A8) -> 1
A9: Z | B9: Здоровье | C9: 4 | D9: BASE_CHARACTERISTIC | E9: 1 | F9: 20 | G9: 1 | H9: SENTIENT_BASE_ONLY | I9: Игрок: базовое значение 1..20. Мыслящий противник: базовое значение 1..35. Постоянные и временные изменения применяются послойно; итог не ниже 1. Rules!Справочники C141 says «Знания», but CORE-031, CORE-117, CORE-119 and Q-CORE-008 consistently use Z as «Здоровье»; the approved fallback PDF explicitly uses «Здоровье (Z)». | J9: CORE-031; CORE-073; CORE-078; CORE-079; CORE-160; CORE-197 | K9: Rules v1.5; при внутреннем конфликте — более специфичная карточка правила | L9: =COUNTIF($A$6:$A$12,A9) -> 1
A10: I | B10: Интеллект | C10: 5 | D10: BASE_CHARACTERISTIC | E10: 1 | F10: 20 | G10: 1 | H10: SENTIENT_BASE_ONLY | I10: Игрок: базовое значение 1..20. Мыслящий противник: базовое значение 1..35. Постоянные и временные изменения применяются послойно; итог не ниже 1. | J10: CORE-073; CORE-078; CORE-079; CORE-160; CORE-197 | K10: Rules v1.5; при внутреннем конфликте — более специфичная карточка правила | L10: =COUNTIF($A$6:$A$12,A10) -> 1
A11: W | B11: Мудрость | C11: 6 | D11: BASE_CHARACTERISTIC | E11: 1 | F11: 20 | G11: 1 | H11: SENTIENT_BASE_ONLY | I11: Игрок: базовое значение 1..20. Мыслящий противник: базовое значение 1..35. Постоянные и временные изменения применяются послойно; итог не ниже 1. Rules!Справочники C143 says «Воля», but the higher-priority CORE-081 card is titled «Слоты навыков от Мудрости» and the approved fallback PDF explicitly uses «Мудрость (W)» on physical page 105. | J11: CORE-073; CORE-078; CORE-079; CORE-081; CORE-160; CORE-197 | K11: Rules v1.5; при внутреннем конфликте — более специфичная карточка правила | L11: =COUNTIF($A$6:$A$12,A11) -> 1
A12: C | B12: Харизма | C12: 7 | D12: BASE_CHARACTERISTIC | E12: 1 | F12: 20 | G12: 1 | H12: SENTIENT_BASE_ONLY | I12: Игрок: базовое значение 1..20. Мыслящий противник: базовое значение 1..35. Постоянные и временные изменения применяются послойно; итог не ниже 1. | J12: CORE-073; CORE-078; CORE-079; CORE-160; CORE-197 | K12: Rules v1.5; при внутреннем конфликте — более специфичная карточка правила | L12: =COUNTIF($A$6:$A$12,A12) -> 1

Sheet 02_Расы
A1: Игровые расы
A2: Только PURE, FREE и UNITED. Множители XP заданы явно: баллы общего счётчика не удваиваются; у FREE прямое и распределённое начисление ×2.
A5: RaceCode | B5: Название | C5: ClassPolicy | D5: BaseSymbiontSlots | E5: SymbioticMonsterAllowed | F5: StatModifierProfileID | G5: GrantedSkillRefs | H5: SymbiontXPPolicy | I5: Creation Rule IDs | J5: Источник | K5: Status | L5: ID unique | M5: DirectXPMultiplier | N5: CounterPointMultiplier | O5: AllocationXPMultiplier
A6: PURE | B6: Чистый | C6: REQUIRED_PURE_CLASS | D6: 0 | E6: =FALSE() -> FALSE | F6: RACE-MOD-PURE | H6: STANDARD_XP_AWARD | I6: CORE-008; CORE-009; CORE-010; CORE-013 | J6: Rules Registry v1.5 | K6: ACTIVE | L6: =COUNTIF($A$6:$A$8,A6) -> 1 | M6: 1 | N6: 1 | O6: 1
A7: FREE | B7: Вольный | C7: NO_CLASS | D7: 1 | E7: =FALSE() -> FALSE | F7: RACE-MOD-FREE | H7: XP_AWARD_X2 | I7: CORE-006; CORE-007 | J7: Rules Registry v1.5 | K7: ACTIVE | L7: =COUNTIF($A$6:$A$8,A7) -> 1 | M7: 2 | N7: 1 | O7: 2
A8: UNITED | B8: Единый | C8: NO_CLASS | D8: 4 | E8: =TRUE() -> TRUE | F8: RACE-MOD-UNITED | G8: FOLLOWING_PAIN | H8: STANDARD_XP_AWARD | I8: CORE-001; CORE-004; CORE-005 | J8: Rules Registry v1.5 | K8: ACTIVE | L8: =COUNTIF($A$6:$A$8,A8) -> 1 | M8: 1 | N8: 1 | O8: 1

Sheet 03_Классы
A1: Классы Чистых
A2: Класс обязателен только для PURE; обязательный классовый навык резервирует один стартовый слот.
A5: ClassCode | B5: RaceCode | C5: Название | D5: MandatorySkillKey | E5: MandatorySkillSlotCost | F5: StatModifierProfileID | G5: ContextModifierRefs | H5: Rule IDs | I5: Источник | J5: Status | K5: ID unique
A6: SEEKER | B6: PURE | C6: Искатель | D6: PURE_SEEKER | E6: 1 | F6: CLASS-MOD-SEEKER | G6: CLASS-MOD-SEEKER-C-VS-PURE; CLASS-MOD-SEEKER-C-VS-UNITED | H6: CORE-009 | I6: Rules Registry v1.5 | J6: ACTIVE | K6: =COUNTIF($A$6:$A$8,A6) -> 1
A7: STALKER | B7: PURE | C7: Сталкер | D7: PURE_STALKER | E7: 1 | F7: CLASS-MOD-STALKER | G7: CLASS-MOD-STALKER-C-VS-PURE; CLASS-MOD-STALKER-C-VS-UNITED | H7: CORE-010 | I7: Rules Registry v1.5 | J7: ACTIVE | K7: =COUNTIF($A$6:$A$8,A7) -> 1
A8: SOLDIER | B8: PURE | C8: Солдат | D8: PURE_SOLDIER | E8: 1 | F8: CLASS-MOD-SOLDIER | G8: CLASS-MOD-SOLDIER-C-VS-PURE; CLASS-MOD-SOLDIER-C-VS-UNITED | H8: CORE-013 | I8: Rules Registry v1.5 | J8: ACTIVE | K8: =COUNTIF($A$6:$A$8,A8) -> 1

Sheet 04_Навыки
A1: Системный каталог навыков
A2: 41 выбираемый навык + 4 фиксированных. Существующие 15 runtime-ключей Sentient v1.1 сохранены; остальные 30 получают новые стабильные ключи этого реестра.
A5: SkillID | B5: SkillKey | C5: Название | D5: Категория | E5: OwnerScopeAllowed | F5: SlotCostMode | G5: BonusDomain / Scope | H5: MaxBonus | I5: CheckTags | J5: MandatoryRace | K5: MandatoryClass | L5: MissingSkillPenalty | M5: Rule IDs | N5: Source Question IDs | O5: Status | P5: ID unique
A6: SKL-001 | B6: UNARMED | C6: Рукопашный бой | D6: SELECTABLE_GENERAL | E6: PLAYER_HOST; SENTIENT_HOST; ADVISER_IF_GRANTED | F6: BONUS_LEVEL_FORMULA_CORE-165 | G6: Удары руками/ногами, блок без щита | H6: NO_RULED_UPPER_LIMIT | I6: UNARMED | L6: -5 | M6: CORE-165; CORE-167 | N6: Q-CORE-024; Q-CORE-051 | O6: ACTIVE | P6: =COUNTIF($B$6:$B$50,B6) -> 1
A7: SKL-002 | B7: GRAPPLING | C7: Борьба | D7: SELECTABLE_GENERAL | E7: PLAYER_HOST; SENTIENT_HOST; ADVISER_IF_GRANTED | F7: BONUS_LEVEL_FORMULA_CORE-165 | G7: Борцовские приёмы | H7: NO_RULED_UPPER_LIMIT | I7: GRAPPLING | L7: -5 | M7: CORE-165; CORE-167 | N7: Q-CORE-024; Q-CORE-051 | O7: ACTIVE | P7: =COUNTIF($B$6:$B$50,B7) -> 1
A8: SKL-003 | B8: WEAPON_THROWING | C8: Метание | D8: SELECTABLE_GENERAL | E8: PLAYER_HOST; SENTIENT_HOST; ADVISER_IF_GRANTED | F8: BONUS_LEVEL_FORMULA_CORE-165 | G8: Метание оружия | H8: NO_RULED_UPPER_LIMIT | I8: WEAPON_THROWING | L8: -3 | M8: CORE-165; CORE-167 | N8: Q-CORE-024; Q-CORE-051 | O8: ACTIVE | P8: =COUNTIF($B$6:$B$50,B8) -> 1
A9: SKL-004 | B9: OBJECT_THROWING | C9: Бросание | D9: SELECTABLE_GENERAL | E9: PLAYER_HOST; SENTIENT_HOST; ADVISER_IF_GRANTED | F9: BONUS_LEVEL_FORMULA_CORE-165 | G9: Бросание предметов | H9: NO_RULED_UPPER_LIMIT | I9: OBJECT_THROWING | L9: -2 | M9: CORE-165; CORE-167 | N9: Q-CORE-024; Q-CORE-051 | O9: ACTIVE | P9: =COUNTIF($B$6:$B$50,B9) -> 1
A10: SKL-005 | B10: SHOOTING | C10: Стрельба | D10: SELECTABLE_GENERAL | E10: PLAYER_HOST; SENTIENT_HOST; ADVISER_IF_GRANTED | F10: BONUS_LEVEL_FORMULA_CORE-165 | G10: Точность атак «Стрельба» | H10: NO_RULED_UPPER_LIMIT | I10: SHOOTING | M10: CORE-165; CORE-167 | N10: Q-CORE-024; Q-CORE-051 | O10: ACTIVE | P10: =COUNTIF($B$6:$B$50,B10) -> 1
A11: SKL-006 | B11: ARCHERY | C11: Стрельба из лука | D11: SELECTABLE_GENERAL | E11: PLAYER_HOST; SENTIENT_HOST; ADVISER_IF_GRANTED | F11: BONUS_LEVEL_FORMULA_CORE-165 | G11: Точность лука | H11: NO_RULED_UPPER_LIMIT | I11: ARCHERY | L11: -5 | M11: CORE-165; CORE-167 | N11: Q-CORE-024; Q-CORE-051 | O11: ACTIVE | P11: =COUNTIF($B$6:$B$50,B11) -> 1
A12: SKL-007 | B12: GROSS | C12: Владение грубым оружием | D12: SELECTABLE_GENERAL | E12: PLAYER_HOST; SENTIENT_HOST; ADVISER_IF_GRANTED | F12: BONUS_LEVEL_FORMULA_CORE-165 | G12: Урон/точность грубого оружия и тяжёлых подручных средств | H12: NO_RULED_UPPER_LIMIT | I12: GROSS | L12: -3 | M12: CORE-165; CORE-167 | N12: Q-CORE-024; Q-CORE-051 | O12: ACTIVE | P12: =COUNTIF($B$6:$B$50,B12) -> 1
A13: SKL-008 | B13: FENCING | C13: Фехтование | D13: SELECTABLE_GENERAL | E13: PLAYER_HOST; SENTIENT_HOST; ADVISER_IF_GRANTED | F13: BONUS_LEVEL_FORMULA_CORE-165 | G13: Урон/точность длинного клинкового, парирование | H13: NO_RULED_UPPER_LIMIT | I13: FENCING | L13: -5 | M13: CORE-165; CORE-167 | N13: Q-CORE-024; Q-CORE-051 | O13: ACTIVE | P13: =COUNTIF($B$6:$B$50,B13) -> 1
A14: SKL-009 | B14: SPEAR | C14: Владение копьём | D14: SELECTABLE_GENERAL | E14: PLAYER_HOST; SENTIENT_HOST; ADVISER_IF_GRANTED | F14: BONUS_LEVEL_FORMULA_CORE-165 | G14: Урон/точность копья | H14: NO_RULED_UPPER_LIMIT | I14: SPEAR | L14: -2 | M14: CORE-165; CORE-167 | N14: Q-CORE-024; Q-CORE-051 | O14: ACTIVE | P14: =COUNTIF($B$6:$B$50,B14) -> 1
A15: SKL-010 | B15: SHORT | C15: Владение коротким оружием | D15: SELECTABLE_GENERAL | E15: PLAYER_HOST; SENTIENT_HOST; ADVISER_IF_GRANTED | F15: BONUS_LEVEL_FORMULA_CORE-165 | G15: Урон/точность короткого клинкового, его метание, сходные предметы | H15: NO_RULED_UPPER_LIMIT | I15: SHORT | L15: -5 | M15: CORE-165; CORE-167 | N15: Q-CORE-024; Q-CORE-051 | O15: ACTIVE | P15: =COUNTIF($B$6:$B$50,B15) -> 1
A16: SKL-011 | B16: AXES | C16: Владение топорами | D16: SELECTABLE_GENERAL | E16: PLAYER_HOST; SENTIENT_HOST; ADVISER_IF_GRANTED | F16: BONUS_LEVEL_FORMULA_CORE-165 | G16: Урон/точность топоров | H16: NO_RULED_UPPER_LIMIT | I16: AXES | L16: -5 | M16: CORE-165; CORE-167 | N16: Q-CORE-024; Q-CORE-051 | O16: ACTIVE | P16: =COUNTIF($B$6:$B$50,B16) -> 1
A17: SKL-012 | B17: SHIELD | C17: Владение щитом | D17: SELECTABLE_GENERAL | E17: PLAYER_HOST; SENTIENT_HOST; ADVISER_IF_GRANTED | F17: BONUS_LEVEL_FORMULA_CORE-165 | G17: Урон/точность щитом и блок щитом | H17: NO_RULED_UPPER_LIMIT | I17: SHIELD | L17: -5 | M17: CORE-165; CORE-167 | N17: Q-CORE-024; Q-CORE-051 | O17: ACTIVE | P17: =COUNTIF($B$6:$B$50,B17) -> 1
A18: SKL-013 | B18: RIDING | C18: Наездник | D18: SELECTABLE_GENERAL | E18: PLAYER_HOST; SENTIENT_HOST; ADVISER_IF_GRANTED | F18: BONUS_LEVEL_FORMULA_CORE-165 | G18: Управление скакуном; небоевое разрешение исключено | H18: NO_RULED_UPPER_LIMIT | I18: RIDING | L18: -5 | M18: CORE-165; CORE-167 | N18: Q-CORE-024; Q-CORE-051 | O18: ACTIVE | P18: =COUNTIF($B$6:$B$50,B18) -> 1
A19: SKL-014 | B19: STEALTH | C19: Скрытность | D19: SELECTABLE_GENERAL | E19: PLAYER_HOST; SENTIENT_HOST; ADVISER_IF_GRANTED | F19: BONUS_LEVEL_FORMULA_CORE-165 | G19: Маскировка, сокрытие, схроны, скрытые перемещения; разрешение исключено | H19: NO_RULED_UPPER_LIMIT | I19: STEALTH | M19: CORE-165; CORE-167 | N19: Q-CORE-024; Q-CORE-051 | O19: ACTIVE | P19: =COUNTIF($B$6:$B$50,B19) -> 1
A20: SKL-015 | B20: THIEVERY | C20: Вор | D20: SELECTABLE_GENERAL | E20: PLAYER_HOST; SENTIENT_HOST; ADVISER_IF_GRANTED | F20: BONUS_LEVEL_FORMULA_CORE-165 | G20: Кражи, замки, обыск, городская маскировка; разрешение исключено | H20: NO_RULED_UPPER_LIMIT | I20: THIEVERY | M20: CORE-165; CORE-167 | N20: Q-CORE-024; Q-CORE-051 | O20: ACTIVE | P20: =COUNTIF($B$6:$B$50,B20) -> 1
A21: SKL-016 | B21: ACROBATICS | C21: Акробатика | D21: SELECTABLE_GENERAL | E21: PLAYER_HOST; SENTIENT_HOST; ADVISER_IF_GRANTED | F21: BONUS_LEVEL_FORMULA_CORE-165 | G21: Лазание, прыжки, кувырки, сложные маршруты, паркур | H21: NO_RULED_UPPER_LIMIT | I21: ACROBATICS | M21: CORE-165; CORE-167 | N21: Q-CORE-024; Q-CORE-051 | O21: ACTIVE | P21: =COUNTIF($B$6:$B$50,B21) -> 1
A22: SKL-017 | B22: ORIENTATION | C22: Ориентирование | D22: SELECTABLE_GENERAL | E22: PLAYER_HOST; SENTIENT_HOST; ADVISER_IF_GRANTED | F22: BONUS_LEVEL_FORMULA_CORE-165 | G22: Маршрут/путь/картина вслепую; разрешение исключено | H22: NO_RULED_UPPER_LIMIT | I22: ORIENTATION | M22: CORE-165; CORE-167 | N22: Q-CORE-024; Q-CORE-051 | O22: ACTIVE | P22: =COUNTIF($B$6:$B$50,B22) -> 1
A23: SKL-018 | B23: LEARNING | C23: Ученик | D23: SELECTABLE_GENERAL | E23: PLAYER_HOST; SENTIENT_HOST; ADVISER_IF_GRANTED | F23: BONUS_LEVEL_FORMULA_CORE-165 | G23: Обучение навыку; разрешение исключено | H23: NO_RULED_UPPER_LIMIT | I23: LEARNING | M23: CORE-165; CORE-167 | N23: Q-CORE-024; Q-CORE-051 | O23: ACTIVE | P23: =COUNTIF($B$6:$B$50,B23) -> 1
A24: SKL-019 | B24: TEACHING | C24: Учитель | D24: SELECTABLE_GENERAL | E24: PLAYER_HOST; SENTIENT_HOST; ADVISER_IF_GRANTED | F24: BONUS_LEVEL_FORMULA_CORE-165 | G24: Обучение/объяснение; разрешение исключено | H24: NO_RULED_UPPER_LIMIT | I24: TEACHING | M24: CORE-165; CORE-167 | N24: Q-CORE-024; Q-CORE-051 | O24: ACTIVE | P24: =COUNTIF($B$6:$B$50,B24) -> 1
A25: SKL-020 | B25: CRAFT | C25: Крафт | D25: SELECTABLE_GENERAL | E25: PLAYER_HOST; SENTIENT_HOST; ADVISER_IF_GRANTED | F25: BONUS_LEVEL_FORMULA_CORE-165 | G25: Можно выбрать и хранить; создание предметов приложением не исполняется | H25: NO_RULED_UPPER_LIMIT | I25: CRAFT | L25: -5 | M25: CORE-165; CORE-167 | N25: Q-CORE-024; Q-CORE-051 | O25: ACTIVE | P25: =COUNTIF($B$6:$B$50,B25) -> 1
A26: SKL-021 | B26: REPAIR | C26: Ремонт | D26: SELECTABLE_GENERAL | E26: PLAYER_HOST; SENTIENT_HOST; ADVISER_IF_GRANTED | F26: BONUS_LEVEL_FORMULA_CORE-165 | G26: Ремонт | H26: NO_RULED_UPPER_LIMIT | I26: REPAIR | L26: -5 | M26: CORE-165; CORE-167 | N26: Q-CORE-024; Q-CORE-051 | O26: ACTIVE | P26: =COUNTIF($B$6:$B$50,B26) -> 1
A27: SKL-022 | B27: TRACKING | C27: Выслеживание | D27: SELECTABLE_GENERAL | E27: PLAYER_HOST; SENTIENT_HOST; ADVISER_IF_GRANTED | F27: BONUS_LEVEL_FORMULA_CORE-165 | G27: Следы/направление/обнаружение; небоевое разрешение исключено | H27: NO_RULED_UPPER_LIMIT | I27: TRACKING | M27: CORE-165; CORE-167 | N27: Q-CORE-024; Q-CORE-051 | O27: ACTIVE | P27: =COUNTIF($B$6:$B$50,B27) -> 1
A28: SKL-023 | B28: AWARENESS | C28: Внимательность | D28: SELECTABLE_GENERAL | E28: PLAYER_HOST; SENTIENT_HOST; ADVISER_IF_GRANTED | F28: BONUS_LEVEL_FORMULA_CORE-165 | G28: Сбор информации, обнаружение, память; небоевое разрешение исключено | H28: NO_RULED_UPPER_LIMIT | I28: AWARENESS | M28: CORE-165; CORE-167 | N28: Q-CORE-024; Q-CORE-051 | O28: ACTIVE | P28: =COUNTIF($B$6:$B$50,B28) -> 1
A29: SKL-024 | B29: ANALYTICAL_THINKING | C29: Аналитическое мышление | D29: SELECTABLE_GENERAL | E29: PLAYER_HOST; SENTIENT_HOST; ADVISER_IF_GRANTED | F29: BONUS_LEVEL_FORMULA_CORE-165 | G29: Анализ, упреждающий удар; социальное сопротивление исключено | H29: NO_RULED_UPPER_LIMIT | I29: ANALYTICAL_THINKING | M29: CORE-165; CORE-167 | N29: Q-CORE-024; Q-CORE-051 | O29: ACTIVE | P29: =COUNTIF($B$6:$B$50,B29) -> 1
A30: SKL-025 | B30: INVENTION | C30: Изобретательство | D30: SELECTABLE_GENERAL | E30: PLAYER_HOST; SENTIENT_HOST; ADVISER_IF_GRANTED | F30: BONUS_LEVEL_FORMULA_CORE-165 | G30: Новое/улучшение/новое применение; разрешение исключено | H30: NO_RULED_UPPER_LIMIT | I30: INVENTION | M30: CORE-165; CORE-167 | N30: Q-CORE-024; Q-CORE-051 | O30: ACTIVE | P30: =COUNTIF($B$6:$B$50,B30) -> 1
A31: SKL-026 | B31: LITERACY | C31: Письмо и чтение | D31: SELECTABLE_GENERAL | E31: PLAYER_HOST; SENTIENT_HOST; ADVISER_IF_GRANTED | F31: BONUS_LEVEL_FORMULA_CORE-165 | G31: Грамотность; Единый/Вольный с W<8 без навыка неграмотен | H31: NO_RULED_UPPER_LIMIT | I31: LITERACY | M31: CORE-165; CORE-167 | N31: Q-CORE-024; Q-CORE-051 | O31: ACTIVE | P31: =COUNTIF($B$6:$B$50,B31) -> 1
A32: SKL-027 | B32: SEDUCTION | C32: Соблазнение | D32: SELECTABLE_GENERAL | E32: PLAYER_HOST; SENTIENT_HOST; ADVISER_IF_GRANTED | F32: BONUS_LEVEL_FORMULA_CORE-165 | G32: Социальное; разрешение исключено | H32: NO_RULED_UPPER_LIMIT | I32: SEDUCTION | M32: CORE-165; CORE-167 | N32: Q-CORE-024; Q-CORE-051 | O32: ACTIVE | P32: =COUNTIF($B$6:$B$50,B32) -> 1
A33: SKL-028 | B33: DECEPTION | C33: Обман | D33: SELECTABLE_GENERAL | E33: PLAYER_HOST; SENTIENT_HOST; ADVISER_IF_GRANTED | F33: BONUS_LEVEL_FORMULA_CORE-165 | G33: Социальное; разрешение исключено | H33: NO_RULED_UPPER_LIMIT | I33: DECEPTION | M33: CORE-165; CORE-167 | N33: Q-CORE-024; Q-CORE-051 | O33: ACTIVE | P33: =COUNTIF($B$6:$B$50,B33) -> 1
A34: SKL-029 | B34: ACTING | C34: Актёрское мастерство | D34: SELECTABLE_GENERAL | E34: PLAYER_HOST; SENTIENT_HOST; ADVISER_IF_GRANTED | F34: BONUS_LEVEL_FORMULA_CORE-165 | G34: Социальное; разрешение исключено | H34: NO_RULED_UPPER_LIMIT | I34: ACTING | M34: CORE-165; CORE-167 | N34: Q-CORE-024; Q-CORE-051 | O34: ACTIVE | P34: =COUNTIF($B$6:$B$50,B34) -> 1
A35: SKL-030 | B35: BARGAINING | C35: Торг | D35: SELECTABLE_GENERAL | E35: PLAYER_HOST; SENTIENT_HOST; ADVISER_IF_GRANTED | F35: BONUS_LEVEL_FORMULA_CORE-165 | G35: Социальное; разрешение исключено | H35: NO_RULED_UPPER_LIMIT | I35: BARGAINING | M35: CORE-165; CORE-167 | N35: Q-CORE-024; Q-CORE-051 | O35: ACTIVE | P35: =COUNTIF($B$6:$B$50,B35) -> 1
A36: SKL-031 | B36: EXECUTIONER | C36: Палач | D36: SELECTABLE_GENERAL | E36: PLAYER_HOST; SENTIENT_HOST; ADVISER_IF_GRANTED | F36: BONUS_LEVEL_FORMULA_CORE-165 | G36: Запугивание/допрос/пытки/связывание; разрешение исключено | H36: NO_RULED_UPPER_LIMIT | I36: EXECUTIONER | M36: CORE-165; CORE-167 | N36: Q-CORE-024; Q-CORE-051 | O36: ACTIVE | P36: =COUNTIF($B$6:$B$50,B36) -> 1
A37: SKL-032 | B37: WILDERNESS_SURVIVAL | C37: Выживание в дикой природе | D37: SELECTABLE_GENERAL | E37: PLAYER_HOST; SENTIENT_HOST; ADVISER_IF_GRANTED | F37: BONUS_LEVEL_FORMULA_CORE-165 | G37: Небоевые действия/маскировка; разрешение исключено | H37: NO_RULED_UPPER_LIMIT | I37: WILDERNESS_SURVIVAL | M37: CORE-165; CORE-167 | N37: Q-CORE-024; Q-CORE-051 | O37: ACTIVE | P37: =COUNTIF($B$6:$B$50,B37) -> 1
A38: SKL-033 | B38: LIGHTNING_REACTION | C38: Молниеносная реакция | D38: SELECTABLE_GENERAL | E38: PLAYER_HOST; SENTIENT_HOST; ADVISER_IF_GRANTED | F38: BONUS_LEVEL_FORMULA_CORE-165 | G38: Реакция на нападение и уклонение | H38: NO_RULED_UPPER_LIMIT | I38: LIGHTNING_REACTION | M38: CORE-165; CORE-167 | N38: Q-CORE-024; Q-CORE-051 | O38: ACTIVE | P38: =COUNTIF($B$6:$B$50,B38) -> 1
... A42: SKL-037 | B42: COOKING | C42: Кулинария | D42: SELECTABLE_GENERAL | E42: PLAYER_HOST; SENTIENT_HOST; ADVISER_IF_GRANTED | F42: BONUS_LEVEL_FORMULA_CORE-165 | G42: Пища/ингредиенты; разрешение исключено | H42: NO_RULED_UPPER_LIMIT | I42: COOKING | M42: CORE-165; CORE-167 | N42: Q-CORE-024; Q-CORE-051 | O42: ACTIVE | P42: =COUNTIF($B$6:$B$50,B42) -> 1
A43: SKL-038 | B43: MEDIC | C43: Медик | D43: SELECTABLE_GENERAL | E43: PLAYER_HOST; SENTIENT_HOST; ADVISER_IF_GRANTED | F43: BONUS_LEVEL_FORMULA_CORE-165 | G43: Медицинские манипуляции; Искатель исключён из штрафа отсутствия | H43: NO_RULED_UPPER_LIMIT | I43: MEDIC | L43: -10 | M43: CORE-165; CORE-167 | N43: Q-CORE-024; Q-CORE-051 | O43: ACTIVE | P43: =COUNTIF($B$6:$B$50,B43) -> 1
A44: SKL-039 | B44: ERUDITION | C44: Эрудиция | D44: SELECTABLE_GENERAL | E44: PLAYER_HOST; SENTIENT_HOST; ADVISER_IF_GRANTED | F44: BONUS_LEVEL_FORMULA_CORE-165 | G44: Вспоминание фактов; разрешение исключено | H44: NO_RULED_UPPER_LIMIT | I44: ERUDITION | M44: CORE-165; CORE-167 | N44: Q-CORE-024; Q-CORE-051 | O44: ACTIVE | P44: =COUNTIF($B$6:$B$50,B44) -> 1
A45: SKL-040 | B45: NATURAL_SCIENCE | C45: Естественнонаучные знания | D45: SELECTABLE_GENERAL | E45: PLAYER_HOST; SENTIENT_HOST; ADVISER_IF_GRANTED | F45: BONUS_LEVEL_FORMULA_CORE-165 | G45: Дополнительный модификатор изобретательства/крафта только при основном навыке | H45: NO_RULED_UPPER_LIMIT | I45: NATURAL_SCIENCE | M45: CORE-165; CORE-167 | N45: Q-CORE-024; Q-CORE-051 | O45: ACTIVE | P45: =COUNTIF($B$6:$B$50,B45) -> 1
...

Sheet 05_Требования_навыков
A1: Требования навыков
A2: Все условия одной RequirementSet соединяются AND и проверяются на skillStageStats: base + race + class, строго до бонусов симбионтов.
A5: RequirementID | B5: SkillKey | C5: RequirementSetID | D5: StatCode | E5: MinValue | F5: EvaluationStage | G5: BeforeSymbiontBonuses | H5: Rule ID | I5: Source Question ID | J5: ID unique
A6: REQ-UNARMED-S | B6: UNARMED | C6: REQSET-UNARMED-CREATION | D6: S | E6: 9 | F6: SKILL_STAGE_PRE_SYMBIONT | G6: =TRUE() -> TRUE | H6: CORE-167 | I6: Q-CORE-024 | J6: =COUNTIF($A$6:$A$89,A6) -> 1
A7: REQ-UNARMED-D | B7: UNARMED | C7: REQSET-UNARMED-CREATION | D7: D | E7: 11 | F7: SKILL_STAGE_PRE_SYMBIONT | G7: =TRUE() -> TRUE | H7: CORE-167 | I7: Q-CORE-024 | J7: =COUNTIF($A$6:$A$89,A7) -> 1
A8: REQ-GRAPPLING-S | B8: GRAPPLING | C8: REQSET-GRAPPLING-CREATION | D8: S | E8: 11 | F8: SKILL_STAGE_PRE_SYMBIONT | G8: =TRUE() -> TRUE | H8: CORE-167 | I8: Q-CORE-024 | J8: =COUNTIF($A$6:$A$89,A8) -> 1
A9: REQ-GRAPPLING-D | B9: GRAPPLING | C9: REQSET-GRAPPLING-CREATION | D9: D | E9: 9 | F9: SKILL_STAGE_PRE_SYMBIONT | G9: =TRUE() -> TRUE | H9: CORE-167 | I9: Q-CORE-024 | J9: =COUNTIF($A$6:$A$89,A9) -> 1
A10: REQ-GRAPPLING-I | B10: GRAPPLING | C10: REQSET-GRAPPLING-CREATION | D10: I | E10: 4 | F10: SKILL_STAGE_PRE_SYMBIONT | G10: =TRUE() -> TRUE | H10: CORE-167 | I10: Q-CORE-024 | J10: =COUNTIF($A$6:$A$89,A10) -> 1
A11: REQ-WEAPON_THROWING-S | B11: WEAPON_THROWING | C11: REQSET-WEAPON_THROWING-CREATION | D11: S | E11: 5 | F11: SKILL_STAGE_PRE_SYMBIONT | G11: =TRUE() -> TRUE | H11: CORE-167 | I11: Q-CORE-024 | J11: =COUNTIF($A$6:$A$89,A11) -> 1
A12: REQ-WEAPON_THROWING-D | B12: WEAPON_THROWING | C12: REQSET-WEAPON_THROWING-CREATION | D12: D | E12: 11 | F12: SKILL_STAGE_PRE_SYMBIONT | G12: =TRUE() -> TRUE | H12: CORE-167 | I12: Q-CORE-024 | J12: =COUNTIF($A$6:$A$89,A12) -> 1
A13: REQ-WEAPON_THROWING-I | B13: WEAPON_THROWING | C13: REQSET-WEAPON_THROWING-CREATION | D13: I | E13: 5 | F13: SKILL_STAGE_PRE_SYMBIONT | G13: =TRUE() -> TRUE | H13: CORE-167 | I13: Q-CORE-024 | J13: =COUNTIF($A$6:$A$89,A13) -> 1
A14: REQ-OBJECT_THROWING-S | B14: OBJECT_THROWING | C14: REQSET-OBJECT_THROWING-CREATION | D14: S | E14: 11 | F14: SKILL_STAGE_PRE_SYMBIONT | G14: =TRUE() -> TRUE | H14: CORE-167 | I14: Q-CORE-024 | J14: =COUNTIF($A$6:$A$89,A14) -> 1
A15: REQ-OBJECT_THROWING-D | B15: OBJECT_THROWING | C15: REQSET-OBJECT_THROWING-CREATION | D15: D | E15: 5 | F15: SKILL_STAGE_PRE_SYMBIONT | G15: =TRUE() -> TRUE | H15: CORE-167 | I15: Q-CORE-024 | J15: =COUNTIF($A$6:$A$89,A15) -> 1
A16: REQ-SHOOTING-S | B16: SHOOTING | C16: REQSET-SHOOTING-CREATION | D16: S | E16: 5 | F16: SKILL_STAGE_PRE_SYMBIONT | G16: =TRUE() -> TRUE | H16: CORE-167 | I16: Q-CORE-024 | J16: =COUNTIF($A$6:$A$89,A16) -> 1
A17: REQ-SHOOTING-D | B17: SHOOTING | C17: REQSET-SHOOTING-CREATION | D17: D | E17: 6 | F17: SKILL_STAGE_PRE_SYMBIONT | G17: =TRUE() -> TRUE | H17: CORE-167 | I17: Q-CORE-024 | J17: =COUNTIF($A$6:$A$89,A17) -> 1
... A89: REQ-VETERAN_DRINKER-Z | B89: VETERAN_DRINKER | C89: REQSET-VETERAN_DRINKER-CREATION | D89: Z | E89: 8 | F89: SKILL_STAGE_PRE_SYMBIONT | G89: =TRUE() -> TRUE | H89: CORE-167 | I89: Q-CORE-024 | J89: =COUNTIF($A$6:$A$89,A89) -> 1

Sheet 06_Модификаторы_персонажа
A1: Модификаторы персонажа
A2: Нормализованные расовые, классовые и профильные симбиотические дельты. Способностные и временные эффекты остаются в карточках способностей.
A5: ModifierID | B5: SourceType | C5: SourceID | D5: TargetKind | E5: TargetCode | F5: Operation | G5: Value | H5: ContextPredicate | I5: ApplicationStage | J5: StackPolicy | K5: Rule IDs | L5: ID unique
A6: MOD-RACE-FREE-MANUAL-S | B6: RACE | C6: FREE | D6: STAT | E6: S | F6: ADD | G6: -2 | H6: creationMode=MANUAL | I6: SKILL_STAGE | J6: ADD_ONCE_PER_SOURCE | K6: CORE-006 | L6: =COUNTIF($A$6:$A$48,A6) -> 1
A7: MOD-RACE-FREE-MANUAL-M | B7: RACE | C7: FREE | D7: STAT | E7: M | F7: ADD | G7: -2 | H7: creationMode=MANUAL | I7: SKILL_STAGE | J7: ADD_ONCE_PER_SOURCE | K7: CORE-006 | L7: =COUNTIF($A$6:$A$48,A7) -> 1
A8: MOD-RACE-FREE-MANUAL-Z | B8: RACE | C8: FREE | D8: STAT | E8: Z | F8: ADD | G8: -2 | H8: creationMode=MANUAL | I8: SKILL_STAGE | J8: ADD_ONCE_PER_SOURCE | K8: CORE-006 | L8: =COUNTIF($A$6:$A$48,A8) -> 1
A9: MOD-RACE-UNITED-RANDOM-S | B9: RACE | C9: UNITED | D9: STAT | E9: S | F9: ADD | G9: -3 | H9: creationMode=RANDOM | I9: SKILL_STAGE | J9: ADD_ONCE_PER_SOURCE | K9: CORE-001 | L9: =COUNTIF($A$6:$A$48,A9) -> 1
A10: MOD-RACE-UNITED-RANDOM-M | B10: RACE | C10: UNITED | D10: STAT | E10: M | F10: ADD | G10: -6 | H10: creationMode=RANDOM | I10: SKILL_STAGE | J10: ADD_ONCE_PER_SOURCE | K10: CORE-001 | L10: =COUNTIF($A$6:$A$48,A10) -> 1
A11: MOD-RACE-UNITED-RANDOM-Z | B11: RACE | C11: UNITED | D11: STAT | E11: Z | F11: ADD | G11: -6 | H11: creationMode=RANDOM | I11: SKILL_STAGE | J11: ADD_ONCE_PER_SOURCE | K11: CORE-001 | L11: =COUNTIF($A$6:$A$48,A11) -> 1
A12: MOD-RACE-UNITED-MANUAL-S | B12: RACE | C12: UNITED | D12: STAT | E12: S | F12: ADD | G12: -7 | H12: creationMode=MANUAL | I12: SKILL_STAGE | J12: ADD_ONCE_PER_SOURCE | K12: CORE-001 | L12: =COUNTIF($A$6:$A$48,A12) -> 1
A13: MOD-RACE-UNITED-MANUAL-M | B13: RACE | C13: UNITED | D13: STAT | E13: M | F13: ADD | G13: -10 | H13: creationMode=MANUAL | I13: SKILL_STAGE | J13: ADD_ONCE_PER_SOURCE | K13: CORE-001 | L13: =COUNTIF($A$6:$A$48,A13) -> 1
A14: MOD-RACE-UNITED-MANUAL-Z | B14: RACE | C14: UNITED | D14: STAT | E14: Z | F14: ADD | G14: -10 | H14: creationMode=MANUAL | I14: SKILL_STAGE | J14: ADD_ONCE_PER_SOURCE | K14: CORE-001 | L14: =COUNTIF($A$6:$A$48,A14) -> 1
A15: MOD-RACE-UNITED-C-VS-UNITED | B15: RACE | C15: UNITED | D15: STAT | E15: C | F15: ADD | G15: 5 | H15: socialTargetRace=UNITED | I15: CHECK_CONTEXT | J15: MOST_SPECIFIC_CONTEXT | K15: CORE-001 | L15: =COUNTIF($A$6:$A$48,A15) -> 1
A16: MOD-RACE-UNITED-C-VS-PURE | B16: RACE | C16: UNITED | D16: STAT | E16: C | F16: ADD | G16: -15 | H16: socialTargetRace=PURE | I16: CHECK_CONTEXT | J16: MOST_SPECIFIC_CONTEXT | K16: CORE-001 | L16: =COUNTIF($A$6:$A$48,A16) -> 1
A17: MOD-CLASS-SEEKER-S | B17: PURE_CLASS | C17: SEEKER | D17: STAT | E17: S | F17: ADD | G17: 2 | H17: ownerRace=PURE | I17: SKILL_STAGE | J17: ADD_ONCE_PER_SOURCE | K17: CORE-009 | L17: =COUNTIF($A$6:$A$48,A17) -> 1
... A48: MOD-SYMBIONT-PLAGUE_DOCTOR-I | B48: SYMBIONT_PROFILE | C48: PLAGUE_DOCTOR | D48: STAT | E48: I | F48: ADD | G48: 10 | H48: symbiontActive=true | I48: EFFECTIVE_STATS | J48: ADD_ONCE_PER_ACTIVE_SPECIES | K48: MON-040 | L48: =COUNTIF($A$6:$A$48,A48) -> 1

Sheet 07_Симбионты
A1: Каталог симбионтов
A2: 20 обычных видов и 3 симбиотических чудовища. LinkedStatCodes — машинный источник прямой маршрутизации XP; нормализованные пары приведены ниже. ADVISER каноничен, ADVISOR — только alias.
A5: SpeciesKey | B5: Название | C5: SymbiontKind | D5: SlotCost | E5: AllowedRaceCodes | F5: MaxL | G5: XPPolicy | H5: OEPolicy | I5: BranchPolicy | J5: AdditionalSlotPolicy | K5: MonsterProfileID | L5: ProfileRuleID | M5: Rule IDs | N5: Источник | O5: Status | P5: ID unique | Q5: LinkedStatCodes
A6: WEAVER | B6: Ткач | C6: ORDINARY | D6: 1 | E6: FREE; UNITED | F6: 6 | G6: SYM-021_AWARD; SYM-022_NODE_COST_EQUALS_NODE_LEVEL | H6: baseMaxOE=50×L; currentOE clamped to max; new instance full except transplant=0 | I6: XOR+OR | J6: NONE | L6: SYM-026 | M6: SYM-026; SYM-009; SYM-020; SYM-021; SYM-022; SYM-024 | N6: 7.5.1–7.5.1.1, стр. 115 (дерево прочитано визуально). | O6: ACTIVE | P6: =COUNTIF($A$6:$A$28,A6) -> 1 | Q6: I
A7: TAIPAN | B7: Тайпан | C7: ORDINARY | D7: 1 | E7: FREE; UNITED | F7: 7 | G7: SYM-021_AWARD; SYM-022_NODE_COST_EQUALS_NODE_LEVEL | H7: baseMaxOE=50×L; currentOE clamped to max; new instance full except transplant=0 | I7: LINEAR_OR_EXPLICIT_PARENTS | J7: NONE | L7: SYM-037 | M7: SYM-037; SYM-009; SYM-020; SYM-021; SYM-022; SYM-024 | N7: 7.5.2–7.5.2.1, стр. 118 (дерево прочитано визуально). | O7: ACTIVE | P7: =COUNTIF($A$6:$A$28,A7) -> 1 | Q7: D; W
A8: OWL | B8: Сова | C8: ORDINARY | D8: 1 | E8: FREE; UNITED | F8: 6 | G8: SYM-021_AWARD; SYM-022_NODE_COST_EQUALS_NODE_LEVEL | H8: baseMaxOE=10×L; currentOE clamped to max; new instance full except transplant=0 | I8: LINEAR_OR_EXPLICIT_PARENTS | J8: NONE | L8: SYM-046 | M8: SYM-046; SYM-009; SYM-020; SYM-021; SYM-022; SYM-024 | N8: 7.5.3–7.5.3.1, стр. 121 (дерево прочитано визуально). | O8: ACTIVE | P8: =COUNTIF($A$6:$A$28,A8) -> 1 | Q8: W
A9: TEACHER | B9: Учитель | C9: ORDINARY | D9: 1 | E9: FREE; UNITED | F9: 6 | G9: SYM-021_AWARD; SYM-022_NODE_COST_EQUALS_NODE_LEVEL | H9: baseMaxOE=20×L; currentOE clamped to max; new instance full except transplant=0 | I9: LINEAR_OR_EXPLICIT_PARENTS | J9: NONE | L9: SYM-053 | M9: SYM-053; SYM-009; SYM-020; SYM-021; SYM-022; SYM-024 | N9: 7.5.4–7.5.4.1, стр. 123 (дерево прочитано визуально). | O9: ACTIVE | P9: =COUNTIF($A$6:$A$28,A9) -> 1 | Q9: W
A10: ARMADILLO | B10: Броненосец | C10: ORDINARY | D10: 1 | E10: FREE; UNITED | F10: 6 | G10: SYM-021_AWARD; SYM-022_NODE_COST_EQUALS_NODE_LEVEL | H10: baseMaxOE=50×L; currentOE clamped to max; new instance full except transplant=0 | I10: LINEAR_OR_EXPLICIT_PARENTS | J10: NONE | L10: SYM-060 | M10: SYM-060; SYM-009; SYM-020; SYM-021; SYM-022; SYM-024 | N10: 7.5.5–7.5.5.1, стр. 125 (дерево прочитано визуально). | O10: ACTIVE | P10: =COUNTIF($A$6:$A$28,A10) -> 1 | Q10: M; Z
A11: DRAGON | B11: Дракон | C11: ORDINARY | D11: 1 | E11: FREE; UNITED | F11: 6 | G11: SYM-021_AWARD; SYM-022_NODE_COST_EQUALS_NODE_LEVEL | H11: baseMaxOE=30×L; currentOE clamped to max; new instance full except transplant=0 | I11: LINEAR_OR_EXPLICIT_PARENTS | J11: NONE | L11: SYM-067 | M11: SYM-067; SYM-009; SYM-020; SYM-021; SYM-022; SYM-024 | N11: 7.5.6–7.5.6.1, стр. 127 (дерево прочитано визуально). | O11: ACTIVE | P11: =COUNTIF($A$6:$A$28,A11) -> 1 | Q11: D; W
A12: TROGR | B12: Трогр | C12: ORDINARY | D12: 1 | E12: FREE; UNITED | F12: 6 | G12: SYM-021_AWARD; SYM-022_NODE_COST_EQUALS_NODE_LEVEL | H12: baseMaxOE=1000×L; currentOE clamped to max; new instance full except transplant=0 | I12: XOR | J12: NONE | L12: SYM-074 | M12: SYM-074; SYM-009; SYM-020; SYM-021; SYM-022; SYM-024 | N12: 7.5.7–7.5.7.1, стр. 129 (дерево прочитано визуально). | O12: ACTIVE | P12: =COUNTIF($A$6:$A$28,A12) -> 1 | Q12: S; D; M
A13: KEEPER | B13: Хранитель | C13: ORDINARY | D13: 1 | E13: FREE; UNITED | F13: 6 | G13: SYM-021_AWARD; SYM-022_NODE_COST_EQUALS_NODE_LEVEL | H13: baseMaxOE=100×L; currentOE clamped to max; new instance full except transplant=0; Кромсатель заменяет формулу на 200×L | I13: OR | J13: NONE | L13: SYM-083 | M13: SYM-083; SYM-009; SYM-020; SYM-021; SYM-022; SYM-024 | N13: 7.5.8–7.5.8.1, стр. 131 (дерево прочитано визуально). | O13: ACTIVE | P13: =COUNTIF($A$6:$A$28,A13) -> 1 | Q13: W; Z
A14: ADVISER | B14: Советник | C14: ORDINARY | D14: 1 | E14: FREE; UNITED | F14: 6 | G14: SYM-021_AWARD; SYM-022_NODE_COST_EQUALS_NODE_LEVEL | H14: baseMaxOE=20×L; currentOE clamped to max; new instance full except transplant=0 | I14: LINEAR_OR_EXPLICIT_PARENTS | J14: NONE | L14: SYM-095 | M14: SYM-095; SYM-009; SYM-020; SYM-021; SYM-022; SYM-024 | N14: 7.5.9–7.5.9.1, стр. 134 (дерево прочитано визуально). | O14: ACTIVE | P14: =COUNTIF($A$6:$A$28,A14) -> 1 | Q14: I; W
A15: TICK | B15: Клещ | C15: ORDINARY | D15: 1 | E15: FREE; UNITED | F15: 6 | G15: SYM-021_AWARD; SYM-022_NODE_COST_EQUALS_NODE_LEVEL | H15: baseMaxOE=50×L; currentOE clamped to max; new instance full except transplant=0 | I15: LINEAR_OR_EXPLICIT_PARENTS | J15: NONE | L15: SYM-102 | M15: SYM-102; SYM-009; SYM-020; SYM-021; SYM-022; SYM-024 | N15: 7.5.10–7.5.10.1, стр. 136 (дерево прочитано визуально). | O15: ACTIVE | P15: =COUNTIF($A$6:$A$28,A15) -> 1 | Q15: S; D
A16: CRICKET | B16: Сверчок | C16: ORDINARY | D16: 1 | E16: FREE; UNITED | F16: 6 | G16: SYM-021_AWARD; SYM-022_NODE_COST_EQUALS_NODE_LEVEL | H16: baseMaxOE=50×L; currentOE clamped to max; new instance full except transplant=0 | I16: LINEAR_OR_EXPLICIT_PARENTS | J16: NONE | L16: SYM-109 | M16: SYM-109; SYM-009; SYM-020; SYM-021; SYM-022; SYM-024 | N16: 7.5.11–7.5.11.1, стр. 138 (дерево прочитано визуально). | O16: ACTIVE | P16: =COUNTIF($A$6:$A$28,A16) -> 1 | Q16: D; M
A17: SPIDER | B17: Паук | C17: ORDINARY | D17: 1 | E17: FREE; UNITED | F17: 6 | G17: SYM-021_AWARD; SYM-022_NODE_COST_EQUALS_NODE_LEVEL | H17: baseMaxOE=50×L; currentOE clamped to max; new instance full except transplant=0 | I17: LINEAR_OR_EXPLICIT_PARENTS | J17: NONE | L17: SYM-116 | M17: SYM-116; SYM-009; SYM-020; SYM-021; SYM-022; SYM-024 | N17: 7.5.12–7.5.12.1, стр. 140 (дерево прочитано визуально). | O17: ACTIVE | P17: =COUNTIF($A$6:$A$28,A17) -> 1 | Q17: D; W
... A25: SKUNK | B25: Скунс | C25: ORDINARY | D25: 1 | E25: FREE; UNITED | F25: 6 | G25: SYM-021_AWARD; SYM-022_NODE_COST_EQUALS_NODE_LEVEL | H25: baseMaxOE=50×L; currentOE clamped to max; new instance full except transplant=0 | I25: LINEAR_OR_EXPLICIT_PARENTS | J25: NONE | L25: SYM-174 | M25: SYM-174; SYM-009; SYM-020; SYM-021; SYM-022; SYM-024 | N25: 7.5.20–7.5.20.1, стр. 160 (дерево прочитано визуально). | O25: ACTIVE | P25: =COUNTIF($A$6:$A$28,A25) -> 1 | Q25: D; M
A26: CHIMERA | B26: Химера | C26: SYMBIOTIC_MONSTER | D26: 4 | E26: UNITED | F26: 6 | G26: SYM-021_AWARD; SYM-022_NODE_COST_EQUALS_NODE_LEVEL | H26: baseMaxOE=400×L; currentOE clamped to max; new instance full except transplant=0 | I26: LINEAR_OR_EXPLICIT_PARENTS | J26: ONLY_CONFIRMED_DEVOURING; initial extraSlots=0; explicit devouringHistory; max +3 | K26: MON-002 | L26: MON-002 | M26: MON-002; SYM-009; SYM-020; SYM-021; SYM-022; SYM-024 | N26: §7.6.1, печ. стр. 163. | O26: ACTIVE | P26: =COUNTIF($A$6:$A$28,A26) -> 1 | Q26: Z; S; D
A27: PUPPETEER | B27: Кукловод | C27: SYMBIOTIC_MONSTER | D27: 4 | E27: UNITED | F27: 6 | G27: SYM-021_AWARD; SYM-022_NODE_COST_EQUALS_NODE_LEVEL | H27: baseMaxOE=400×L; currentOE clamped to max; new instance full except transplant=0 | I27: LINEAR_OR_EXPLICIT_PARENTS | J27: ORDINARY_ADDITIONAL_SYMBIONTS_FORBIDDEN | K27: MON-025 | L27: MON-025 | M27: MON-025; SYM-009; SYM-020; SYM-021; SYM-022; SYM-024 | N27: §7.6.2, печ. стр. 167. | O27: ACTIVE | P27: =COUNTIF($A$6:$A$28,A27) -> 1 | Q27: C; I; W
A28: PLAGUE_DOCTOR | B28: Чумной доктор | C28: SYMBIOTIC_MONSTER | D28: 4 | E28: UNITED | F28: 8 | G28: SYM-021_AWARD; SYM-022_NODE_COST_EQUALS_NODE_LEVEL | H28: baseMaxOE=400×L; currentOE clamped to max; new instance full except transplant=0 | I28: XOR | J28: ORDINARY_ADDITIONAL_SYMBIONTS_FORBIDDEN | K28: MON-040 | L28: MON-040 | M28: MON-040; SYM-009; SYM-020; SYM-021; SYM-022; SYM-024 | N28: §7.6.3, печ. стр. 170. | O28: ACTIVE | P28: =COUNTIF($A$6:$A$28,A28) -> 1 | Q28: Z; I; W
A31: Нормализованные связи SpeciesKey ↔ LinkedStatCode | B31: Нормализованные связи SpeciesKey ↔ LinkedStatCode | C31: Нормализованные связи SpeciesKey ↔ LinkedStatCode | D31: Нормализованные связи SpeciesKey ↔ LinkedStatCode | E31: Нормализованные связи SpeciesKey ↔ LinkedStatCode | F31: Нормализованные связи SpeciesKey ↔ LinkedStatCode | G31: Нормализованные связи SpeciesKey ↔ LinkedStatCode
A32: 48 отношений, дословно извлечённых из профильных карточек Rules v1.6. Модификатор характеристики профиля не считается связью. | B32: 48 отношений, дословно извлечённых из профильных карточек Rules v1.6. Модификатор характеристики профиля не считается связью. | C32: 48 отношений, дословно извлечённых из профильных карточек Rules v1.6. Модификатор характеристики профиля не считается связью. | D32: 48 отношений, дословно извлечённых из профильных карточек Rules v1.6. Модификатор характеристики профиля не считается связью. | E32: 48 отношений, дословно извлечённых из профильных карточек Rules v1.6. Модификатор характеристики профиля не считается связью. | F32: 48 отношений, дословно извлечённых из профильных карточек Rules v1.6. Модификатор характеристики профиля не считается связью. | G32: 48 отношений, дословно извлечённых из профильных карточек Rules v1.6. Модификатор характеристики профиля не считается связью.
A34: LinkID | B34: SpeciesKey | C34: LinkedStatCode | D34: StatOrder | E34: ProfileRuleID | F34: Status | G34: ID unique
A35: SYMSTAT-WEAVER-I | B35: WEAVER | C35: I | D35: 5 | E35: SYM-026 | F35: ACTIVE | G35: =COUNTIF($A$35:$A$80,A35) -> 1
A36: SYMSTAT-TAIPAN-D | B36: TAIPAN | C36: D | D36: 2 | E36: SYM-037 | F36: ACTIVE | G36: =COUNTIF($A$35:$A$80,A36) -> 1
A37: SYMSTAT-TAIPAN-W | B37: TAIPAN | C37: W | D37: 6 | E37: SYM-037 | F37: ACTIVE | G37: =COUNTIF($A$35:$A$80,A37) -> 1
A38: SYMSTAT-OWL-W | B38: OWL | C38: W | D38: 6 | E38: SYM-046 | F38: ACTIVE | G38: =COUNTIF($A$35:$A$80,A38) -> 1
A39: SYMSTAT-TEACHER-W | B39: TEACHER | C39: W | D39: 6 | E39: SYM-053 | F39: ACTIVE | G39: =COUNTIF($A$35:$A$80,A39) -> 1
A40: SYMSTAT-ARMADILLO-M | B40: ARMADILLO | C40: M | D40: 3 | E40: SYM-060 | F40: ACTIVE | G40: =COUNTIF($A$35:$A$80,A40) -> 1
A41: SYMSTAT-ARMADILLO-Z | B41: ARMADILLO | C41: Z | D41: 4 | E41: SYM-060 | F41: ACTIVE | G41: =COUNTIF($A$35:$A$80,A41) -> 1
A42: SYMSTAT-DRAGON-D | B42: DRAGON | C42: D | D42: 2 | E42: SYM-067 | F42: ACTIVE | G42: =COUNTIF($A$35:$A$80,A42) -> 1
A43: SYMSTAT-DRAGON-W | B43: DRAGON | C43: W | D43: 6 | E43: SYM-067 | F43: ACTIVE | G43: =COUNTIF($A$35:$A$80,A43) -> 1
A44: SYMSTAT-TROGR-S | B44: TROGR | C44: S | D44: 1 | E44: SYM-074 | F44: ACTIVE | G44: =COUNTIF($A$35:$A$80,A44) -> 1
A45: SYMSTAT-TROGR-D | B45: TROGR | C45: D | D45: 2 | E45: SYM-074 | F45: ACTIVE | G45: =COUNTIF($A$35:$A$80,A45) -> 1
A46: SYMSTAT-TROGR-M | B46: TROGR | C46: M | D46: 3 | E46: SYM-074 | F46: ACTIVE | G46: =COUNTIF($A$35:$A$80,A46) -> 1
... A80: SYMSTAT-PLAGUE_DOCTOR-Z | B80: PLAGUE_DOCTOR | C80: Z | D80: 4 | E80: MON-040 | F80: ACTIVE | G80: =COUNTIF($A$35:$A$80,A80) -> 1
A81: SYMSTAT-PLAGUE_DOCTOR-I | B81: PLAGUE_DOCTOR | C81: I | D81: 5 | E81: MON-040 | F81: ACTIVE | G81: 1
A82: SYMSTAT-PLAGUE_DOCTOR-W | B82: PLAGUE_DOCTOR | C82: W | D82: 6 | E82: MON-040 | F82: ACTIVE | G82: 1

Sheet 08_Уровни_симбионтов
A1: Уровни симбионтов
A2: Уровень 1 и все его узлы выдаются бесплатно; узел уровня N стоит N XP. MaxOE указан для базовой профильной формулы до частных замен.
A5: LevelProfileID | B5: SpeciesKey | C5: L | D5: XPThreshold / NodeCost | E5: Base MaxOE | F5: NodeUnlockCount | G5: RequiredPriorLevel | H5: Rule IDs | I5: ID unique
A6: LVL-WEAVER-1 | B6: WEAVER | C6: 1 | D6: 0 | E6: 50 | F6: 1 | H6: SYM-026; SYM-009; SYM-020; SYM-022; SYM-024 | I6: =COUNTIF($A$6:$A$149,A6) -> 1
A7: LVL-WEAVER-2 | B7: WEAVER | C7: 2 | D7: 2 | E7: 100 | F7: 2 | G7: 1 | H7: SYM-026; SYM-009; SYM-020; SYM-022; SYM-024 | I7: =COUNTIF($A$6:$A$149,A7) -> 1
A8: LVL-WEAVER-3 | B8: WEAVER | C8: 3 | D8: 3 | E8: 150 | F8: 2 | G8: 2 | H8: SYM-026; SYM-009; SYM-020; SYM-022; SYM-024 | I8: =COUNTIF($A$6:$A$149,A8) -> 1
A9: LVL-WEAVER-4 | B9: WEAVER | C9: 4 | D9: 4 | E9: 200 | F9: 2 | G9: 3 | H9: SYM-026; SYM-009; SYM-020; SYM-022; SYM-024 | I9: =COUNTIF($A$6:$A$149,A9) -> 1
A10: LVL-WEAVER-5 | B10: WEAVER | C10: 5 | D10: 5 | E10: 250 | F10: 2 | G10: 4 | H10: SYM-026; SYM-009; SYM-020; SYM-022; SYM-024 | I10: =COUNTIF($A$6:$A$149,A10) -> 1
A11: LVL-WEAVER-6 | B11: WEAVER | C11: 6 | D11: 6 | E11: 300 | F11: 1 | G11: 5 | H11: SYM-026; SYM-009; SYM-020; SYM-022; SYM-024 | I11: =COUNTIF($A$6:$A$149,A11) -> 1
A12: LVL-TAIPAN-1 | B12: TAIPAN | C12: 1 | D12: 0 | E12: 50 | F12: 1 | H12: SYM-037; SYM-009; SYM-020; SYM-022; SYM-024 | I12: =COUNTIF($A$6:$A$149,A12) -> 1
A13: LVL-TAIPAN-2 | B13: TAIPAN | C13: 2 | D13: 2 | E13: 100 | F13: 1 | G13: 1 | H13: SYM-037; SYM-009; SYM-020; SYM-022; SYM-024 | I13: =COUNTIF($A$6:$A$149,A13) -> 1
A14: LVL-TAIPAN-3 | B14: TAIPAN | C14: 3 | D14: 3 | E14: 150 | F14: 1 | G14: 2 | H14: SYM-037; SYM-009; SYM-020; SYM-022; SYM-024 | I14: =COUNTIF($A$6:$A$149,A14) -> 1
A15: LVL-TAIPAN-4 | B15: TAIPAN | C15: 4 | D15: 4 | E15: 200 | F15: 1 | G15: 3 | H15: SYM-037; SYM-009; SYM-020; SYM-022; SYM-024 | I15: =COUNTIF($A$6:$A$149,A15) -> 1
A16: LVL-TAIPAN-5 | B16: TAIPAN | C16: 5 | D16: 5 | E16: 250 | F16: 1 | G16: 4 | H16: SYM-037; SYM-009; SYM-020; SYM-022; SYM-024 | I16: =COUNTIF($A$6:$A$149,A16) -> 1
A17: LVL-TAIPAN-6 | B17: TAIPAN | C17: 6 | D17: 6 | E17: 300 | F17: 1 | G17: 5 | H17: SYM-037; SYM-009; SYM-020; SYM-022; SYM-024 | I17: =COUNTIF($A$6:$A$149,A17) -> 1
A18: LVL-TAIPAN-7 | B18: TAIPAN | C18: 7 | D18: 7 | E18: 350 | F18: 1 | G18: 6 | H18: SYM-037; SYM-009; SYM-020; SYM-022; SYM-024 | I18: =COUNTIF($A$6:$A$149,A18) -> 1
A19: LVL-OWL-1 | B19: OWL | C19: 1 | D19: 0 | E19: 10 | F19: 1 | H19: SYM-046; SYM-009; SYM-020; SYM-022; SYM-024 | I19: =COUNTIF($A$6:$A$149,A19) -> 1
A20: LVL-OWL-2 | B20: OWL | C20: 2 | D20: 2 | E20: 20 | F20: 1 | G20: 1 | H20: SYM-046; SYM-009; SYM-020; SYM-022; SYM-024 | I20: =COUNTIF($A$6:$A$149,A20) -> 1
A21: LVL-OWL-3 | B21: OWL | C21: 3 | D21: 3 | E21: 30 | F21: 1 | G21: 2 | H21: SYM-046; SYM-009; SYM-020; SYM-022; SYM-024 | I21: =COUNTIF($A$6:$A$149,A21) -> 1
A22: LVL-OWL-4 | B22: OWL | C22: 4 | D22: 4 | E22: 40 | F22: 1 | G22: 3 | H22: SYM-046; SYM-009; SYM-020; SYM-022; SYM-024 | I22: =COUNTIF($A$6:$A$149,A22) -> 1
A23: LVL-OWL-5 | B23: OWL | C23: 5 | D23: 5 | E23: 50 | F23: 1 | G23: 4 | H23: SYM-046; SYM-009; SYM-020; SYM-022; SYM-024 | I23: =COUNTIF($A$6:$A$149,A23) -> 1
A24: LVL-OWL-6 | B24: OWL | C24: 6 | D24: 6 | E24: 60 | F24: 1 | G24: 5 | H24: SYM-046; SYM-009; SYM-020; SYM-022; SYM-024 | I24: =COUNTIF($A$6:$A$149,A24) -> 1
A25: LVL-TEACHER-1 | B25: TEACHER | C25: 1 | D25: 0 | E25: 20 | F25: 1 | H25: SYM-053; SYM-009; SYM-020; SYM-022; SYM-024 | I25: =COUNTIF($A$6:$A$149,A25) -> 1
A26: LVL-TEACHER-2 | B26: TEACHER | C26: 2 | D26: 2 | E26: 40 | F26: 1 | G26: 1 | H26: SYM-053; SYM-009; SYM-020; SYM-022; SYM-024 | I26: =COUNTIF($A$6:$A$149,A26) -> 1
A27: LVL-TEACHER-3 | B27: TEACHER | C27: 3 | D27: 3 | E27: 60 | F27: 1 | G27: 2 | H27: SYM-053; SYM-009; SYM-020; SYM-022; SYM-024 | I27: =COUNTIF($A$6:$A$149,A27) -> 1
A28: LVL-TEACHER-4 | B28: TEACHER | C28: 4 | D28: 4 | E28: 80 | F28: 1 | G28: 3 | H28: SYM-053; SYM-009; SYM-020; SYM-022; SYM-024 | I28: =COUNTIF($A$6:$A$149,A28) -> 1
A29: LVL-TEACHER-5 | B29: TEACHER | C29: 5 | D29: 5 | E29: 100 | F29: 1 | G29: 4 | H29: SYM-053; SYM-009; SYM-020; SYM-022; SYM-024 | I29: =COUNTIF($A$6:$A$149,A29) -> 1
A30: LVL-TEACHER-6 | B30: TEACHER | C30: 6 | D30: 6 | E30: 120 | F30: 1 | G30: 5 | H30: SYM-053; SYM-009; SYM-020; SYM-022; SYM-024 | I30: =COUNTIF($A$6:$A$149,A30) -> 1
A31: LVL-ARMADILLO-1 | B31: ARMADILLO | C31: 1 | D31: 0 | E31: 50 | F31: 1 | H31: SYM-060; SYM-009; SYM-020; SYM-022; SYM-024 | I31: =COUNTIF($A$6:$A$149,A31) -> 1
A32: LVL-ARMADILLO-2 | B32: ARMADILLO | C32: 2 | D32: 2 | E32: 100 | F32: 1 | G32: 1 | H32: SYM-060; SYM-009; SYM-020; SYM-022; SYM-024 | I32: =COUNTIF($A$6:$A$149,A32) -> 1
A33: LVL-ARMADILLO-3 | B33: ARMADILLO | C33: 3 | D33: 3 | E33: 150 | F33: 1 | G33: 2 | H33: SYM-060; SYM-009; SYM-020; SYM-022; SYM-024 | I33: =COUNTIF($A$6:$A$149,A33) -> 1
A34: LVL-ARMADILLO-4 | B34: ARMADILLO | C34: 4 | D34: 4 | E34: 200 | F34: 1 | G34: 3 | H34: SYM-060; SYM-009; SYM-020; SYM-022; SYM-024 | I34: =COUNTIF($A$6:$A$149,A34) -> 1
A35: LVL-ARMADILLO-5 | B35: ARMADILLO | C35: 5 | D35: 5 | E35: 250 | F35: 1 | G35: 4 | H35: SYM-060; SYM-009; SYM-020; SYM-022; SYM-024 | I35: =COUNTIF($A$6:$A$149,A35) -> 1
A36: LVL-ARMADILLO-6 | B36: ARMADILLO | C36: 6 | D36: 6 | E36: 300 | F36: 1 | G36: 5 | H36: SYM-060; SYM-009; SYM-020; SYM-022; SYM-024 | I36: =COUNTIF($A$6:$A$149,A36) -> 1
A37: LVL-DRAGON-1 | B37: DRAGON | C37: 1 | D37: 0 | E37: 30 | F37: 1 | H37: SYM-067; SYM-009; SYM-020; SYM-022; SYM-024 | I37: =COUNTIF($A$6:$A$149,A37) -> 1
A38: LVL-DRAGON-2 | B38: DRAGON | C38: 2 | D38: 2 | E38: 60 | F38: 1 | G38: 1 | H38: SYM-067; SYM-009; SYM-020; SYM-022; SYM-024 | I38: =COUNTIF($A$6:$A$149,A38) -> 1
A39: LVL-DRAGON-3 | B39: DRAGON | C39: 3 | D39: 3 | E39: 90 | F39: 1 | G39: 2 | H39: SYM-067; SYM-009; SYM-020; SYM-022; SYM-024 | I39: =COUNTIF($A$6:$A$149,A39) -> 1
A40: LVL-DRAGON-4 | B40: DRAGON | C40: 4 | D40: 4 | E40: 120 | F40: 1 | G40: 3 | H40: SYM-067; SYM-009; SYM-020; SYM-022; SYM-024 | I40: =COUNTIF($A$6:$A$149,A40) -> 1
A41: LVL-DRAGON-5 | B41: DRAGON | C41: 5 | D41: 5 | E41: 150 | F41: 1 | G41: 4 | H41: SYM-067; SYM-009; SYM-020; SYM-022; SYM-024 | I41: =COUNTIF($A$6:$A$149,A41) -> 1
A42: LVL-DRAGON-6 | B42: DRAGON | C42: 6 | D42: 6 | E42: 180 | F42: 1 | G42: 5 | H42: SYM-067; SYM-009; SYM-020; SYM-022; SYM-024 | I42: =COUNTIF($A$6:$A$149,A42) -> 1
...

Sheet 09_Узлы_развития
A1: Узлы и ветви развития
A2: Полная топология из 182 узлов. Для 15 неавтоматизируемых узлов сохранены только имя, уровень, родители и ограничения — без исполняемого поведения.
A5: NodeRef | B5: SpeciesKey | C5: Название | D5: L | E5: BranchCode | F5: NodeKind | G5: ParentNodeRef | H5: ParentMode | I5: ChoiceGroupID | J5: AbilityID | K5: AutomationStatus | L5: SelectionConstraint | M5: Rule IDs | N5: Source Question IDs | O5: ID unique
A6: SYM-027 | B6: WEAVER | C6: Регенерация | D6: 1 | F6: AUTOMATED_ABILITY_NODE | H6: ALL | J6: SYM-027 | K6: AUTOMATED_ACCEPTED | L6: ROOT | M6: SYM-027 | O6: =COUNTIF($A$6:$A$187,A6) -> 1
A7: SYM-028 | B7: WEAVER | C7: Замена органа | D7: 2 | E7: SELF_REGENERATION | F7: AUTOMATED_ABILITY_NODE | G7: SYM-027 | H7: ALL | I7: WEAVER_L2_XOR | J7: SYM-028 | K7: AUTOMATED_ACCEPTED | L7: ALL(SYM-027); XOR:WEAVER_L2_XOR; BRANCH:SELF_REGENERATION | M7: SYM-028 | N7: Q-SYM-005; Q-SYM-007; Q-SYM-008 | O7: =COUNTIF($A$6:$A$187,A7) -> 1
A8: SYM-029 | B8: WEAVER | C8: Внешняя регенерация | D8: 2 | E8: EXTERNAL_REGENERATION | F8: AUTOMATED_ABILITY_NODE | G8: SYM-027 | H8: ALL | I8: WEAVER_L2_XOR | J8: SYM-029 | K8: AUTOMATED_ACCEPTED | L8: ALL(SYM-027); XOR:WEAVER_L2_XOR; BRANCH:EXTERNAL_REGENERATION | M8: SYM-029 | O8: =COUNTIF($A$6:$A$187,A8) -> 1
A9: SYM-030 | B9: WEAVER | C9: Дублирование органов | D9: 3 | E9: SELF_REGENERATION | F9: AUTOMATED_ABILITY_NODE | G9: SYM-028 | H9: ALL | J9: SYM-030 | K9: AUTOMATED_ACCEPTED | L9: ALL(SYM-028); BRANCH:SELF_REGENERATION | M9: SYM-030 | N9: Q-SYM-005; Q-SYM-009 | O9: =COUNTIF($A$6:$A$187,A9) -> 1
A10: SYM-032 | B10: WEAVER | C10: Анаболический форсаж | D10: 4 | E10: SELF_REGENERATION | F10: AUTOMATED_ABILITY_NODE | G10: SYM-030 | H10: ALL | J10: SYM-032 | K10: AUTOMATED_ACCEPTED | L10: ALL(SYM-030); BRANCH:SELF_REGENERATION | M10: SYM-032 | N10: Q-SYM-005; Q-SYM-011 | O10: =COUNTIF($A$6:$A$187,A10) -> 1
A11: SYM-034 | B11: WEAVER | C11: Абсолютная регенерация | D11: 5 | E11: SELF_REGENERATION | F11: AUTOMATED_ABILITY_NODE | G11: SYM-032 | H11: ALL | J11: SYM-034 | K11: AUTOMATED_ACCEPTED | L11: ALL(SYM-032); BRANCH:SELF_REGENERATION | M11: SYM-034 | N11: Q-SYM-005; Q-SYM-013; Q-SYM-014 | O11: =COUNTIF($A$6:$A$187,A11) -> 1
A12: SYM-031 | B12: WEAVER | C12: Выстрел регенерона | D12: 3 | E12: EXTERNAL_REGENERATION | F12: AUTOMATED_ABILITY_NODE | G12: SYM-029 | H12: ALL | J12: SYM-031 | K12: AUTOMATED_ACCEPTED | L12: ALL(SYM-029); BRANCH:EXTERNAL_REGENERATION | M12: SYM-031 | N12: Q-SYM-010 | O12: =COUNTIF($A$6:$A$187,A12) -> 1
A13: SYM-033 | B13: WEAVER | C13: Адреналиновая реанимация | D13: 4 | E13: EXTERNAL_REGENERATION | F13: AUTOMATED_ABILITY_NODE | G13: SYM-031 | H13: ALL | J13: SYM-033 | K13: AUTOMATED_ACCEPTED | L13: ALL(SYM-031); BRANCH:EXTERNAL_REGENERATION | M13: SYM-033 | N13: Q-SYM-010; Q-SYM-012 | O13: =COUNTIF($A$6:$A$187,A13) -> 1
A14: SYM-035 | B14: WEAVER | C14: Абсолютная реанимация | D14: 5 | E14: EXTERNAL_REGENERATION | F14: AUTOMATED_ABILITY_NODE | G14: SYM-033 | H14: ALL | J14: SYM-035 | K14: AUTOMATED_ACCEPTED | L14: ALL(SYM-033); BRANCH:EXTERNAL_REGENERATION | M14: SYM-035 | N14: Q-SYM-015 | O14: =COUNTIF($A$6:$A$187,A14) -> 1
A15: SYM-036 | B15: WEAVER | C15: Облако регенерона | D15: 6 | F15: AUTOMATED_ABILITY_NODE | G15: SYM-034; SYM-035 | H15: ANY | J15: SYM-036 | K15: AUTOMATED_ACCEPTED | L15: ANY(SYM-034,SYM-035) | M15: SYM-036 | O15: =COUNTIF($A$6:$A$187,A15) -> 1
A16: SYM-039 | B16: TAIPAN | C16: Смертельный яд | D16: 1 | F16: AUTOMATED_ABILITY_NODE | H16: ALL | J16: SYM-039 | K16: AUTOMATED_ACCEPTED | L16: ROOT | M16: SYM-039 | N16: Q-SYM-005; Q-SYM-017; Q-SYM-076; Q-APP-002 | O16: =COUNTIF($A$6:$A$187,A16) -> 1
A17: SYM-040 | B17: TAIPAN | C17: Проницаемая кожа | D17: 2 | F17: AUTOMATED_ABILITY_NODE | G17: SYM-039 | H17: ALL | J17: SYM-040 | K17: AUTOMATED_ACCEPTED | L17: ALL(SYM-039) | M17: SYM-040 | N17: Q-SYM-018 | O17: =COUNTIF($A$6:$A$187,A17) -> 1
A18: SYM-041 | B18: TAIPAN | C18: Плевок ядом | D18: 3 | F18: AUTOMATED_ABILITY_NODE | G18: SYM-040 | H18: ALL | J18: SYM-041 | K18: AUTOMATED_ACCEPTED | L18: ALL(SYM-040) | M18: SYM-041 | N18: Q-SYM-010; Q-SYM-075 | O18: =COUNTIF($A$6:$A$187,A18) -> 1
A19: SYM-042 | B19: TAIPAN | C19: Ослабляющий яд | D19: 4 | F19: AUTOMATED_ABILITY_NODE | G19: SYM-041 | H19: ALL | J19: SYM-042 | K19: AUTOMATED_ACCEPTED | L19: ALL(SYM-041) | M19: SYM-042 | N19: Q-SYM-005; Q-SYM-017; Q-SYM-019; Q-SYM-076; Q-APP-002 | O19: =COUNTIF($A$6:$A$187,A19) -> 1
A20: SYM-043 | B20: TAIPAN | C20: Ядовитый шип | D20: 5 | F20: AUTOMATED_ABILITY_NODE | G20: SYM-042 | H20: ALL | J20: SYM-043 | K20: AUTOMATED_ACCEPTED | L20: ALL(SYM-042) | M20: SYM-043 | N20: Q-SYM-010 | O20: =COUNTIF($A$6:$A$187,A20) -> 1
A21: SYM-044 | B21: TAIPAN | C21: Кумулятивный шип | D21: 6 | F21: AUTOMATED_ABILITY_NODE | G21: SYM-043 | H21: ALL | J21: SYM-044 | K21: AUTOMATED_ACCEPTED | L21: ALL(SYM-043) | M21: SYM-044 | N21: Q-SYM-010 | O21: =COUNTIF($A$6:$A$187,A21) -> 1
A22: SYM-045 | B22: TAIPAN | C22: Парализующий яд | D22: 7 | F22: AUTOMATED_ABILITY_NODE | G22: SYM-044 | H22: ALL | J22: SYM-045 | K22: AUTOMATED_ACCEPTED | L22: ALL(SYM-044) | M22: SYM-045 | N22: Q-SYM-005; Q-SYM-017; Q-SYM-020; Q-SYM-076; Q-APP-002 | O22: =COUNTIF($A$6:$A$187,A22) -> 1
A23: SYM-047 | B23: OWL | C23: Безупречное зрение | D23: 1 | F23: AUTOMATED_ABILITY_NODE | H23: ALL | J23: SYM-047 | K23: AUTOMATED_ACCEPTED | L23: ROOT | M23: SYM-047 | N23: Q-SYM-021 | O23: =COUNTIF($A$6:$A$187,A23) -> 1
A24: SYM-048 | B24: OWL | C24: Абсолютное ночное зрение | D24: 2 | F24: AUTOMATED_ABILITY_NODE | G24: SYM-047 | H24: ALL | J24: SYM-048 | K24: AUTOMATED_ACCEPTED | L24: ALL(SYM-047) | M24: SYM-048 | O24: =COUNTIF($A$6:$A$187,A24) -> 1
A25: SYM-049 | B25: OWL | C25: Абсолютное обоняние | D25: 3 | F25: AUTOMATED_ABILITY_NODE | G25: SYM-048 | H25: ALL | J25: SYM-049 | K25: AUTOMATED_ACCEPTED | L25: ALL(SYM-048) | M25: SYM-049 | O25: =COUNTIF($A$6:$A$187,A25) -> 1
A26: SYM-050 | B26: OWL | C26: Абсолютный слух | D26: 4 | F26: AUTOMATED_ABILITY_NODE | G26: SYM-049 | H26: ALL | J26: SYM-050 | K26: AUTOMATED_ACCEPTED | L26: ALL(SYM-049) | M26: SYM-050 | O26: =COUNTIF($A$6:$A$187,A26) -> 1
A27: SYM-051 | B27: OWL | C27: Звуковая картина | D27: 5 | F27: AUTOMATED_ABILITY_NODE | G27: SYM-050 | H27: ALL | J27: SYM-051 | K27: AUTOMATED_ACCEPTED | L27: ALL(SYM-050) | M27: SYM-051 | N27: Q-SYM-022 | O27: =COUNTIF($A$6:$A$187,A27) -> 1
A28: SYM-052 | B28: OWL | C28: Восприятие хищника | D28: 6 | F28: AUTOMATED_ABILITY_NODE | G28: SYM-051 | H28: ALL | J28: SYM-052 | K28: AUTOMATED_ACCEPTED | L28: ALL(SYM-051) | M28: SYM-052 | O28: =COUNTIF($A$6:$A$187,A28) -> 1
A29: SYM-054 | B29: TEACHER | C29: Развивайся, ученик | D29: 1 | F29: AUTOMATED_ABILITY_NODE | H29: ALL | J29: SYM-054 | K29: AUTOMATED_ACCEPTED | L29: ROOT | M29: SYM-054 | O29: =COUNTIF($A$6:$A$187,A29) -> 1
A30: SYM-055 | B30: TEACHER | C30: Век живи — век учись | D30: 2 | F30: AUTOMATED_ABILITY_NODE | G30: SYM-054 | H30: ALL | J30: SYM-055 | K30: AUTOMATED_ACCEPTED | L30: ALL(SYM-054) | M30: SYM-055 | N30: Q-SYM-085 | O30: =COUNTIF($A$6:$A$187,A30) -> 1
A31: SYM-056 | B31: TEACHER | C31: Практикуйтесь, ученики | D31: 3 | F31: AUTOMATED_ABILITY_NODE | G31: SYM-055 | H31: ALL | J31: SYM-056 | K31: AUTOMATED_ACCEPTED | L31: ALL(SYM-055) | M31: SYM-056 | O31: =COUNTIF($A$6:$A$187,A31) -> 1
A32: SYM-057 | B32: TEACHER | C32: Свети, ученик | D32: 4 | F32: AUTOMATED_ABILITY_NODE | G32: SYM-056 | H32: ALL | J32: SYM-057 | K32: AUTOMATED_ACCEPTED | L32: ALL(SYM-056) | M32: SYM-057 | N32: Q-SYM-023; Q-SYM-024 | O32: =COUNTIF($A$6:$A$187,A32) -> 1
A33: SYM-058 | B33: TEACHER | C33: Берегись невежд, ученик | D33: 5 | F33: AUTOMATED_ABILITY_NODE | G33: SYM-057 | H33: ALL | J33: SYM-058 | K33: AUTOMATED_ACCEPTED | L33: ALL(SYM-057) | M33: SYM-058 | O33: =COUNTIF($A$6:$A$187,A33) -> 1
A34: SYM-059 | B34: TEACHER | C34: Внимай, ученик | D34: 6 | F34: AUTOMATED_ABILITY_NODE | G34: SYM-058 | H34: ALL | J34: SYM-059 | K34: AUTOMATED_ACCEPTED | L34: ALL(SYM-058) | M34: SYM-059 | N34: Q-SYM-024; Q-SYM-025 | O34: =COUNTIF($A$6:$A$187,A34) -> 1
A35: SYM-061 | B35: ARMADILLO | C35: Подкожный панцирь | D35: 1 | F35: AUTOMATED_ABILITY_NODE | H35: ALL | J35: SYM-061 | K35: AUTOMATED_ACCEPTED | L35: ROOT | M35: SYM-061 | O35: =COUNTIF($A$6:$A$187,A35) -> 1
A36: SYM-062 | B36: ARMADILLO | C36: Здоров как буйвол | D36: 2 | F36: AUTOMATED_ABILITY_NODE | G36: SYM-061 | H36: ALL | J36: SYM-062 | K36: AUTOMATED_ACCEPTED | L36: ALL(SYM-061) | M36: SYM-062 | O36: =COUNTIF($A$6:$A$187,A36) -> 1
A37: SYM-063 | B37: ARMADILLO | C37: Не вырубишь! | D37: 3 | F37: AUTOMATED_ABILITY_NODE | G37: SYM-062 | H37: ALL | J37: SYM-063 | K37: AUTOMATED_ACCEPTED | L37: ALL(SYM-062) | M37: SYM-063 | O37: =COUNTIF($A$6:$A$187,A37) -> 1
A38: SYM-064 | B38: ARMADILLO | C38: Не подчиняюсь! | D38: 4 | F38: AUTOMATED_ABILITY_NODE | G38: SYM-063 | H38: ALL | J38: SYM-064 | K38: AUTOMATED_ACCEPTED | L38: ALL(SYM-063) | M38: SYM-064 | O38: =COUNTIF($A$6:$A$187,A38) -> 1
A39: SYM-065 | B39: ARMADILLO | C39: Не сдвинешь! | D39: 5 | F39: AUTOMATED_ABILITY_NODE | G39: SYM-064 | H39: ALL | J39: SYM-065 | K39: AUTOMATED_ACCEPTED | L39: ALL(SYM-064) | M39: SYM-065 | O39: =COUNTIF($A$6:$A$187,A39) -> 1
A40: SYM-066 | B40: ARMADILLO | C40: Поднять щиты! | D40: 6 | F40: AUTOMATED_ABILITY_NODE | G40: SYM-065 | H40: ALL | J40: SYM-066 | K40: AUTOMATED_ACCEPTED | L40: ALL(SYM-065) | M40: SYM-066 | N40: Q-SYM-026 | O40: =COUNTIF($A$6:$A$187,A40) -> 1
A41: SYM-068 | B41: DRAGON | C41: Горючая слюна | D41: 1 | F41: AUTOMATED_ABILITY_NODE | H41: ALL | J41: SYM-068 | K41: AUTOMATED_ACCEPTED | L41: ROOT | M41: SYM-068 | N41: Q-SYM-027 | O41: =COUNTIF($A$6:$A$187,A41) -> 1
A42: SYM-069 | B42: DRAGON | C42: Огнеупорная глотка | D42: 2 | F42: AUTOMATED_ABILITY_NODE | G42: SYM-068 | H42: ALL | J42: SYM-069 | K42: AUTOMATED_ACCEPTED | L42: ALL(SYM-068) | M42: SYM-069 | N42: Q-SYM-028 | O42: =COUNTIF($A$6:$A$187,A42) -> 1
...

Sheet 10_Способности
A1: Автоматизируемые способности симбионтов
A2: Только 167 способностей, принятых для исполнения приложением. Флаги Combat/Peace отделены от доступности команды игроку, чтобы пассивы и автотриггеры не становились ручными кнопками.
A5: AbilityID | B5: SpeciesKey | C5: NodeRef | D5: Название | E5: AbilityKind | F5: AutomationStatus | G5: CombatAllowed | H5: PlayerCommandCombat | I5: PeaceAllowed | J5: PlayerCommandPeace | K5: CombatBehavior | L5: PeaceBehavior | M5: Source Rule IDs | N5: Source Question IDs | O5: Priority | P5: Status | Q5: ID unique
