Workbook

Sheet 00_Паспорт
A1: SYMBIOSIS V7 — Effects & Diseases Registry v1.2
A2: Дополняющий реестр состояний, сочетаний и runtime-схем • 2026-07-31 • окончательные решения по COMB-031 и GAP-030
A4: Параметр | B4: Значение | C4: Статус | D4: Параметр | E4: Значение | F4: Статус | G4: Параметр | H4: Значение | I4: Статус | J4: Примечание
A5: Версия | B5: v1.2 | C5: PASS | D5: Семейств | E5: 24 | F5: PASS | G5: Типов эффектов | H5: 67 | I5: PASS | J5: Стабильные supplemental ID: 66 моделируемых типов + 1 явная граница NOT_MODELED
A6: Болезней | B6: 10 | C6: PASS | D6: Профилей ядов | E6: 8 | F6: PASS | G6: Травм/ран | H6: 8 | I6: PASS | J6: Неполные модели помечены явно
A7: Правил сочетаний | B7: 67 | C7: PASS | D7: Пар в матрице | E7: 300 | F7: PASS | G7: QA | H7: 98/98 PASS | I7: PASS | J7: Все исходные и новые сценарии пройдены
A8: Rules source index | B8: 306 | C8: PASS | D8: Payload JSON | E8: 185 | F8: PASS | G8: Baseline files | H8: 9 | I8: PASS | J8: Байты согласованных файлов не меняются
A9: Роль | B9: SUPPLEMENTAL_NORMATIVE_REGISTRY | C9: PASS | D9: Manifest v1.1 | E9: NOT_MODIFIED | F9: PASS | G9: Baseline tuple | H9: Rules v1.6 | Character-Skills-Symbionts v1.1 | Items v1.5_with_icons | Bestiary v1.3 | Sentient v1.2 | I9: PASS | J9: Реестр не включён задним числом в согласованный манифест
A10: Неразрешённые GAP | B10: 0 | C10: PASS | D10: Прочие локальные ветви | E10: 0 | F10: PASS | G10: Нарративный текст | H10: NO_MECHANICAL_EFFECT | I10: PASS | J10: Все авторские развилки закрыты; слепота явно исключена из модели приложения
A11: Итог | B11: READY_AS_SUPPLEMENT_V1.2 | C11: PASS | D11: Формат | E11: XLSX | F11: PASS | G11: Дата | H11: 2026-07-31 | I11: PASS | J11: Единый машинно-читаемый контракт
A13: Нормативные границы
A14: 1 | B14: Все девять файлов базовой линии являются неизменяемыми согласованными входами.
A15: 2 | B15: Этот реестр вводит ID, схему экземпляра и разрешители сочетаний, но не переписывает исходные Rule ID.
A16: 3 | B16: При расхождении приоритет имеет конкретная карточка согласованного Rules/Q&A; строка source index служит навигацией.
A17: 4 | B17: Авторских решений не требуется; NOT_MODELED является явной границей приложения, а не незакрытым GAP.

Sheet 01_Семейства
A1: Семейства состояний
A2: Закрытый уровень классификации для матрицы сочетаний. Он не заменяет конкретные EffectTypeID и частные Rule ID.
A4: FamilyCode | B4: Название | C4: Область | D4: State bucket | E4: Композиция по умолчанию | F4: Стадия ответа | G4: Rule refs | H4: ID count
A5: FAM-LIFECYCLE | B5: Жизненный цикл | C5: Тяжёлое ранение, таймер смерти, окончательная смерть | D5: actorFlags / currentEffects | E5: TERMINAL_OR_SOURCE_SPECIFIC | F5: AFTER_DAMAGE_RECALC | G5: CORE-152–156; CORE-182; CORE-222 | H5: =COUNTIF($A$5:$A$28,A5) -> 1
A6: FAM-CONSCIOUSNESS | B6: Сознание | C6: Бессознательность и сон | D6: actorFlags / currentEffects | E6: RESTRICTIONS_UNION | F6: AFTER_EACH_CONSEQUENCE | G6: CORE-061; CORE-103; MON-075 | H6: =COUNTIF($A$5:$A$28,A6) -> 1
A7: FAM-PHYSICAL_CONTROL | B7: Физический контроль | C7: Паралич, оглушение, захват, удержание, опутывание, кокон | D7: currentEffects | E7: RESTRICTIONS_UNION; MAX_ACTION_PENALTY; SOURCES_INDEPENDENT | F7: BEFORE_APPLY_CONTROL | G7: CORE-103; CORE-138; CORE-141; CORE-143–144 | H7: =COUNTIF($A$5:$A$28,A7) -> 1
A8: FAM-MENTAL_CONTROL | B8: Ментальный контроль | C8: Принуждение, бегство, внешний контроллер | D8: currentEffects / controlLease | E8: ONE_EFFECTIVE_CONTROLLER_BY_PRIORITY | F8: BEFORE_APPLY_CONTROL | G8: CORE-178; CORE-181; CORE-221; MON-038 | H8: =COUNTIF($A$5:$A$28,A8) -> 1
A9: FAM-MOBILITY_POSITION | B9: Положение и мобильность | C9: Сбит с ног, выгодная позиция, вынужденное перемещение | D9: currentEffects | E9: RESTRICTIONS_UNION | F9: COMMAND_FILTER | G9: CORE-138–144; MON-165 | H9: =COUNTIF($A$5:$A$28,A9) -> 1
A10: FAM-ACTION_ECONOMY | B10: Действия и серия | C10: Бонусы и штрафы действий, пропуск хода, следующий ход/серия | D10: currentEffects | E10: SOURCE_SPECIFIC; MIN_ZERO | F10: TURN_START_OR_CONSUME | G10: CORE-031; CORE-043–048; CORE-070; MON-150; MON-160 | H10: =COUNTIF($A$5:$A$28,A10) -> 1
A11: FAM-TRAUMA | B11: Травмы | C11: Зональные травмы и отключение конечности | D11: currentTraumas / derivedProjection | E11: SAME_ZONE_ADDITIVE; DIFFERENT_ZONE_INDEPENDENT | F11: AFTER_ACTUAL_DAMAGE | G11: CORE-117; CORE-119–121 | H11: =COUNTIF($A$5:$A$28,A11) -> 1
A12: FAM-WOUND_BLEEDING | B12: Раны и кровотечения | C12: Формализованная рана, кровотечение и профилактика через рану | D12: currentWounds | E12: PER_EVENT_PER_REGION; BLEEDING_PER_WOUND | F12: SOURCE_SPECIFIC | G12: CORE-059; CORE-063 | H12: =COUNTIF($A$5:$A$28,A12) -> 1
A13: FAM-DISEASE | B13: Болезни | C13: Назначенные мастером заболевания и их модификаторы | D13: currentEffects | E13: SAME_DISEASE_NO_STACK; DIFFERENT_DISEASE_ADD | F13: ASSIGN_REMOVE_RECALC | G13: MON-075–087; CQA-060 | H13: =COUNTIF($A$5:$A$28,A13) -> 1
A14: FAM-POISON | B14: Яды | C14: POISON payload, урон, дебафф, счётчик и зональный паралич | D14: currentEffects / activeCoatings | E14: PROFILE_SPECIFIC | F14: IMMUNITY_BEFORE_ROLL | G14: CORE-109; CORE-228; SYM-039; SYM-042; SYM-045 | H14: =COUNTIF($A$5:$A$28,A14) -> 1
A15: FAM-FIRE | B15: Огонь и горение | C15: Бинарное горение персонажа и огненные ответы | D15: currentEffects | E15: ONE_BINARY_STATE; MAX_REMAINING_DURATION | F15: BEFORE_APPLY_BURN | G15: CORE-112; CORE-114 | H15: =COUNTIF($A$5:$A$28,A15) -> 1
A16: FAM-PERIODIC_DAMAGE | B16: Периодический урон | C16: Автономные и поддерживаемые тики урона | D16: currentEffects | E16: PER_INSTANCE; ORDER_BY_CREATED_AT_UUID | F16: TIME_PHASE_1 | G16: CORE-101; AQA-024 | H16: =COUNTIF($A$5:$A$28,A16) -> 1
... A28: FAM-NARRATIVE | B28: Нарративная пометка | C28: Текст без механического изменения | D28: narrativeMarkers | E28: NO_MECHANICAL_EFFECT | F28: NONE | G28: AQ2-009; AQA-045 | H28: =COUNTIF($A$5:$A$28,A28) -> 1

Sheet 02_Типы_эффектов
A1: Каталог типов эффектов
A2: Стабильные EffectTypeID, целевой bucket, stack/removal policy и граница автоматизации.
A4: EffectTypeID | B4: Название | C4: FamilyCode | D4: State bucket | E4: Stack policy | F4: Timer policy | G4: Removal policy | H4: Семантика | I4: State writes | J4: Rule refs | K4: Automation | L4: Schema status | M4: ID count
A5: EFF-LIFE-DEAD | B5: Окончательная смерть | C5: FAM-LIFECYCLE | D5: actorFlags | E5: TERMINAL_SINGLETON | F5: SOURCE_SPECIFIC_OR_EXPLICIT | G5: NONE | H5: Терминальное состояние; обычное лечение и снятие эффекта не воскрешают | I5: dead=true | J5: CORE-155–156; CQA-001 | K5: AUTOMATED | L5: DEFINED | M5: =COUNTIF($A$5:$A$71,A5) -> 1
A6: EFF-LIFE-SEVERE_WOUND | B6: Тяжёлое ранение | C6: FAM-LIFECYCLE | D6: actorFlags | E6: SINGLETON | F6: SOURCE_SPECIFIC_OR_EXPLICIT | G6: SOURCE_OR_REANIMATION | H6: HP=0; специальная дееспособность возможна только по прямому источнику | I6: severeWound=true | J6: CORE-152; CORE-182; CORE-222 | K6: AUTOMATED | L6: DEFINED | M6: =COUNTIF($A$5:$A$71,A6) -> 1
A7: EFF-LIFE-DEATH_TIMER | B7: Таймер смерти | C7: FAM-LIFECYCLE | D7: currentEffects | E7: SINGLETON_BY_ACTOR | F7: SOURCE_SPECIFIC_OR_EXPLICIT | G7: EXPLICIT_REANIMATION_OR_EXPIRY | H7: Точный остаток хранится без округления интерфейсом | I7: deathTimer | J7: CORE-153–156 | K7: AUTOMATED | L7: DEFINED | M7: =COUNTIF($A$5:$A$71,A7) -> 1
A8: EFF-CONSCIOUS-UNCONSCIOUS | B8: Без сознания | C8: FAM-CONSCIOUSNESS | D8: actorFlags | E8: BINARY_SOURCE_TRACKED | F8: SOURCE_SPECIFIC_OR_EXPLICIT | G8: SOURCE_SPECIFIC | H8: Нет действий, реакций и активной защиты; броня работает | I8: unconscious=true | J8: CORE-103; MON-075; CORE-222 | K8: AUTOMATED | L8: DEFINED | M8: =COUNTIF($A$5:$A$71,A8) -> 1
A9: EFF-CONSCIOUS-SLEEP | B9: Сон | C9: FAM-CONSCIOUSNESS | D9: currentEffects | E9: PER_SOURCE | F9: SOURCE_SPECIFIC_OR_EXPLICIT | G9: DAMAGE_OR_SPECIFIC_ANTIDOTE | H9: Фармацевтический сон снимается любым уроном либо CORE-060 | I9: currentEffects[] | J9: CORE-061; CORE-103 | K9: AUTOMATED | L9: DEFINED | M9: =COUNTIF($A$5:$A$71,A9) -> 1
A10: EFF-CONTROL-PARALYSIS | B10: Паралич | C10: FAM-PHYSICAL_CONTROL | D10: currentEffects | E10: PER_SOURCE | F10: SOURCE_SPECIFIC_OR_EXPLICIT | G10: SOURCE_SPECIFIC | H10: Нет физических действий и активной защиты; чисто ментальные действия условно возможны | I10: currentEffects[] | J10: CORE-062; CORE-103; MON-150 | K10: AUTOMATED | L10: DEFINED | M10: =COUNTIF($A$5:$A$71,A10) -> 1
A11: EFF-CONTROL-STUN | B11: Оглушение | C11: FAM-PHYSICAL_CONTROL | D11: currentEffects | E11: PER_SOURCE | F11: SOURCE_SPECIFIC_OR_EXPLICIT | G11: EXPIRY_OR_CONTROL_CLEANSE | H11: Пропуск указанных ходов и реакций; частное правило может сохранить защиты | I11: currentEffects[] | J11: CORE-031; CORE-103 | K11: AUTOMATED | L11: DEFINED | M11: =COUNTIF($A$5:$A$71,A11) -> 1
A12: EFF-CONTROL-TURN_SKIP | B12: Пропуск хода | C12: FAM-ACTION_ECONOMY | D12: currentEffects | E12: PER_SOURCE | F12: SOURCE_SPECIFIC_OR_EXPLICIT | G12: CONSUME_NAMED_TURNS | H12: Нет боевых и небоевых действий; защита вне хода только по прямому разрешению | I12: currentEffects[] | J12: CORE-103; MON-124 | K12: AUTOMATED | L12: DEFINED | M12: =COUNTIF($A$5:$A$71,A12) -> 1
A13: EFF-CONTROL-GRAPPLE | B13: Захват | C13: FAM-PHYSICAL_CONTROL | D13: currentEffects | E13: PER_SOURCE_TARGET | F13: SOURCE_SPECIFIC_OR_EXPLICIT | G13: RELEASE_OR_SOURCE_BREAK | H13: Модификаторы CORE-138; число параллельных захватов ограничено свободными хватательными конечностями | I13: CaptureState | J13: CORE-138; MON-117; MON-127; MON-133 | K13: AUTOMATED | L13: DEFINED | M13: =COUNTIF($A$5:$A$71,A13) -> 1
A14: EFF-CONTROL-LIMB_HOLD | B14: Удержание конечности | C14: FAM-PHYSICAL_CONTROL | D14: currentEffects | E14: PER_SOURCE_LIMB | F14: SOURCE_SPECIFIC_OR_EXPLICIT | G14: CONTESTED_RELEASE | H14: Предусловие для травмирующего/болевого приёма | I14: currentEffects[] | J14: CORE-141 | K14: AUTOMATED | L14: DEFINED | M14: =COUNTIF($A$5:$A$71,A14) -> 1
A15: EFF-CONTROL-PAIN_HOLD | B15: Болевой приём | C15: FAM-PHYSICAL_CONTROL | D15: currentEffects | E15: PER_SOURCE | F15: SOURCE_SPECIFIC_OR_EXPLICIT | G15: CONTESTED_RELEASE | H15: При неуспешном самообладании доступны только защитные действия борьбы | I15: currentEffects[] | J15: CORE-143 | K15: AUTOMATED | L15: DEFINED | M15: =COUNTIF($A$5:$A$71,A15) -> 1
A16: EFF-CONTROL-CHOKE_HOLD | B16: Удушающий приём | C16: FAM-PHYSICAL_CONTROL | D16: currentEffects | E16: PER_SOURCE | F16: SOURCE_SPECIFIC_OR_EXPLICIT | G16: BREAK_GRAPPLE_OR_RELEASE | H16: Требует цепочки захват → выгодная позиция → удушение | I16: currentEffects[] | J16: CORE-144 | K16: AUTOMATED | L16: DEFINED | M16: =COUNTIF($A$5:$A$71,A16) -> 1
... A71: EFF-EQUIPMENT-STUCK | B71: Застрявшее оружие | C71: FAM-ITEM_STATE | D71: currentEffects | E71: PER_ITEM_TARGET | F71: SOURCE_SPECIFIC_OR_EXPLICIT | G71: ACTION_AND_CHECK | H71: Освобождение по конкретной карточке | I71: itemLink | J71: MON-129 | K71: AUTOMATED | L71: DEFINED | M71: =COUNTIF($A$5:$A$71,A71) -> 1

Sheet 03_Болезни
A1: Канонический каталог болезней
A2: Назначение и снятие выполняет мастер; disease modifiers могут опускать effectiveStat ниже 1, после чего применяется MON-075.
A4: DiseaseID | B4: Название | C4: Status | D4: Assignment | E4: Duration | F4: Stat modifiers JSON | G4: Check modifiers JSON | H4: Periodic | I4: Stacking | J4: Unconscious projection | K4: Effect family | L4: Is poison | M4: Rule refs | N4: Locator | O4: Примечание | P4: ID count
A5: DIS-POISONING | B5: Отравление | C5: ACTIVE | D5: GM_ASSIGN_REMOVE | E5: UNTIL_GM_REMOVE_OR_SPECIFIC_CURE | F5: {"S":-2,"M":-2} | G5: {} | H5: NONE | I5: NO_STACK_SAME_ID | J5: FOR_EACH_REDUCED_STAT_IF_EFFECTIVE_X_PLUS_EFFECTIVE_Z_LT_1 | K5: DISEASE | L5: false | M5: MON-076 | N5: Реестр правил!B230:AH230 | O5: Название не делает болезнь POISON | P5: =COUNTIF($A$5:$A$14,A5) -> 1
A6: DIS-RHINITIS | B6: Насморк | C6: ACTIVE | D6: GM_ASSIGN_REMOVE | E6: UNTIL_GM_REMOVE_OR_SPECIFIC_CURE | F6: {"M":-2} | G6: {} | H6: NONE | I6: NO_STACK_SAME_ID | J6: FOR_EACH_REDUCED_STAT_IF_EFFECTIVE_X_PLUS_EFFECTIVE_Z_LT_1 | K6: DISEASE | L6: false | M6: MON-077 | N6: Реестр правил!B231:AH231 | P6: =COUNTIF($A$5:$A$14,A6) -> 1
A7: DIS-FEVER | B7: Жар | C7: ACTIVE | D7: GM_ASSIGN_REMOVE | E7: UNTIL_GM_REMOVE_OR_SPECIFIC_CURE | F7: {"M":-10} | G7: {} | H7: NONE | I7: NO_STACK_SAME_ID | J7: FOR_EACH_REDUCED_STAT_IF_EFFECTIVE_X_PLUS_EFFECTIVE_Z_LT_1 | K7: DISEASE | L7: false | M7: MON-078 | N7: Реестр правил!B232:AH232 | P7: =COUNTIF($A$5:$A$14,A7) -> 1
A8: DIS-SCABIES | B8: Чесотка | C8: ACTIVE | D8: GM_ASSIGN_REMOVE | E8: UNTIL_GM_REMOVE_OR_SPECIFIC_CURE | F8: {"I":-4,"C":-4,"D":-2} | G8: {} | H8: NONE | I8: NO_STACK_SAME_ID | J8: FOR_EACH_REDUCED_STAT_IF_EFFECTIVE_X_PLUS_EFFECTIVE_Z_LT_1 | K8: DISEASE | L8: false | M8: MON-079 | N8: Реестр правил!B233:AH233 | P8: =COUNTIF($A$5:$A$14,A8) -> 1
A9: DIS-PNEUMONIA | B9: Пневмония | C9: ACTIVE | D9: GM_ASSIGN_REMOVE | E9: UNTIL_GM_REMOVE_OR_SPECIFIC_CURE | F9: {"M":-14,"S":-12,"D":-12} | G9: {} | H9: HP_MINUS_10_EACH_FULL_DAY | I9: NO_STACK_SAME_ID | J9: FOR_EACH_REDUCED_STAT_IF_EFFECTIVE_X_PLUS_EFFECTIVE_Z_LT_1 | K9: DISEASE | L9: false | M9: MON-080; MON-087 | N9: Реестр правил!B234:AH234 | O9: Периодический урон явно разрешён | P9: =COUNTIF($A$5:$A$14,A9) -> 1
A10: DIS-MIGRAINE | B10: Мигрень | C10: ACTIVE | D10: GM_ASSIGN_REMOVE | E10: UNTIL_GM_REMOVE_OR_SPECIFIC_CURE | F10: {"I":-6,"C":-2} | G10: {} | H10: NONE | I10: NO_STACK_SAME_ID | J10: FOR_EACH_REDUCED_STAT_IF_EFFECTIVE_X_PLUS_EFFECTIVE_Z_LT_1 | K10: DISEASE | L10: false | M10: MON-081 | N10: Реестр правил!B235:AH235 | P10: =COUNTIF($A$5:$A$14,A10) -> 1
A11: DIS-FLATULENCE | B11: Метеоризм | C11: ACTIVE | D11: GM_ASSIGN_REMOVE | E11: UNTIL_GM_REMOVE_OR_SPECIFIC_CURE | F11: {"C":-5} | G11: {"STEALTH":-5} | H11: NONE | I11: NO_STACK_SAME_ID | J11: FOR_EACH_REDUCED_STAT_IF_EFFECTIVE_X_PLUS_EFFECTIVE_Z_LT_1 | K11: DISEASE | L11: false | M11: MON-082 | N11: Реестр правил!B236:AH236 | P11: =COUNTIF($A$5:$A$14,A11) -> 1
A12: DIS-SKIN_GROWTHS | B12: Образования на коже | C12: ACTIVE | D12: GM_ASSIGN_REMOVE | E12: UNTIL_GM_REMOVE_OR_SPECIFIC_CURE | F12: {"C":-6} | G12: {} | H12: NONE | I12: NO_STACK_SAME_ID | J12: FOR_EACH_REDUCED_STAT_IF_EFFECTIVE_X_PLUS_EFFECTIVE_Z_LT_1 | K12: DISEASE | L12: false | M12: MON-083 | N12: Реестр правил!B237:AH237 | P12: =COUNTIF($A$5:$A$14,A12) -> 1
A13: DIS-ITCHY_SKIN_GROWTHS | B13: Чешущиеся образования на коже | C13: ACTIVE | D13: GM_ASSIGN_REMOVE | E13: UNTIL_GM_REMOVE_OR_SPECIFIC_CURE | F13: {"D":-3,"C":-6} | G13: {} | H13: NONE | I13: NO_STACK_SAME_ID | J13: FOR_EACH_REDUCED_STAT_IF_EFFECTIVE_X_PLUS_EFFECTIVE_Z_LT_1 | K13: DISEASE | L13: false | M13: MON-084 | N13: Реестр правил!B238:AH238 | P13: =COUNTIF($A$5:$A$14,A13) -> 1
A14: DIS-PESTILENCE | B14: Поветрие | C14: TRACE_ONLY | D14: SOURCE_SPECIFIC_TREATMENT | E14: SOURCE_RULE | F14: {"S":-3,"D":-3,"M":-3} | G14: {} | H14: DAILY_DEGRADATION; FLOWER_ON_DEATH | I14: SOURCE_SPECIFIC | J14: FOR_EACH_REDUCED_STAT_IF_EFFECTIVE_X_PLUS_EFFECTIVE_Z_LT_1 | K14: DISEASE | L14: false | M14: MON-058–060 | N14: Реестр правил (MON-058–060) | O14: Не автоматизируется; при любом S/D/M<1 тяжёлая рана | P14: =COUNTIF($A$5:$A$14,A14) -> 1

Sheet 04_Яды
A1: Профили ядов
A2: POISON отделён от болезни «Отравление». Абсолютный иммунитет применяется до бросков и payload.
A4: PoisonProfileID | B4: Название | C4: Effect family | D4: Source kind | E4: Payload kind | F4: Payload | G4: Repeat policy | H4: Stacking key | I4: Immunity stage | J4: Blocked payload | K4: Rule refs | L4: Примечание | M4: ID count
A5: POI-TAIPAN-DEADLY | B5: Смертельный яд Тайпана | C5: POISON | D5: SYMBIOTIC | E5: PERIODIC_DAMAGE | F5: R20/5+L per turn; duration R20/2 | G5: REPLACE_STRENGTH_AND_DURATION_RESTART | H5: TARGET | I5: IMMUNE_BEFORE_ROLL | J5: damage,state,counter,secondary effects | K5: SYM-039 | L5: Первый тик в конце следующего хода цели; оружие даёт половину урона за тик | M5: =COUNTIF($A$5:$A$12,A5) -> 1
A6: POI-TAIPAN-WEAKENING | B6: Ослабляющий яд Тайпана | C6: POISON | D6: SYMBIOTIC | E6: STAT_DEBUFF | F6: K=max(0,R20+L−Z); S/D/M decrease, each not below 1; duration R20/2 | G6: REPLACE_STRENGTH_AND_DURATION | H6: TARGET | I6: IMMUNE_BEFORE_ROLL | J6: absolute immunity: all; SYM-144: poison damage/control only | K6: SYM-042 | L6: Ослабление характеристик SYM-042 не является уроном или контролем и проходит через SYM-144 | M6: =COUNTIF($A$5:$A$12,A6) -> 1
A7: POI-TAIPAN-PARALYTIC | B7: Парализующий яд Тайпана | C7: POISON | D7: SYMBIOTIC | E7: LIMB_DISABLE | F7: if R20+L>Z: humanoid active limb; duration R20/3; nonhumanoid secondary paralysis skipped | G7: PER_DISTINCT_LIMB | H7: TARGET_LIMB | I7: IMMUNE_BEFORE_ROLL | J7: damage,state,counter,secondary effects | K7: SYM-045 | L7: На негуманоида паралич не действует; попадание и остальные последствия сохраняются При травме той же конечности числовые штрафы не складываются: применяется наиболее строгий; ограничения и снятие источников независимы. | M7: =COUNTIF($A$5:$A$12,A7) -> 1
A8: POI-VIVISECTOR-ENTRY | B8: Слизь Вивисектора при входе | C8: POISON | D8: CANONICAL | E8: DIRECT_POISON_DAMAGE | F8: R12+8 once on entry | G8: ONE_EVENT_DEDUP | H8: SOURCE_TARGET_ENTRY | I8: IMMUNE_BEFORE_ROLL | J8: damage,state,counter,secondary effects | K8: MON-098; MON-100 | L8: Дублирующие описания не должны дать двойной урон | M8: =COUNTIF($A$5:$A$12,A8) -> 1
A9: POI-VIVISECTOR-FUMES | B9: Ядовитые пары Вивисектора | C9: POISON | D9: CANONICAL | E9: POISON_DAMAGE_CHECK | F9: end target turn in 6m; R20+Z vs R20+12; fail R12 damage | G9: PER_SOURCE_TARGET_TURN | H9: SOURCE_TARGET | I9: IMMUNE_BEFORE_ROLL | J9: damage,state,counter,secondary effects | K9: MON-099 | L9: По одной проверке на каждого Вивисектора в конце хода цели; источники разрешаются отдельно в стабильном порядке | M9: =COUNTIF($A$5:$A$12,A9) -> 1
A10: POI-SWADDLER-SEQUENCE | B10: Яд Пеленальщицы | C10: POISON | D10: CANONICAL | E10: FAIL_COUNTER_CONTROL | F10: first fail −2 next series; second consecutive fail paralysis 5 own turns | G10: SUCCESS_RESETS; SECOND_REPLACES_FIRST | H10: SOURCE_TARGET | I10: IMMUNE_BEFORE_ROLL | J10: damage,state,counter,secondary effects | K10: MON-150 | L10: Счётчик отдельный для пары sourceId+targetId; успех сбрасывает только этот счётчик | M10: =COUNTIF($A$5:$A$12,A10) -> 1
A11: POI-FELIDA-NUMBING | B11: Плевок Фелиды-Тайпана | C11: POISON | D11: CANONICAL | E11: LIMB_DISABLE | F11: R20+7>Z; random active limb; duration round_half_up(R20/3), min 1 | G11: PER_LIMB | H11: TARGET_LIMB | I11: IMMUNE_BEFORE_ROLL | J11: damage,state,counter,secondary effects | K11: MON-169 | L11: Округление до ближайшего целого, ровно 0,5 вверх; положительная длительность минимум 1 ход При травме той же конечности числовые штрафы не складываются: применяется наиболее строгий; ограничения и снятие источников независимы. | M11: =COUNTIF($A$5:$A$12,A11) -> 1
A12: POI-FOOD_ALCOHOL | B12: Пищевое/алкогольное отравление | C12: POISON | D12: ORDINARY | E12: SOURCE_SPECIFIC | F12: By CORE-110 | G12: SOURCE_SPECIFIC | H12: TARGET | I12: IMMUNE_BEFORE_ROLL | J12: damage,state,counter,secondary effects | K12: CORE-110 | L12: Не смешивать с болезнью DIS-POISONING | M12: =COUNTIF($A$5:$A$12,A12) -> 1

Sheet 05_Травмы_и_раны
A1: Травмы, тяжёлые ранения и открытые раневые состояния
A2: Чётко разделены автоматизируемые травмы и состояния, для которых канон пока задаёт только снятие/упоминание.
A4: InjuryID | B4: Название | C4: Kind | D4: State bucket | E4: Trigger | F4: Payload | G4: Stacking | H4: Consequence | I4: Recovery | J4: Rule refs | K4: Примечание | L4: ID count
A5: TRM-LIMB | B5: Травма конечности | C5: TRAUMA | D5: currentTraumas | E5: R20+Z < actualDamage | F5: injury=max(0,round_math(R12−Z/3)) | G5: ADDITIVE_SAME_LIMB | H5: DISABLED_IF_TOTAL_GT_6 | I5: EXPLICIT_ABILITY_PROCEDURE_OR_GM | J5: CORE-117; CORE-119 | K5: Автоматического восстановления нет При временном онемении той же конечности применяется наиболее строгий числовой штраф; ограничения объединяются, снятие одного состояния не снимает другое. | L5: =COUNTIF($A$5:$A$12,A5) -> 1
A6: TRM-HEAD | B6: Травма головы | C6: TRAUMA | D6: currentTraumas | E6: R20+Z < actualDamage | F6: CORE-120 | G6: PER_EVENT | H6: SOURCE_SPECIFIC | I6: EXPLICIT_ABILITY_PROCEDURE_OR_GM | J6: CORE-117; CORE-120 | K6: Травма головы не создаёт слепоту: потеря зрения исключена из модели приложения | L6: =COUNTIF($A$5:$A$12,A6) -> 1
A7: TRM-TORSO | B7: Травма корпуса | C7: TRAUMA | D7: currentTraumas | E7: R20+Z < actualDamage | F7: one-time extra HP loss | G7: PER_EVENT | H7: NO_RECURSIVE_TRAUMA | I7: EXPLICIT_ABILITY_PROCEDURE_OR_GM | J7: CORE-117; CORE-121 | L7: =COUNTIF($A$5:$A$12,A7) -> 1
A8: TRM-MULTILIMB | B8: Травма многоконечного существа | C8: TRAUMA | D8: currentTraumas | E8: SOURCE_SPECIFIC | F8: not automated | G8: TRACE_ONLY | H8: UNSUPPORTED_ANATOMY_POLICY | I8: EXPLICIT_ABILITY_PROCEDURE_OR_GM | J8: CORE-122–124 | K8: Не автоматизируется | L8: =COUNTIF($A$5:$A$12,A8) -> 1
A9: WND-SEVERE | B9: Тяжёлое ранение | C9: WOUND | D9: actorFlags | E9: HP reaches 0 after protections | F9: severeWound=true; death timer | G9: SINGLETON | H9: NEW_HP_LOSS_GT_0_CAUSES_DEATH | I9: SOURCE_SPECIFIC | J9: CORE-152–156; CORE-182 | K9: Для обычных монстров одновременно unconscious | L9: =COUNTIF($A$5:$A$12,A9) -> 1
A10: WND-DEATH_TIMER | B10: Таймер смерти | C10: WOUND_TIMER | D10: currentEffects | E10: severe wound created | F10: D6 turns or D6×5m; exact remainder | G10: SINGLETON | H10: EXPIRE_TO_DEAD_OR_REANIMATE | I10: SOURCE_SPECIFIC | J10: CORE-153 | K10: Дубль ×4 применяется один раз | L10: =COUNTIF($A$5:$A$12,A10) -> 1
A11: WND-GENERIC | B11: Рана | C11: WOUND | D11: currentWounds | E11: SOURCE_HAS_CREATES_WOUND_OR_GM | F11: one wound per event with regionId | G11: PER_EVENT_AND_REGION | H11: FORMAL_WOUND_FOR_TARGETED_TREATMENT | I11: EXPLICIT_TREATMENT_OR_GM_ONLY | J11: CORE-059 | K11: Автоматического заживления нет | L11: =COUNTIF($A$5:$A$12,A11) -> 1
A12: WND-BLEEDING | B12: Кровотечение | C12: WOUND | D12: currentWounds | E12: SOURCE_EXPLICIT_DAMAGE_PER_TICK | F12: damagePerTick; tick=end_of_target_turn | G12: PER_WOUND_INSTANCE | H12: CORE-063_REMOVES_ALL | I12: CORE-063_OR_EXPLICIT_TREATMENT_OR_GM | J12: CORE-063 | K12: Значение урона по умолчанию не вводится | L12: =COUNTIF($A$5:$A$12,A12) -> 1

Sheet 06_Карта_источников
A1: Индекс источников состояний Rules v1.6
A2: 306 релевантных карточек. Нормализация FamilyCode служит поиску; исходная карточка остаётся нормативной.
A4: SourceMapID | B4: Rule ID | C4: Название | D4: Статус | E4: Режим реализации | F4: Категория | G4: Normalized family | H4: Mapping confidence | I4: State result | J4: Algorithm excerpt | K4: Exceptions excerpt | L4: Source ref | M4: Locator | N4: Source record SHA-256 | O4: Mapping role
A5: SRCMAP-001 | B5: CORE-004 | C5: Навык Единого «Идущий вслед за болью» | D5: Активно | E5: Реализовать в игровом ядре | F5: раса / пассивный навык. | G5: FAM-NARRATIVE | H5: LOW_CONFIDENCE_INDEX_ONLY | I5: постоянный навык и модификатор. | J5: навык добавляется автоматически, не занимает слот; к указанным проверкам +15. | K5: социальная механика пыток вне охвата; бонус к самообладанию при пожаре применяется по CORE-114. | L5: §3.2.6.1.1, стр. 48. | M5: Реестр правил!B3:AH3 | N5: b0e9fcdd3f9f348f8329b5b04d16a567fa4e8b245fd7240f04908993286d9e0d | O5: DISCOVERY_INDEX_ONLY; SOURCE_RULE_REMAINS_NORMATIVE
A6: SRCMAP-002 | B6: CORE-060 | C6: Отвар, приводящий в сознание | D6: Активно | E6: Реализовать в игровом ядре | F6: фармацевтика / реанимация. | G6: FAM-LIFECYCLE | H6: EXPLICIT | I6: цель в сознании, HP 1 при реанимации. | J6: снять тяжёлое ранение и установить HP=1; прекратить снотворное и паралитик без проверок; остановить таймер смерти. | K6: окончательную смерть не отменяет. | L6: §4.6, таблица 5, стр. 83–84; §5.5, стр. 104. | M6: Реестр правил!B29:AH29 | N6: 601c8f1bdcd89b6be61ee1a6222b775ed165e8fbd19da37184033efb39bcf3bf | O6: DISCOVERY_INDEX_ONLY; SOURCE_RULE_REMAINS_NORMATIVE
A7: SRCMAP-003 | B7: CORE-064 | C7: Восстанавливающий отвар | D7: Активно | E7: Реализовать в игровом ядре | F7: фармацевтика / лечение. | G7: FAM-PERIODIC_HEAL | H7: EXPLICIT | I7: восстановление HP. | J7: HP=min(maxHP,HP+25). | K7: не реанимирует CORE-156. | L7: §4.6, таблица 5, стр. 84. | M7: Реестр правил!B30:AH30 | N7: 028eace02932bf398b081979ef5258aa25bf25895fa1c3b411f3c9170345b094 | O7: DISCOVERY_INDEX_ONLY; SOURCE_RULE_REMAINS_NORMATIVE
A8: SRCMAP-004 | B8: CORE-066 | C8: Таблетка ночного зрения | D8: Активно | E8: Реализовать в игровом ядре | F8: фармацевтика / восприятие. | G8: FAM-SENSE_VISIBILITY | H8: EXPLICIT | I8: временный флаг зрения. | J8: на 2 часа видеть в темноте как днём; повтор обновляет 2 часа. | K8: числовые штрафы темноты в анализируемых разделах не заданы. | L8: §4.6, таблица 5, стр. 84. | M8: Реестр правил!B31:AH31 | N8: ed731903f84fe610458451f98e85f83f91c837935c1fcfdb0d79f7cb3bf46541 | O8: DISCOVERY_INDEX_ONLY; SOURCE_RULE_REMAINS_NORMATIVE
A9: SRCMAP-005 | B9: CORE-067 | C9: Таблетка бритвенных рефлексов | D9: Активно | E9: Реализовать в игровом ядре | F9: фармацевтика / бой. | G9: FAM-CHECK_MODIFIER | H9: EXPLICIT | I9: временный эффект. | J9: длительность max(1,round_math(R20/3)) личных ходов; на срок +3 к уклонению и парированию; повтор не складывает, обновляет срок. | K9: общая длительность CORE-101. | L9: §4.6, таблица 5, стр. 84. | M9: Реестр правил!B32:AH32 | N9: bcec27675d19ce1dd5adb2d541b3c32b0f60d214d84cb9ead460994d3382dff9 | O9: DISCOVERY_INDEX_ONLY; SOURCE_RULE_REMAINS_NORMATIVE
A10: SRCMAP-006 | B10: CORE-070 | C10: Таблетка куража | D10: Активно | E10: Реализовать в игровом ядре | F10: фармацевтика / серия. | G10: FAM-ACTION_ECONOMY | H10: EXPLICIT | I10: +1 боевое действие в текущем и каждом следующем личном ходу этого боя. | J10: seriesBonus=+1 до конца боя; если первая доза принята в собственный текущий ход после расчёта серии, немедленно увеличить combatActionsRemaining на 1; повтор не увеличивает бонус/остаток, лишь обновляет эффект (практически до того же конца боя). | K10: может увеличить серию выше 5. | L10: §4.6, таблица 5, стр. 84. | M10: Реестр правил!B33:AH33 | N10: 1666b9ad8f9b32be0bf6debe12627829e7ba9b383911ffcec37b741fb4bd88b3 | O10: DISCOVERY_INDEX_ONLY; SOURCE_RULE_REMAINS_NORMATIVE
A11: SRCMAP-007 | B11: CORE-071 | C11: Восстанавливающая таблетка | D11: Активно | E11: Реализовать в игровом ядре | F11: фармацевтика / периодическое лечение. | G11: FAM-PERIODIC_HEAL | H11: EXPLICIT | I11: периодический эффект. | J11: до конца боя в конце каждого хода HP=min(maxHP,HP+5); повтор не складывает. | K11: обычное лечение не действует в тяжёлом ранении. | L11: §4.6, таблица 5, стр. 84; §5.4.2.5, стр. 95. | M11: Реестр правил!B34:AH34 | N11: 6e11e3910324408b608761565f50dfe1a2f89fe07787d1e89f2847be923c5fe9 | O11: DISCOVERY_INDEX_ONLY; SOURCE_RULE_REMAINS_NORMATIVE
A12: SRCMAP-008 | B12: CORE-077 | C12: Границы HP и ОЭ | D12: Активно | E12: Реализовать в игровом ядре | F12: ресурс. | G12: FAM-NARRATIVE | H12: EXPLICIT | I12: валидный ресурс. | J12: clamp текущего в [0,currentMax]; избыточное восстановление пропадает; при временном снижении max текущий снизить до нового max, если выше; увеличение max само не восстанавливает текущий запас. | K12: тяжёлое ранение срабатывает при HP=0. | L12: §5.1, стр. 86. | M12: Реестр правил!B39:AH39 | N12: f0f2e107bea3271fe561a8333ad17850d762866599f264632582317be9e910ee | O12: DISCOVERY_INDEX_ONLY; SOURCE_RULE_REMAINS_NORMATIVE
A13: SRCMAP-009 | B13: CORE-079 | C13: Порядок применения модификаторов характеристики | D13: Активно | E13: Реализовать в игровом ядре | F13: характеристика / вычисление. | G13: FAM-STAT_MODIFIER | H13: EXPLICIT | I13: итоговая характеристика. | J13: 1) постоянное значение; 2) временные прибавки/штрафы; 3) умножение/деление; 4) точная установка и явно названные min/max. «Становится равной/до» применяется после обычных модификаторов. | K13: при несовместимых установках — более конкретная, при равной конкретности более ограничительная. | L13: §5.1, стр. 87. | M13: Реестр правил!B41:AH41 | N13: 882daef991d1af28f3c507c642a828526e6a1214872f70b7e0c6350ffec41305 | O13: DISCOVERY_INDEX_ONLY; SOURCE_RULE_REMAINS_NORMATIVE
A14: SRCMAP-010 | B14: CORE-086 | C14: Начало и окончание боя | D14: Активно | E14: Реализовать в игровом ядре | F14: бой / жизненный цикл. | G14: FAM-LIFECYCLE | H14: EXPLICIT | I14: combat.active и границы эффектов «до конца боя». | J14: открыть бой; завершить, если полный круг никто не совершал и не готовил враждебных действий либо одна сторона утратила возможность или намерение продолжать. | K14: решение о завершении сцены принимает мастер. | L14: §5.4.1, стр. 92–93. | M14: Реестр правил!B45:AH45 | N14: 55256a39e88ca9bc9b7e267da6efc1538417f4f85df7d22821e51ebcc35d4d9e | O14: DISCOVERY_INDEX_ONLY; SOURCE_RULE_REMAINS_NORMATIVE
A15: SRCMAP-011 | B15: CORE-103 | C15: Состояния без сознания, паралич, оглушение, пропуск | D15: Активно | E15: Реализовать в игровом ядре | F15: бой / состояние. | G15: FAM-CONSCIOUSNESS | H15: EXPLICIT | I15: фильтр допустимых команд и таймер. | J15: без сознания — нет действий, реакций, активных защит, броня работает; парализован — нет физических действий/активных защит, ментальные возможны только без речи/движения/управления телом; оглушён — пропускает указанные собственные ходы и реакции, если эффект не разрешил защиты; «пропускает ход» — не получает боевых/небоевых, защиты вне хода только при прямом разрешении. | K15: конкретный эффект может сохранить дееспособность. | L15: §5.4.2.5, стр. 95–96. | M15: Реестр правил!B57:AH57 | N15: 071cedd0f66688a1eaf597bbec9eaf47c0c25457965bc261f12c90258b80398b | O15: DISCOVERY_INDEX_ONLY; SOURCE_RULE_REMAINS_NORMATIVE
... A310: SRCMAP-306 | B310: CORE-228 | C310: Типизация яда и абсолютный иммунитет | D310: Активно | E310: Реализовать в игровом ядре | F310: эффект / яд. | G310: FAM-IMMUNITY_RESISTANCE | H310: EXPLICIT | I310: Симбиотический яд не обходит абсолютный иммунитет. | J310: Каждый яд обязан иметь effectFamily=POISON и poisonSourceKind=ORDINARY|NATURAL|ARTIFICIAL|SYMBIOTIC|CANONICAL. Ответ IMMUNE_BEFORE_ROLL с SourceScope=ANY полностью отклоняет прямой урон, состояние, счётчик и вторичные ядовитые эффекты до бросков. Крысюк и Гигантская жаба имеют такой ответ ко всем источникам. | K310: Болезнь с названием «Отравление» без effectFamily=POISON остаётся болезнью; облако Скунса не считается ядом без явного тега. | L310: Предразработочный QA и прямые ответы пользователя 2026-07-29 | M310: Реестр правил!B734:AH734 | N310: 9cdf3f652540a435de8ba35d3dd5dc9a26e1c9ef97358ab7010b2ced23b1eed2 | O310: DISCOVERY_INDEX_ONLY; SOURCE_RULE_REMAINS_NORMATIVE

Sheet 07_Правила_сочетаний
A1: Явные правила сочетаний состояний
A2: Частные разрешители сильнее общего coexistence. Все авторские ветви определены; исключённые механики имеют статус NOT_MODELED.
A4: CombinationRuleID | B4: Левый селектор | C4: Правый селектор | D4: Результат | E4: Приоритет | F4: Stack / timer | G4: Removal / transition / note | H4: Rule refs | I4: Left family | J4: Right family | K4: Automation | L4: Status | M4: ID count
A5: COMB-001 | B5: same effect name, numeric | C5: same effect name, numeric | D5: STRONGEST_MAGNITUDE_APPLIES; TIMERS_INDEPENDENT | E5: SPECIFIC_RULE_OVERRIDES_DEFAULT_COEXISTENCE | F5: STRONGEST_MAGNITUDE_APPLIES; TIMERS_INDEPENDENT | G5: После сильнейшего автоматически действует следующий активный | H5: CORE-080 | I5: FAM-STAT_MODIFIER | J5: FAM-STAT_MODIFIER | K5: AUTOMATED | L5: DEFINED | M5: =COUNTIF($A$5:$A$69,A5) -> 1
A6: COMB-002 | B6: same pharmaceutical effect | C6: repeat dose | D6: REFRESH_DURATION; DO_NOT_INCREASE_VALUE | E6: SPECIFIC_RULE_OVERRIDES_DEFAULT_COEXISTENCE | F6: REFRESH_DURATION; DO_NOT_INCREASE_VALUE | G6: Специальное правило сильнее общего стека | H6: CORE-058 | I6: FAM-PREPARED_EFFECT | J6: FAM-STAT_MODIFIER | K6: AUTOMATED | L6: DEFINED | M6: =COUNTIF($A$5:$A$69,A6) -> 1
A7: COMB-003 | B7: same diseaseId | C7: same diseaseId | D7: NO_DUPLICATE_PENALTIES | E7: SPECIFIC_RULE_OVERRIDES_DEFAULT_COEXISTENCE | F7: NO_DUPLICATE_PENALTIES | G7: Один экземпляр/один набор штрафов | H7: MON-085 | I7: FAM-DISEASE | J7: FAM-DISEASE | K7: AUTOMATED | L7: DEFINED | M7: =COUNTIF($A$5:$A$69,A7) -> 1
A8: COMB-004 | B8: different diseaseId | C8: different diseaseId | D8: COEXIST; MODIFIERS_ADD | E8: SPECIFIC_RULE_OVERRIDES_DEFAULT_COEXISTENCE | F8: COEXIST; MODIFIERS_ADD | G8: Периодика каждой болезни остаётся собственной | H8: MON-085 | I8: FAM-DISEASE | J8: FAM-DISEASE | K8: AUTOMATED | L8: DEFINED | M8: =COUNTIF($A$5:$A$69,A8) -> 1
A9: COMB-005 | B9: disease modifiers | C9: other stat modifiers | D9: APPLY_CORE_079_PIPELINE; RECALC_DERIVED_STATES | E9: SPECIFIC_RULE_OVERRIDES_DEFAULT_COEXISTENCE | F9: APPLY_CORE_079_PIPELINE; RECALC_DERIVED_STATES | G9: Порог бессознательности проверяется после пересчёта | H9: CORE-079; MON-075 | I9: FAM-DISEASE | J9: FAM-STAT_MODIFIER | K9: AUTOMATED | L9: DEFINED | M9: =COUNTIF($A$5:$A$69,A9) -> 1
A10: COMB-006 | B10: DIS-POISONING | C10: POISON immunity | D10: DISEASE_REMAINS; NOT_A_POISON_WITHOUT_TAG | E10: SPECIFIC_RULE_OVERRIDES_DEFAULT_COEXISTENCE | F10: DISEASE_REMAINS; NOT_A_POISON_WITHOUT_TAG | G10: Совпадение бытового названия не меняет effectFamily | H10: CORE-228; MON-076 | I10: FAM-DISEASE | J10: FAM-IMMUNITY_RESISTANCE | K10: AUTOMATED | L10: DEFINED | M10: =COUNTIF($A$5:$A$69,A10) -> 1
A11: COMB-007 | B11: physical hit payload | C11: poison payload with absolute immunity | D11: KEEP_VALID_PHYSICAL_PAYLOAD; DROP_POISON_DAMAGE_STATE_COUNTER_SECONDARY | E11: SPECIFIC_RULE_OVERRIDES_DEFAULT_COEXISTENCE | F11: KEEP_VALID_PHYSICAL_PAYLOAD; DROP_POISON_DAMAGE_STATE_COUNTER_SECONDARY | G11: Иммунитет обрабатывается до бросков яда | H11: CORE-228 | I11: FAM-POISON | J11: FAM-IMMUNITY_RESISTANCE | K11: AUTOMATED | L11: DEFINED | M11: =COUNTIF($A$5:$A$69,A11) -> 1
A12: COMB-008 | B12: existing poison | C12: newly gained poison immunity | D12: NO_AUTOMATIC_CLEANSE_UNLESS_SOURCE_SAYS_SO | E12: SPECIFIC_RULE_OVERRIDES_DEFAULT_COEXISTENCE | F12: NO_AUTOMATIC_CLEANSE_UNLESS_SOURCE_SAYS_SO | G12: Иммунитет по умолчанию предотвращает наложение | H12: CORE-228; CORE-080 | I12: FAM-POISON | J12: FAM-IMMUNITY_RESISTANCE | K12: AUTOMATED | L12: DEFINED | M12: =COUNTIF($A$5:$A$69,A12) -> 1
A13: COMB-009 | B13: Taipan deadly/weakening poison | C13: same poison again | D13: REPLACE_STRENGTH_AND_DURATION; RESTART_TIMER | E13: SPECIFIC_RULE_OVERRIDES_DEFAULT_COEXISTENCE | F13: REPLACE_STRENGTH_AND_DURATION; RESTART_TIMER | G13: Не складывать два пакета одного профиля | H13: SYM-039; SYM-042 | I13: FAM-POISON | J13: FAM-POISON | K13: AUTOMATED | L13: DEFINED | M13: =COUNTIF($A$5:$A$69,A13) -> 1
A14: COMB-010 | B14: Taipan paralytic poison on limb A | C14: same profile on limb B | D14: COEXIST_PER_DISTINCT_LIMB | E14: SPECIFIC_RULE_OVERRIDES_DEFAULT_COEXISTENCE | F14: COEXIST_PER_DISTINCT_LIMB | G14: Уже онемевшая конечность исключается из выбора | H14: SYM-045 | I14: FAM-POISON | J14: FAM-TRAUMA | K14: AUTOMATED | L14: DEFINED | M14: =COUNTIF($A$5:$A$69,A14) -> 1
A15: COMB-011 | B15: Taipan suppressed/disabled | C15: already injected poison | D15: POISON_CONTINUES_TO_EXPIRY | E15: SPECIFIC_RULE_OVERRIDES_DEFAULT_COEXISTENCE | F15: POISON_CONTINUES_TO_EXPIRY | G15: Подавление прекращает производство, не автономный payload | H15: SYM-038; CQA-002 | I15: FAM-SYMBIONT_STATE | J15: FAM-POISON | K15: AUTOMATED | L15: DEFINED | M15: =COUNTIF($A$5:$A$69,A15) -> 1
A16: COMB-012 | B16: burning | C16: new burning | D16: ONE_BINARY_STATE; remaining=max(current,new); damagePerTick=max(current,new); NO_INSTANT_SECOND_TICK | E16: SPECIFIC_RULE_OVERRIDES_DEFAULT_COEXISTENCE | F16: ONE_BINARY_STATE; remaining=max(current,new); damagePerTick=max(current,new); NO_INSTANT_SECOND_TICK | G16: Повторное горение не создаёт немедленный тик | H16: CORE-112 | I16: FAM-FIRE | J16: FAM-FIRE | K16: AUTOMATED | L16: DEFINED | M16: =COUNTIF($A$5:$A$69,A16) -> 1
... A69: COMB-065 | B69: dead actor | C69: stored effects on corpse/resurrection | D69: ON_FINAL_DEATH TERMINATE_TEMPORARY_AND_CONTROL; PRESERVE_TRAUMAS_WOUNDS_ITEM_STATE_INVENTORY_SYMBIONTS; NO_RESUME_ON_RESURRECTION | E69: SPECIFIC_RULE_OVERRIDES_DEFAULT_COEXISTENCE | F69: ON_FINAL_DEATH TERMINATE_TEMPORARY_AND_CONTROL; PRESERVE_TRAUMAS_WOUNDS_ITEM_STATE_INVENTORY_SYMBIONTS; NO_RESUME_ON_RESURRECTION | G69: Сохранённые состояния трупа не возобновляют завершённые временные эффекты | H69: CQA-001; AQA-024 | I69: FAM-LIFECYCLE | J69: FAM-SOURCE_LINK | K69: AUTOMATED | L69: DEFINED | M69: =COUNTIF($A$5:$A$69,A69) -> 1
A70: COMB-066 | B70: multiple MON-159 psi-protection charges | C70: same defensive check | D70: CONSUME_ONE_EARLIEST_CHARGE; OTHER_SOURCE_CHARGES_REMAIN | E70: SPECIFIC_RULE_OVERRIDES_DEFAULT_COEXISTENCE | F70: CONSUME_ONE_EARLIEST_CHARGE; OTHER_SOURCE_CHARGES_REMAIN | G70: Бонусы не складываются на одной проверке | H70: MON-159 | I70: FAM-CHECK_MODIFIER | J70: FAM-CHECK_MODIFIER | K70: AUTOMATED | L70: DEFINED | M70: =COUNTIF($A$5:$A$71,A70) -> 1
A71: COMB-067 | B71: multiple Vivisector fumes | C71: same target at end of target turn | D71: ONE_CHECK_PER_SOURCE; STABLE_CREATED_AT_THEN_UUID; NO_ZONE_MERGE | E71: SPECIFIC_RULE_OVERRIDES_DEFAULT_COEXISTENCE | F71: ONE_CHECK_PER_SOURCE; STABLE_CREATED_AT_THEN_UUID; NO_ZONE_MERGE | G71: Урон и зоны каждого источника разрешаются отдельно | H71: MON-099; AQA-024 | I71: FAM-POISON | J71: FAM-POISON | K71: AUTOMATED | L71: DEFINED | M71: =COUNTIF($A$5:$A$71,A71) -> 1

Sheet 08_Матрица_семейств
A1: Полная матрица сочетаний семейств
A2: 24 семейств → 300 неупорядоченных пар с диагональю. Без override разные семейства сосуществуют и проходят обычные pipelines.
A4: PairID | B4: Left family | C4: Right family | D4: Default outcome | E4: Resolver | F4: CombinationRuleIDs | G4: Canonical basis | H4: Automation | I4: Status | J4: Pair count
A5: PAIR-001 | B5: FAM-LIFECYCLE | C5: FAM-LIFECYCLE | D5: TYPE_AND_SOURCE_SPECIFIC | E5: APPLY_LISTED_COMBINATION_RULES | F5: COMB-023 | G5: CORE-154 | H5: DEFAULT_OR_EXPLICIT | I5: DEFINED | J5: =COUNTIFS($B$5:$B$304,B5,$C$5:$C$304,C5) -> 1
A6: PAIR-002 | B6: FAM-LIFECYCLE | C6: FAM-CONSCIOUSNESS | D6: COEXIST_AND_COMPOSE_BY_DEFAULT | E6: APPLY_LISTED_COMBINATION_RULES | F6: COMB-060; COMB-061 | G6: CORE-222; CORE-152; CORE-103 | H6: DEFAULT_OR_EXPLICIT | I6: DEFINED | J6: =COUNTIFS($B$5:$B$304,B6,$C$5:$C$304,C6) -> 1
A7: PAIR-003 | B7: FAM-LIFECYCLE | C7: FAM-PHYSICAL_CONTROL | D7: COEXIST_AND_COMPOSE_BY_DEFAULT | E7: UNION_RESTRICTIONS_AND_RUN_NORMAL_PIPELINES | G7: CORE-079; CORE-080 | H7: DEFAULT_OR_EXPLICIT | I7: DEFINED | J7: =COUNTIFS($B$5:$B$304,B7,$C$5:$C$304,C7) -> 1
A8: PAIR-004 | B8: FAM-LIFECYCLE | C8: FAM-MENTAL_CONTROL | D8: COEXIST_AND_COMPOSE_BY_DEFAULT | E8: UNION_RESTRICTIONS_AND_RUN_NORMAL_PIPELINES | G8: CORE-079; CORE-080 | H8: DEFAULT_OR_EXPLICIT | I8: DEFINED | J8: =COUNTIFS($B$5:$B$304,B8,$C$5:$C$304,C8) -> 1
A9: PAIR-005 | B9: FAM-LIFECYCLE | C9: FAM-MOBILITY_POSITION | D9: COEXIST_AND_COMPOSE_BY_DEFAULT | E9: UNION_RESTRICTIONS_AND_RUN_NORMAL_PIPELINES | G9: CORE-079; CORE-080 | H9: DEFAULT_OR_EXPLICIT | I9: DEFINED | J9: =COUNTIFS($B$5:$B$304,B9,$C$5:$C$304,C9) -> 1
A10: PAIR-006 | B10: FAM-LIFECYCLE | C10: FAM-ACTION_ECONOMY | D10: COEXIST_AND_COMPOSE_BY_DEFAULT | E10: UNION_RESTRICTIONS_AND_RUN_NORMAL_PIPELINES | G10: CORE-079; CORE-080 | H10: DEFAULT_OR_EXPLICIT | I10: DEFINED | J10: =COUNTIFS($B$5:$B$304,B10,$C$5:$C$304,C10) -> 1
A11: PAIR-007 | B11: FAM-LIFECYCLE | C11: FAM-TRAUMA | D11: COEXIST_AND_COMPOSE_BY_DEFAULT | E11: APPLY_LISTED_COMBINATION_RULES | F11: COMB-062 | G11: CORE-219; CORE-222 | H11: DEFAULT_OR_EXPLICIT | I11: DEFINED | J11: =COUNTIFS($B$5:$B$304,B11,$C$5:$C$304,C11) -> 1
A12: PAIR-008 | B12: FAM-LIFECYCLE | C12: FAM-WOUND_BLEEDING | D12: COEXIST_AND_COMPOSE_BY_DEFAULT | E12: UNION_RESTRICTIONS_AND_RUN_NORMAL_PIPELINES | G12: CORE-079; CORE-080 | H12: DEFAULT_OR_EXPLICIT | I12: DEFINED | J12: =COUNTIFS($B$5:$B$304,B12,$C$5:$C$304,C12) -> 1
A13: PAIR-009 | B13: FAM-LIFECYCLE | C13: FAM-DISEASE | D13: COEXIST_AND_COMPOSE_BY_DEFAULT | E13: UNION_RESTRICTIONS_AND_RUN_NORMAL_PIPELINES | G13: CORE-079; CORE-080 | H13: DEFAULT_OR_EXPLICIT | I13: DEFINED | J13: =COUNTIFS($B$5:$B$304,B13,$C$5:$C$304,C13) -> 1
A14: PAIR-010 | B14: FAM-LIFECYCLE | C14: FAM-POISON | D14: COEXIST_AND_COMPOSE_BY_DEFAULT | E14: UNION_RESTRICTIONS_AND_RUN_NORMAL_PIPELINES | G14: CORE-079; CORE-080 | H14: DEFAULT_OR_EXPLICIT | I14: DEFINED | J14: =COUNTIFS($B$5:$B$304,B14,$C$5:$C$304,C14) -> 1
A15: PAIR-011 | B15: FAM-LIFECYCLE | C15: FAM-FIRE | D15: COEXIST_AND_COMPOSE_BY_DEFAULT | E15: UNION_RESTRICTIONS_AND_RUN_NORMAL_PIPELINES | G15: CORE-079; CORE-080 | H15: DEFAULT_OR_EXPLICIT | I15: DEFINED | J15: =COUNTIFS($B$5:$B$304,B15,$C$5:$C$304,C15) -> 1
A16: PAIR-012 | B16: FAM-LIFECYCLE | C16: FAM-PERIODIC_DAMAGE | D16: COEXIST_AND_COMPOSE_BY_DEFAULT | E16: APPLY_LISTED_COMBINATION_RULES | F16: COMB-025; COMB-028 | G16: CORE-155; AQA-024 | H16: DEFAULT_OR_EXPLICIT | I16: DEFINED | J16: =COUNTIFS($B$5:$B$304,B16,$C$5:$C$304,C16) -> 1
A17: PAIR-013 | B17: FAM-LIFECYCLE | C17: FAM-PERIODIC_HEAL | D17: COEXIST_AND_COMPOSE_BY_DEFAULT | E17: APPLY_LISTED_COMBINATION_RULES | F17: COMB-021; COMB-026; COMB-057 | G17: CORE-071; CORE-156; CORE-156; AQA-028; CORE-071 | H17: DEFAULT_OR_EXPLICIT | I17: DEFINED | J17: =COUNTIFS($B$5:$B$304,B17,$C$5:$C$304,C17) -> 1
A18: PAIR-014 | B18: FAM-LIFECYCLE | C18: FAM-STAT_MODIFIER | D18: COEXIST_AND_COMPOSE_BY_DEFAULT | E18: UNION_RESTRICTIONS_AND_RUN_NORMAL_PIPELINES | G18: CORE-079; CORE-080 | H18: DEFAULT_OR_EXPLICIT | I18: DEFINED | J18: =COUNTIFS($B$5:$B$304,B18,$C$5:$C$304,C18) -> 1
A19: PAIR-015 | B19: FAM-LIFECYCLE | C19: FAM-CHECK_MODIFIER | D19: COEXIST_AND_COMPOSE_BY_DEFAULT | E19: APPLY_LISTED_COMBINATION_RULES | F19: COMB-024 | G19: CORE-069 | H19: DEFAULT_OR_EXPLICIT | I19: DEFINED | J19: =COUNTIFS($B$5:$B$304,B19,$C$5:$C$304,C19) -> 1
A20: PAIR-016 | B20: FAM-LIFECYCLE | C20: FAM-SENSE_VISIBILITY | D20: COEXIST_AND_COMPOSE_BY_DEFAULT | E20: UNION_RESTRICTIONS_AND_RUN_NORMAL_PIPELINES | G20: CORE-079; CORE-080 | H20: DEFAULT_OR_EXPLICIT | I20: DEFINED | J20: =COUNTIFS($B$5:$B$304,B20,$C$5:$C$304,C20) -> 1
A21: PAIR-017 | B21: FAM-LIFECYCLE | C21: FAM-FORM_MODE | D21: COEXIST_AND_COMPOSE_BY_DEFAULT | E21: UNION_RESTRICTIONS_AND_RUN_NORMAL_PIPELINES | G21: CORE-079; CORE-080 | H21: DEFAULT_OR_EXPLICIT | I21: DEFINED | J21: =COUNTIFS($B$5:$B$304,B21,$C$5:$C$304,C21) -> 1
A22: PAIR-018 | B22: FAM-LIFECYCLE | C22: FAM-SYMBIONT_STATE | D22: COEXIST_AND_COMPOSE_BY_DEFAULT | E22: UNION_RESTRICTIONS_AND_RUN_NORMAL_PIPELINES | G22: CORE-079; CORE-080 | H22: DEFAULT_OR_EXPLICIT | I22: DEFINED | J22: =COUNTIFS($B$5:$B$304,B22,$C$5:$C$304,C22) -> 1
A23: PAIR-019 | B23: FAM-LIFECYCLE | C23: FAM-IMMUNITY_RESISTANCE | D23: COEXIST_AND_COMPOSE_BY_DEFAULT | E23: UNION_RESTRICTIONS_AND_RUN_NORMAL_PIPELINES | G23: CORE-079; CORE-080 | H23: DEFAULT_OR_EXPLICIT | I23: DEFINED | J23: =COUNTIFS($B$5:$B$304,B23,$C$5:$C$304,C23) -> 1
A24: PAIR-020 | B24: FAM-LIFECYCLE | C24: FAM-INFECTION | D24: COEXIST_AND_COMPOSE_BY_DEFAULT | E24: UNION_RESTRICTIONS_AND_RUN_NORMAL_PIPELINES | G24: CORE-079; CORE-080 | H24: DEFAULT_OR_EXPLICIT | I24: DEFINED | J24: =COUNTIFS($B$5:$B$304,B24,$C$5:$C$304,C24) -> 1
A25: PAIR-021 | B25: FAM-LIFECYCLE | C25: FAM-PREPARED_EFFECT | D25: COEXIST_AND_COMPOSE_BY_DEFAULT | E25: APPLY_LISTED_COMBINATION_RULES | F25: COMB-022; COMB-027; COMB-046 | G25: CORE-060; CORE-156; MON-114–115; CORE-222; Q-CORE-063; CORE-153 | H25: DEFAULT_OR_EXPLICIT | I25: DEFINED | J25: =COUNTIFS($B$5:$B$304,B25,$C$5:$C$304,C25) -> 1
A26: PAIR-022 | B26: FAM-LIFECYCLE | C26: FAM-SOURCE_LINK | D26: COEXIST_AND_COMPOSE_BY_DEFAULT | E26: APPLY_LISTED_COMBINATION_RULES | F26: COMB-040; COMB-065 | G26: CQA-002; AQ2-020; CQA-001; AQA-024 | H26: DEFAULT_OR_EXPLICIT | I26: DEFINED | J26: =COUNTIFS($B$5:$B$304,B26,$C$5:$C$304,C26) -> 1
A27: PAIR-023 | B27: FAM-LIFECYCLE | C27: FAM-ITEM_STATE | D27: COEXIST_AND_COMPOSE_BY_DEFAULT | E27: UNION_RESTRICTIONS_AND_RUN_NORMAL_PIPELINES | G27: CORE-079; CORE-080 | H27: DEFAULT_OR_EXPLICIT | I27: DEFINED | J27: =COUNTIFS($B$5:$B$304,B27,$C$5:$C$304,C27) -> 1
A28: PAIR-024 | B28: FAM-LIFECYCLE | C28: FAM-NARRATIVE | D28: COEXIST_AND_COMPOSE_BY_DEFAULT | E28: UNION_RESTRICTIONS_AND_RUN_NORMAL_PIPELINES | G28: CORE-079; CORE-080 | H28: DEFAULT_OR_EXPLICIT | I28: DEFINED | J28: =COUNTIFS($B$5:$B$304,B28,$C$5:$C$304,C28) -> 1
A29: PAIR-025 | B29: FAM-CONSCIOUSNESS | C29: FAM-CONSCIOUSNESS | D29: TYPE_AND_SOURCE_SPECIFIC | E29: APPLY_EFFECT_TYPE_STACK_POLICY | G29: CORE-079; CORE-080 | H29: DEFAULT_OR_EXPLICIT | I29: DEFINED | J29: =COUNTIFS($B$5:$B$304,B29,$C$5:$C$304,C29) -> 1
A30: PAIR-026 | B30: FAM-CONSCIOUSNESS | C30: FAM-PHYSICAL_CONTROL | D30: COEXIST_AND_COMPOSE_BY_DEFAULT | E30: APPLY_LISTED_COMBINATION_RULES | F30: COMB-018; COMB-019 | G30: CORE-061–062; CORE-103; CORE-103 | H30: DEFAULT_OR_EXPLICIT | I30: DEFINED | J30: =COUNTIFS($B$5:$B$304,B30,$C$5:$C$304,C30) -> 1
A31: PAIR-027 | B31: FAM-CONSCIOUSNESS | C31: FAM-MENTAL_CONTROL | D31: COEXIST_AND_COMPOSE_BY_DEFAULT | E31: APPLY_LISTED_COMBINATION_RULES | F31: COMB-020 | G31: SYM-100; CORE-181 | H31: DEFAULT_OR_EXPLICIT | I31: DEFINED | J31: =COUNTIFS($B$5:$B$304,B31,$C$5:$C$304,C31) -> 1
A32: PAIR-028 | B32: FAM-CONSCIOUSNESS | C32: FAM-MOBILITY_POSITION | D32: COEXIST_AND_COMPOSE_BY_DEFAULT | E32: UNION_RESTRICTIONS_AND_RUN_NORMAL_PIPELINES | G32: CORE-079; CORE-080 | H32: DEFAULT_OR_EXPLICIT | I32: DEFINED | J32: =COUNTIFS($B$5:$B$304,B32,$C$5:$C$304,C32) -> 1
A33: PAIR-029 | B33: FAM-CONSCIOUSNESS | C33: FAM-ACTION_ECONOMY | D33: COEXIST_AND_COMPOSE_BY_DEFAULT | E33: UNION_RESTRICTIONS_AND_RUN_NORMAL_PIPELINES | G33: CORE-079; CORE-080 | H33: DEFAULT_OR_EXPLICIT | I33: DEFINED | J33: =COUNTIFS($B$5:$B$304,B33,$C$5:$C$304,C33) -> 1
A34: PAIR-030 | B34: FAM-CONSCIOUSNESS | C34: FAM-TRAUMA | D34: COEXIST_AND_COMPOSE_BY_DEFAULT | E34: UNION_RESTRICTIONS_AND_RUN_NORMAL_PIPELINES | G34: CORE-079; CORE-080 | H34: DEFAULT_OR_EXPLICIT | I34: DEFINED | J34: =COUNTIFS($B$5:$B$304,B34,$C$5:$C$304,C34) -> 1
A35: PAIR-031 | B35: FAM-CONSCIOUSNESS | C35: FAM-WOUND_BLEEDING | D35: COEXIST_AND_COMPOSE_BY_DEFAULT | E35: UNION_RESTRICTIONS_AND_RUN_NORMAL_PIPELINES | G35: CORE-079; CORE-080 | H35: DEFAULT_OR_EXPLICIT | I35: DEFINED | J35: =COUNTIFS($B$5:$B$304,B35,$C$5:$C$304,C35) -> 1
A36: PAIR-032 | B36: FAM-CONSCIOUSNESS | C36: FAM-DISEASE | D36: COEXIST_AND_COMPOSE_BY_DEFAULT | E36: UNION_RESTRICTIONS_AND_RUN_NORMAL_PIPELINES | G36: CORE-079; CORE-080 | H36: DEFAULT_OR_EXPLICIT | I36: DEFINED | J36: =COUNTIFS($B$5:$B$304,B36,$C$5:$C$304,C36) -> 1
A37: PAIR-033 | B37: FAM-CONSCIOUSNESS | C37: FAM-POISON | D37: COEXIST_AND_COMPOSE_BY_DEFAULT | E37: UNION_RESTRICTIONS_AND_RUN_NORMAL_PIPELINES | G37: CORE-079; CORE-080 | H37: DEFAULT_OR_EXPLICIT | I37: DEFINED | J37: =COUNTIFS($B$5:$B$304,B37,$C$5:$C$304,C37) -> 1
A38: PAIR-034 | B38: FAM-CONSCIOUSNESS | C38: FAM-FIRE | D38: COEXIST_AND_COMPOSE_BY_DEFAULT | E38: APPLY_LISTED_COMBINATION_RULES | F38: COMB-014 | G38: CORE-103; CQA-002 | H38: DEFAULT_OR_EXPLICIT | I38: DEFINED | J38: =COUNTIFS($B$5:$B$304,B38,$C$5:$C$304,C38) -> 1
A39: PAIR-035 | B39: FAM-CONSCIOUSNESS | C39: FAM-PERIODIC_DAMAGE | D39: COEXIST_AND_COMPOSE_BY_DEFAULT | E39: APPLY_LISTED_COMBINATION_RULES | F39: COMB-016 | G39: CORE-061 | H39: DEFAULT_OR_EXPLICIT | I39: DEFINED | J39: =COUNTIFS($B$5:$B$304,B39,$C$5:$C$304,C39) -> 1
A40: PAIR-036 | B40: FAM-CONSCIOUSNESS | C40: FAM-PERIODIC_HEAL | D40: COEXIST_AND_COMPOSE_BY_DEFAULT | E40: UNION_RESTRICTIONS_AND_RUN_NORMAL_PIPELINES | G40: CORE-079; CORE-080 | H40: DEFAULT_OR_EXPLICIT | I40: DEFINED | J40: =COUNTIFS($B$5:$B$304,B40,$C$5:$C$304,C40) -> 1
A41: PAIR-037 | B41: FAM-CONSCIOUSNESS | C41: FAM-STAT_MODIFIER | D41: COEXIST_AND_COMPOSE_BY_DEFAULT | E41: UNION_RESTRICTIONS_AND_RUN_NORMAL_PIPELINES | G41: CORE-079; CORE-080 | H41: DEFAULT_OR_EXPLICIT | I41: DEFINED | J41: =COUNTIFS($B$5:$B$304,B41,$C$5:$C$304,C41) -> 1
...

Sheet 09_Профили_дееспособности
A1: Проекции дееспособности для значимых сочетаний
A2: Это производные профили интерфейса и фильтра команд; активные исходные EffectInstance не удаляются.
A4: ProfileID | B4: Активные состояния | C4: Физические действия | D4: Ментальные действия | E4: Реакции | F4: Активная защита | G4: Перемещение | H4: Броня | I4: Таймеры / автономные эффекты | J4: Контроллер | K4: Выход | L4: Rule refs | M4: Status
A5: PRF-CLEAN | B5: — | C5: YES | D5: YES | E5: YES | F5: YES | G5: YES | H5: YES | I5: Normal | J5: owningController | K5: — | L5: AQA-009 | M5: DEFINED
A6: PRF-UNCONSCIOUS | B6: EFF-CONSCIOUS-UNCONSCIOUS | C6: NO | D6: NO | E6: NO | F6: NO | G6: NO | H6: YES | I6: Autonomous effects continue | J6: owningController unless specific override | K6: Remove source condition | L6: CORE-103 | M6: DEFINED
A7: PRF-SLEEP | B7: EFF-CONSCIOUS-SLEEP | C7: NO | D7: NO | E7: NO | F7: NO | G7: NO | H7: YES | I7: Autonomous effects continue | J7: owningController | K7: Damage or CORE-060 | L7: CORE-061; CORE-103 | M7: DEFINED
A8: PRF-PARALYZED | B8: EFF-CONTROL-PARALYSIS | C8: NO | D8: CONDITIONAL_NO_SPEECH_MOVEMENT_BODY | E8: NO_PHYSICAL | F8: NO_ACTIVE_PHYSICAL | G8: NO | H8: YES | I8: Autonomous effects continue | J8: owningController | K8: Expiry or source removal | L8: CORE-062; CORE-103 | M8: DEFINED
A9: PRF-STUNNED | B9: EFF-CONTROL-STUN | C9: NO_NAMED_TURNS | D9: SOURCE_SPECIFIC | E9: NO | F9: SOURCE_SPECIFIC | G9: NO_NAMED_TURNS | H9: YES | I9: Autonomous effects continue | J9: owningController | K9: Consume named turns / cleanse | L9: CORE-103 | M9: DEFINED
A10: PRF-GRAPPLED | B10: EFF-CONTROL-GRAPPLE | C10: YES_WITH_MINUS_5 | D10: YES | E10: YES_WITH_MODS | F10: NO_DODGE; OTHER_BY_RULE | G10: PAIR_MOVE_ONLY | H10: YES | I10: Normal | J10: owningController | K10: Release contest / source release | L10: CORE-138 | M10: DEFINED
A11: PRF-RESTRAINED | B11: EFF-CONTROL-RESTRAINED | C11: YES_WITH_SOURCE_PENALTY | D11: YES | E11: YES_WITH_SOURCE_PENALTY | F11: YES_WITH_SOURCE_PENALTY | G11: SOURCE_SPECIFIC | H11: YES | I11: Normal | J11: owningController | K11: Source-specific check | L11: MON-136; MON-149 | M11: DEFINED
A12: PRF-SEVERE-PC | B12: EFF-LIFE-SEVERE_WOUND | C12: NO_BY_DEFAULT | D12: NO_BY_DEFAULT | E12: NO | F12: NO | G12: NO | H12: YES | I12: Death timer; heal blocked | J12: owningController | K12: Explicit reanimation only | L12: CORE-152–156 | M12: DEFINED
A13: PRF-SEVERE-DUPLICATE | B13: EFF-LIFE-SEVERE_WOUND + EFF-CAPABILITY-SEVERE_WOUND | C13: YES | D13: YES | E13: YES | F13: YES | G13: YES | H13: YES | I13: Timer ×4 once; new damage kills | J13: owningController | K13: Source completion/reanimation/death | L13: CORE-154; SYM-028 | M13: DEFINED
A14: PRF-SEVERE-TABLET | B14: EFF-LIFE-SEVERE_WOUND + CORE-069 capability | C14: YES_UNTIL_COMBAT_END | D14: YES | E14: YES | F14: YES | G14: YES | H14: YES | I14: Timer; periodic heal still blocked | J14: owningController | K14: Combat end/reanimation/death | L14: CORE-069 | M14: DEFINED
A15: PRF-DEAD | B15: EFF-LIFE-DEAD | C15: NO | D15: NO | E15: NO | F15: NO | G15: NO | H15: N/A | I15: Cancel remaining personal events; death-triggered events may run | J15: NONE | K15: Explicit resurrection only | L15: AQA-024; CORE-156 | M15: DEFINED
... A25: PRF-FIRE-FLEA-DETONATING-DEAD | B25: dead + prepared detonation | C25: NO | D25: NO | E25: NO | F25: NO | G25: NO | H25: N/A | I25: Detonation still resolves | J25: NONE | K25: Special neutralization/trigger | L25: MON-114–115; CORE-222 | M25: DEFINED

Sheet 10_Иммунитеты
A1: Профили ответов, иммунитетов и сопротивлений
A2: Ответ не создаёт отсутствующую проверку. IMMUNE_BEFORE_ROLL отбрасывает только соответствующий payload.
A4: ResponseProfileID | B4: Provider | C4: Effect family | D4: Source scope | E4: Response | F4: Modifier | G4: Blocked payload | H4: Existing effect policy / note | I4: Rule refs
A5: RSP-KRYSYUK-POISON | B5: CBT-KRYSYUK | C5: POISON | D5: ANY | E5: IMMUNE_BEFORE_ROLL | F5: — | G5: damage,state,counter,secondary effects | H5: No automatic cleanse | I5: MON-104; CORE-228
A6: RSP-KRYSYUK-DISEASE | B6: CBT-KRYSYUK | C6: DISEASE | D6: ANY | E6: CHECK_MODIFIER | F6: +5 | G6: — | H6: Only an existing check | I6: MON-104
A7: RSP-KRYSYUK-EXHAUSTION | B7: CBT-KRYSYUK | C7: EXHAUSTION | D7: ANY | E7: CHECK_MODIFIER | F7: +5 | G7: — | H7: Mechanic otherwise orphaned | I7: MON-104
A8: RSP-GIANT-TOAD-POISON | B8: CBT-GIANT-TOAD | C8: POISON | D8: ANY | E8: IMMUNE_BEFORE_ROLL | F8: — | G8: damage,state,counter,secondary effects | H8: No automatic cleanse | I8: MON-155; CORE-228
A9: RSP-GIANT-TOAD-DISEASE | B9: CBT-GIANT-TOAD | C9: DISEASE | D9: ANY | E9: CHECK_MODIFIER | F9: +10 | G9: — | H9: No exhaustion bonus | I9: MON-155
A10: RSP-VIVISECTOR-SELF | B10: CBT-VIVISECTOR | C10: POISON | D10: OWN_SLIME_OR_FUMES | E10: IMMUNE | F10: — | G10: own poison payload | H10: No own effect created | I10: MON-101
A11: RSP-VIVISECTOR-NATURAL | B11: CBT-VIVISECTOR | C11: POISON | D11: NATURAL | E11: CHECK_MODIFIER | F11: +10 | G11: — | H11: Artificial/symbiotic normal | I11: MON-101
A12: RSP-VIVISECTOR-FIRE | B12: CBT-VIVISECTOR | C12: FIRE | D12: ORDINARY | E12: DAMAGE_MULTIPLIER | F12: ×0.5 | G12: — | H12: Burn may still apply | I12: MON-101
A13: RSP-FIRE-FLEA-FIRE | B13: CBT-FIRE-FLEA | C13: FIRE | D13: ORDINARY | E13: IMMUNE_STANDARD_FIRE | F13: — | G13: standard fire damage/burn | H13: Specific explosion rules separate | I13: MON-113
A14: RSP-NAIT-INHALED | B14: ITEM:ITM-ARM-005 sealed | C14: INHALED_CHEMICAL_OR_INFECTION | D14: EXTERNAL | E14: BLOCK_APPLICATION | F14: — | G14: fumes, pheromones, infected vapor | H14: Does not cleanse existing | I14: CORE-053
A15: RSP-NAIT-CHECK | B15: ITEM:ITM-ARM-005 sealed | C15: DISEASE|SYMBIONT_INFECTION|EXTERNAL_CHEMICAL | D15: EXTERNAL | E15: CHECK_MODIFIER | F15: +20 | G15: — | H15: Only while sealed | I15: CORE-053
... A24: RSP-BUBUI-ALCOHOL | B24: CBT-BUBUI | C24: ALCOHOL | D24: ANY | E24: IGNORE_SELECTED_PENALTIES | F24: — | G24: S/D/I penalties only | H24: Other alcohol effects remain | I24: MON-095

Sheet 11_Таймеры_порядок
A1: Таймеры и транзакционный порядок
A2: AQA-024 используется как поздняя детальная семантика обработки одной временной метки.
A4: PolicyID | B4: Название | C4: Code | D4: Контекст | E4: Алгоритм / инвариант | F4: Rule refs
A5: TIME-001 | B5: Личный ход | C5: PERSONAL_TURN | D5: Источник или цель по карточке | E5: Срок N начинается немедленно и завершается в конце N-го последующего хода источника | F5: CORE-101
A6: TIME-002 | B6: Круг инициативы | C6: INITIATIVE_ROUND | D6: Глобальный боевой круг | E6: Используется, если нет личного источника либо карточка прямо говорит круг | F6: CORE-101; CORE-176
A7: TIME-003 | B7: До конца боя | C7: COMBAT_BOUND | D7: Активная угроза | E7: Не сохраняется только ради формального состояния без угрозы | F7: CORE-086; CORE-101
A8: TIME-004 | B8: Часы/минуты | C8: WORLD_TIME | D8: Календарь кампании | E8: Хранить точные отметки времени | F8: CORE-101; Q-CORE-063
A9: TIME-005 | B9: Полные сутки | C9: FULL_DAY_TICK | D9: 24 часа эффекта | E9: Пневмония тикает только за полные сутки | F9: MON-080
A10: TIME-006 | B10: Тяжёлое ранение | C10: SEVERE_WOUND_TIMER | D10: Личная/мировая шкала | E10: 1 боевой ход остатка = 5 минут вне боя | F10: CORE-153; Q-CORE-063
A11: TIME-007 | B11: Обычный остаток | C11: NORMAL_CONVERSION | D11: Смена бой↔мир | E11: 1 оставшийся ход = 1 минута | F11: Q-CORE-063
A12: TIME-008 | B12: Точный остаток | C12: EXACT_REMAINDER | D12: Хранилище | E12: Округление вверх допустимо только для отображения | F12: Q-CORE-063
A13: TIME-009 | B13: Список событий метки | C13: EVENT_SNAPSHOT | D13: Одна временная метка | E13: Сначала фиксируется неизменяемый список существовавших событий | F13: AQA-024
A14: TIME-010 | B14: Фаза 1 | C14: COSTS_AND_TICKS | D14: Одна временная метка | E14: Обязательные цены и периодические тики | F14: AQA-024
A15: TIME-011 | B15: Немедленный пересчёт | C15: RECALC_AFTER_EACH_TICK | D15: После каждого тика | E15: Тяжёлая рана, сознание, смерть и немедленные триггеры | F15: AQA-024
... A25: TIME-021 | B25: Дробная длительность R20/3 | C25: ROUND_NEAREST_HALF_UP_MIN_ONE | D25: Фелида и иные явно совместимые источники | E25: Округлить до ближайшего целого; ровно 0,5 вверх; положительный результат минимум 1; результат ≤0 не создаёт эффект | F25: MON-169; авторское решение GAP-018

Sheet 12_Runtime_контракты
A1: Runtime-контракты эффектов и болезней
A2: Схема заполняет существующие currentEffects/currentTraumas/currentWounds без изменения согласованных файлов.
A4: Entity | B4: Field | C4: Type | D4: Required | E4: Семантика / инвариант | F4: Источник / статус
A5: EffectDefinition | B5: effectTypeId | C5: string | D5: YES | E5: Стабильный ID из 02_Типы_эффектов | F5: NEW_SUPPLEMENT_SCHEMA
A6: EffectDefinition | B6: familyCode | C6: enum | D6: YES | E6: FK на 01_Семейства | F6: NEW_SUPPLEMENT_SCHEMA
A7: EffectDefinition | B7: displayName | C7: string | D7: YES | E7: Пользовательское имя | F7: NEW_SUPPLEMENT_SCHEMA
A8: EffectDefinition | B8: stateBucket | C8: enum | D8: YES | E8: currentEffects/currentTraumas/currentWounds/actorFlags/item/source/narrative | F8: NEW_SUPPLEMENT_SCHEMA
A9: EffectDefinition | B9: defaultStackPolicy | C9: enum | D9: YES | E9: Не заменяет частную карточку источника | F9: NEW_SUPPLEMENT_SCHEMA
A10: EffectDefinition | B10: defaultSourceLifecycle | C10: enum | D10: YES | E10: SOURCE_MAINTAINED/AUTONOMOUS/SOURCE_SPECIFIC | F10: NEW_SUPPLEMENT_SCHEMA
A11: EffectDefinition | B11: automationStatus | C11: enum | D11: YES | E11: AUTOMATED/PARTIAL/TRACE_ONLY/BLOCKED/NOT_MODELED | F11: NEW_SUPPLEMENT_SCHEMA
A12: EffectInstance | B12: effectInstanceId | C12: UUID | D12: YES | E12: Уникален в mutable graph; новый UUID при клонировании | F12: REQUIRED
A13: EffectInstance | B13: effectTypeId | C13: string | D13: YES | E13: FK EffectDefinition | F13: REQUIRED
A14: EffectInstance | B14: familyCode | C14: enum | D14: YES | E14: Дублируется для быстрого ответа и валидируется по типу | F14: REQUIRED
A15: EffectInstance | B15: targetActorId | C15: UUID | D15: YES | E15: Владелец состояния | F15: REQUIRED
... A73: DerivedStateProjection | B73: regionPenaltyById | C73: map<regionId,number> | D73: YES | E73: Для одной зоны действует наиболее строгий числовой штраф из травмы/онемения; источники хранятся раздельно, самостоятельные ограничения объединяются, после снятия выполняется пересчёт | F73: CORE-119; MON-169; SYM-045; COMB-031; Author decision 2026-07-31

Sheet 13_Операции
A1: Атомарные операции приложения
A2: Каждая операция валидирует источник, ответ, анатомию и stack policy до изменения mutable state.
A4: OperationID | B4: Inputs | C4: Алгоритм | D4: State writes | E4: Idempotency / audit | F4: Failure policy | G4: Rule refs
A5: APPLY_EFFECT | B5: EffectDefinition + source payload + target | C5: Validate response → anatomy → known EffectTypeID; reject BLOCKED/NOT_MODELED; then aggregateKey/stack policy → create or aggregate | D5: currentEffects/source bucket; audit | E5: IDEMPOTENCY_KEY | F5: REJECT_BLOCKED_OR_NOT_MODELED | G5: CORE-080; CORE-228
A6: REMOVE_EFFECT | B6: effectInstanceId + authorized reason | C6: Validate specific removal permission | D6: status=REMOVED; recalc | E6: effectInstanceId+revision | F6: REJECT_TERMINAL_DEAD_CLEAR | G6: AQA-028; AQA-045
A7: REPLACE_EFFECT | B7: old instance + new payload | C7: End old version and create new atomically | D7: old=REPLACED; new revision | E7: commandId | F7: NO_ROLLBACK | G7: AQA-045
A8: REFRESH_EFFECT | B8: effectInstanceId + new duration | C8: Only if source profile says refresh | D8: Update through replacement/versioning | E8: commandId | F8: REJECT_IF_STACK_POLICY_DIFFERS | G8: CORE-058; AQA-045
