Workbook

Sheet 00_Паспорт
A1: SYMBIOSIS V7 — Soundtrack Playback Registry v1.1
A2: Implementation-ready specification. Night synchronized with campaign dayPhase [21:00,06:00); localLighting does not affect music. APPROVED FOR DEVELOPMENT · 2026-08-01
A4: Release summary | B4: Value | D4: Authoritative scope
A5: Source MP3 count | B5: =COUNTA('03_Треки'!$A$5:$A$93) -> 89 | D5: Audio files remain external assets. This workbook is the source of truth for logical Track_IDs, eligible contexts and transitions.
A6: Menu tracks | B6: =COUNTIF('03_Треки'!$E$5:$E$93,"MENU") -> 4 | D6: Map source: page 7 of Symbiosis_V7_print_final(2).pdf. Normalized geometry is versioned against the 1437×2029 embedded raster.
A7: Battle tracks | B7: =COUNTIF('03_Треки'!$E$5:$E$93,"BATTLE") -> 6 | D7: Archive source: Итог.7z. Every MP3 is represented exactly once in the track catalog and at least once in a playback pool.
A8: Ambient tracks | B8: =COUNTIF('03_Треки'!$E$5:$E$93,"AMBIENT") -> 79 | D8: Do not infer extra sublocations from track names. Arena/Centre/Swamp names are local entry alternatives, not new marker properties.
A9: Cities | B9: =COUNTIF('04_Локации'!$C$5:$C$37,"CITY") -> 30 | D9: Runtime may deduplicate identical audio bytes, but it must preserve distinct logical context assignments for MUS-009 and MUS-041.
A10: Free garrisons | B10: =COUNTIF('04_Локации'!$C$5:$C$37,"GARRISON") -> 3 | D10: If the map image or track filenames change, increment the registry version and update coordinates/pools without changing code-level rules.
A11: Playback pools | B11: =COUNTA('02_Пулы'!$A$5:$A$30) -> 26
A12: Acceptance cases | B12: =COUNTA('07_QA'!$A$5:$A$44) -> 40 | D12: Workbook navigation
A13: Track-registry errors | B13: =COUNTIF('03_Треки'!$O$5:$O$93,"ERROR") -> 0 | D13: 01_Алгоритм | E13: Priority, state transitions, parameters and events
A14: Location-coordinate errors | B14: =COUNTIF('04_Локации'!$P$5:$P$37,"ERROR") -> 0 | D14: 02_Пулы | E14: Effective playback pools and membership
D15: 03_Треки | E15: Full 89-file registry with CRC and logical assignment
D16: 04_Локации | E16: 30 cities + 3 Free garrisons with entry rules and coordinates
D17: 05_Карта | E17: Normalized coordinate convention and visual grid
D18: 06_Геозоны | E18: Polygon definitions and vertices
D19: 07_QA | E19: Acceptance tests
D20: 08_Решения | E20: Traceability of the 21 approved decisions

Sheet 01_Алгоритм
A1: 01 — Playback algorithm
A2: Rules are evaluated in order. All clients receive the master's resolved Track_ID and playback state.
A4: Rule_ID | B4: Area | C4: Normative requirement
A5: R-001 | B5: Source of truth | C5: The master's computer owns the active logical track, playback position, start timestamp, active pool and shuffle-bag state. Clients reproduce this state.
A6: R-002 | B6: Priority | C6: BATTLE > NIGHT AMBIENT > DAY AMBIENT. Menu music applies only on pre-campaign menu flows.
A7: R-003 | B7: Determining battle | C7: Any active battle globally enables battle music. If several battles exist, use the battle involving the largest eligible group; ties use the older group.
A8: R-004 | B8: Determining group | C8: Outside battle, use the location of the eligible group with the greatest headcount. Ties use immutable creationSequence ascending.
A9: R-005 | B9: Headcount | C9: Count living active player characters and allied NPCs explicitly included in the group. Exclude enemies, dead characters and removed/inactive members.
A10: R-006 | B10: Location precedence | C10: City/garrison circle > No-Man's coastal overlay > No-Man's polygon > faction territory > Sea. Nэйт is always a Pure city override.
A11: R-007 | B11: Night interval | C11: Night is [21:00, 06:00). Day is [06:00, 21:00). Use campaign game time/dayPhase; master-set localLighting never changes the music phase.
A12: R-008 | B12: Context switch | C12: Switch immediately with a 2,000 ms crossfade when battle, dayPhase, determining group or spatial context changes. At exactly 21:00 outside battle, resolve the night pool.
A13: R-009 | B13: Same-pool stability | C13: Do not interrupt the current track when the effective pool remains unchanged, except for a required settlement/location entry opener.
A14: R-010 | B14: Settlement entry | C14: On every new entry, marker placement or focus activation in a settlement, apply its entry rule. Movement within the same settlement does not restart music; exit and re-entry does.
A15: R-011 | B15: Local alternatives | C15: Chado, Urahanta and Sadena choose randomly among their two local entry tracks. No separate Arena/Centre/Swamp sublocation field exists.
... A31: Parameter | B31: Value | C31: Meaning
A32: NIGHT_START_HOUR | B32: 21 | C32: Inclusive; campaign game time
A33: DAY_START_HOUR | B33: 6 | C33: Inclusive; campaign game time
A34: CROSSFADE_MS | B34: 2000 | C34: Default transition duration
A35: CITY_RADIUS_UV | B35: 0.018 | C35: Normalized radius around city star
A36: GARRISON_RADIUS_UV | B36: 0.012 | C36: Normalized radius around red garrison mark
A37: BOUNDARY_EPSILON_UV | B37: 0.005 | C37: Treat as boundary band for diagnostics
A38: ZONE_HYSTERESIS_UV | B38: 0.01 | C38: Prevents flicker from tiny marker moves near a border
A39: MAP_SOURCE_WIDTH_PX | B39: 1437 | C39: Embedded raster on page 7
A40: MAP_SOURCE_HEIGHT_PX | B40: 2029 | C40: Embedded raster on page 7
A41: PLAYABLE_CROP_X0_PX | B41: 20 | C41: Left edge used for normalized coordinates
A42: PLAYABLE_CROP_Y0_PX | B42: 170 | C42: Top edge used for normalized coordinates
A43: PLAYABLE_CROP_WIDTH_PX | B43: 1397 | C43: x1 - x0
A44: PLAYABLE_CROP_HEIGHT_PX | B44: 1450 | C44: y1 - y0
A45: NO_GROUP_POLICY | B45: SILENCE | C45: Technical fallback
A46: GROUP_TIE_BREAK | B46: creationSequence ASC | C46: Immutable creation order
A49: Event_ID | B49: Event | C49: Condition | D49: Required action
A50: EV-01 | B50: Open pre-campaign menu | C50: No active campaign scene | D50: Activate POOL_MENU; preserve current menu track across menu screens.
A51: EV-02 | B51: Start/load campaign | C51: Eligible group exists | D51: Resolve determining group, phase and zone; apply focus activation entry rules.
A52: EV-03 | B52: Place/move determining marker | C52: Marker enters a new zone | D52: Re-resolve context. Settlement/location entry opener may force a switch.
A53: EV-04 | B53: Move within same zone | C53: Effective pool unchanged | D53: Continue current track.
A54: EV-05 | B54: Change group membership | C54: Largest group may change | D54: Recalculate headcount and determining group.
A55: EV-06 | B55: Create another group | C55: Group count tie possible | D55: Use largest headcount; tie uses earlier creationSequence.
A56: EV-07 | B56: Start battle | C56: At least one active battle | D56: Immediately activate determining battle music; night is ignored.
A57: EV-08 | B57: End battle | C57: No active battles remain | D57: Re-evaluate current ambient context; no automatic city-entry replay.
A58: EV-09 | B58: Clock reaches 21:00 | C58: No battle | D58: Activate night context; only night-eligible tracks.
...

Sheet 02_Пулы
A1: 02 — Playback pools
A2: Pool membership is authoritative. Initial-entry pools may lead into a separate continuation pool.
A4: Pool_ID | B4: Context | C4: Territory | D4: Location_Mode | E4: Phase | F4: Initial_Rule | G4: Track_Count | H4: Track_IDs | I4: Randomization | J4: Use | K4: QC
A5: POOL_MENU | B5: MENU | C5: N/A | D5: MENU | E5: ANY | F5: Random from shuffle bag | G5: 4 | H5: MUS-008; MUS-009; MUS-010; MUS-011 | I5: SHUFFLE_BAG | J5: Main menu, character creation, campaign creation and campaign join. | K5: =IF(AND(A5<>"",G5>0,H5<>""),"OK","ERROR") -> OK
A6: POOL_COMBAT_GENERAL | B6: BATTLE | C6: VARIABLE | D6: BATTLE | E6: ANY | F6: Random from shuffle bag | G6: 4 | H6: MUS-002; MUS-005; MUS-006; MUS-007 | I6: SHUFFLE_BAG | J6: Any determining battle without a Pure participant. | K6: =IF(AND(A6<>"",G6>0,H6<>""),"OK","ERROR") -> OK
A7: POOL_COMBAT_PURE_OPENERS | B7: BATTLE | C7: VARIABLE | D7: BATTLE | E7: ANY | F7: Required first-track pool | G7: 2 | H7: MUS-003; MUS-004 | I7: SHUFFLE_BAG | J7: First track when the determining battle includes at least one Pure participant. | K7: =IF(AND(A7<>"",G7>0,H7<>""),"OK","ERROR") -> OK
A8: POOL_COMBAT_PURE_CONTINUATION | B8: BATTLE | C8: VARIABLE | D8: BATTLE | E8: ANY | F8: Used after a Pure-specific opener | G8: 6 | H8: MUS-002; MUS-003; MUS-004; MUS-005; MUS-006; MUS-007 | I8: SHUFFLE_BAG | J8: Continuation of a determining battle that includes at least one Pure participant. | K8: =IF(AND(A8<>"",G8>0,H8<>""),"OK","ERROR") -> OK
A9: POOL_FREE_CITY_DAY | B9: AMBIENT | C9: FREE | D9: CITY_OR_GARRISON | E9: DAY | F9: Local entry rule; otherwise pool random | G9: 10 | H9: MUS-012; MUS-013; MUS-014; MUS-015; MUS-016; MUS-017; MUS-018; MUS-020; MUS-021; MUS-022 | I9: SHUFFLE_BAG | J9: Daytime settlements controlled by the Free. | K9: =IF(AND(A9<>"",G9>0,H9<>""),"OK","ERROR") -> OK
A10: POOL_FREE_CITY_NIGHT_NORTH | B10: AMBIENT | C10: FREE | D10: CITY_OR_GARRISON | E10: NIGHT | F10: Random from shuffle bag | G10: 6 | H10: MUS-019; MUS-066; MUS-067; MUS-068; MUS-069; MUS-076 | I10: SHUFFLE_BAG | J10: Night in northern Free settlements. | K10: =IF(AND(A10<>"",G10>0,H10<>""),"OK","ERROR") -> OK
A11: POOL_FREE_CITY_NIGHT_SOUTH | B11: AMBIENT | C11: FREE | D11: CITY_OR_GARRISON | E11: NIGHT | F11: Random from shuffle bag | G11: 5 | H11: MUS-019; MUS-066; MUS-067; MUS-068; MUS-069 | I11: SHUFFLE_BAG | J11: Night in southern Free settlements. | K11: =IF(AND(A11<>"",G11>0,H11<>""),"OK","ERROR") -> OK
A12: POOL_UNITED_CITY_DAY | B12: AMBIENT | C12: UNITED | D12: CITY | E12: DAY | F12: Local entry rule | G12: 10 | H12: MUS-023; MUS-024; MUS-025; MUS-026; MUS-027; MUS-028; MUS-029; MUS-030; MUS-031; MUS-032 | I12: SHUFFLE_BAG | J12: Daytime cities of the United. | K12: =IF(AND(A12<>"",G12>0,H12<>""),"OK","ERROR") -> OK
A13: POOL_UNITED_CITY_NIGHT | B13: AMBIENT | C13: UNITED | D13: CITY | E13: NIGHT | F13: Random from shuffle bag | G13: 2 | H13: MUS-070; MUS-071 | I13: SHUFFLE_BAG | J13: Night in cities of the United. | K13: =IF(AND(A13<>"",G13>0,H13<>""),"OK","ERROR") -> OK
A14: POOL_PURE_CITY_DAY | B14: AMBIENT | C14: PURE | D14: CITY | E14: DAY | F14: Local entry rule; random pool for cities without a named track | G14: 8 | H14: MUS-001; MUS-033; MUS-034; MUS-035; MUS-036; MUS-037; MUS-038; MUS-040 | I14: SHUFFLE_BAG | J14: Daytime cities of the Pure. | K14: =IF(AND(A14<>"",G14>0,H14<>""),"OK","ERROR") -> OK
A15: POOL_PURE_CITY_NIGHT | B15: AMBIENT | C15: PURE | D15: CITY | E15: NIGHT | F15: Ainzbern local entry; otherwise pool random | G15: 3 | H15: MUS-062; MUS-072; MUS-073 | I15: SHUFFLE_BAG | J15: Night in cities of the Pure. | K15: =IF(AND(A15<>"",G15>0,H15<>""),"OK","ERROR") -> OK
A16: POOL_FREE_OUTSIDE_DAY_NORTH | B16: AMBIENT | C16: FREE | D16: OUTSIDE | E16: DAY | F16: Random from shuffle bag | G16: 3 | H16: MUS-080; MUS-087; MUS-088 | I16: SHUFFLE_BAG | J16: Day outside settlements in northern Free territory. | K16: =IF(AND(A16<>"",G16>0,H16<>""),"OK","ERROR") -> OK
... A30: POOL_SEA_NIGHT_CONTINUATION | B30: AMBIENT | C30: SEA | D30: SEA | E30: NIGHT | F30: Used after the night entry track | G30: 5 | H30: MUS-042; MUS-043; MUS-044; MUS-045; MUS-046 | I30: SHUFFLE_BAG | J30: Night continuation in the Sea of Solitude. | K30: =IF(AND(A30<>"",G30>0,H30<>""),"OK","ERROR") -> OK

Sheet 03_Треки
A1: 03 — Track registry
A2: Exact filenames from Итог.7z. CRC32 and byte size support installation-time integrity checks.
A4: Track_ID | B4: File_Name | C4: CRC32_HEX | D4: Size_MiB | E4: Context | F4: Territory | G4: Location_Mode | H4: Phase | I4: Named_Location | J4: Pool_IDs | K4: Entry_Use | L4: Continuation | M4: Duplicate_Group | N4: Notes | O4: QC
A5: MUS-001 | B5: Блараде 6.mp3 | C5: 0x26521318 | D5: 4.0090809 | E5: AMBIENT | F5: PURE | G5: CITY | H5: DAY | I5: Бларадэ | J5: POOL_PURE_CITY_DAY | K5: POOL; NOT BLARADE OPENER | L5: YES | N5: Additional Blarade/Pure-city track. The fixed Blarade opener remains MUS-034. | O5: =IF(AND(A5<>"",B5<>"",E5<>"",J5<>""),"OK","ERROR") -> OK
A6: MUS-002 | B6: Боевая музыка 1.mp3 | C6: 0xA751C3E8 | D6: 2.6475134 | E6: BATTLE | F6: VARIABLE | G6: BATTLE | H6: ANY | J6: POOL_COMBAT_GENERAL; POOL_COMBAT_PURE_CONTINUATION | K6: SHUFFLE_POOL | L6: YES | O6: =IF(AND(A6<>"",B6<>"",E6<>"",J6<>""),"OK","ERROR") -> OK
A7: MUS-003 | B7: Боевая музыка 2 - чистые в бою.mp3 | C7: 0x4C952350 | D7: 2.6483192 | E7: BATTLE | F7: VARIABLE | G7: BATTLE | H7: ANY | J7: POOL_COMBAT_PURE_OPENERS; POOL_COMBAT_PURE_CONTINUATION | K7: SHUFFLE_POOL | L7: YES | O7: =IF(AND(A7<>"",B7<>"",E7<>"",J7<>""),"OK","ERROR") -> OK
A8: MUS-004 | B8: Боевая музыка 3 - чистые в бою.mp3 | C8: 0x5791F95E | D8: 2.6419115 | E8: BATTLE | F8: VARIABLE | G8: BATTLE | H8: ANY | J8: POOL_COMBAT_PURE_OPENERS; POOL_COMBAT_PURE_CONTINUATION | K8: SHUFFLE_POOL | L8: YES | O8: =IF(AND(A8<>"",B8<>"",E8<>"",J8<>""),"OK","ERROR") -> OK
A9: MUS-005 | B9: Боевая музыка 4.mp3 | C9: 0xB618825A | D9: 2.6212521 | E9: BATTLE | F9: VARIABLE | G9: BATTLE | H9: ANY | J9: POOL_COMBAT_GENERAL; POOL_COMBAT_PURE_CONTINUATION | K9: SHUFFLE_POOL | L9: YES | O9: =IF(AND(A9<>"",B9<>"",E9<>"",J9<>""),"OK","ERROR") -> OK
A10: MUS-006 | B10: Боевая ситуация 2.mp3 | C10: 0xF2F7481A | D10: 2.5911112 | E10: BATTLE | F10: VARIABLE | G10: BATTLE | H10: ANY | J10: POOL_COMBAT_GENERAL; POOL_COMBAT_PURE_CONTINUATION | K10: SHUFFLE_POOL | L10: YES | O10: =IF(AND(A10<>"",B10<>"",E10<>"",J10<>""),"OK","ERROR") -> OK
A11: MUS-007 | B11: Боевая ситуация.mp3 | C11: 0x90B543DA | D11: 4.0021076 | E11: BATTLE | F11: VARIABLE | G11: BATTLE | H11: ANY | J11: POOL_COMBAT_GENERAL; POOL_COMBAT_PURE_CONTINUATION | K11: SHUFFLE_POOL | L11: YES | O11: =IF(AND(A11<>"",B11<>"",E11<>"",J11<>""),"OK","ERROR") -> OK
A12: MUS-008 | B12: Главное меню, меню создания персонажа, меню создания кампании и присоединения к ней.mp3 | C12: 0xD55695FA | D12: 1.0889263 | E12: MENU | F12: N/A | G12: MENU | H12: ANY | J12: POOL_MENU | K12: SHUFFLE_POOL | L12: YES | O12: =IF(AND(A12<>"",B12<>"",E12<>"",J12<>""),"OK","ERROR") -> OK
A13: MUS-009 | B13: Главное меню, меню создания персонажа, создание кампании, присоединение к кампании 4.mp3 | C13: 0xEBA8ABC6 | D13: 2.6473684 | E13: MENU | F13: N/A | G13: MENU | H13: ANY | J13: POOL_MENU | K13: SHUFFLE_POOL | L13: YES | M13: DUP-EBA8ABC6 | N13: Same bytes as MUS-041; retained as the menu logical use. | O13: =IF(AND(A13<>"",B13<>"",E13<>"",J13<>""),"OK","ERROR") -> OK
A14: MUS-010 | B14: Главное меню, меню создания персонажа, создание кампании, присоединение к кампании.mp3 | C14: 0xBAD60F7E | D14: 1.9358702 | E14: MENU | F14: N/A | G14: MENU | H14: ANY | J14: POOL_MENU | K14: SHUFFLE_POOL | L14: YES | O14: =IF(AND(A14<>"",B14<>"",E14<>"",J14<>""),"OK","ERROR") -> OK
A15: MUS-011 | B15: Главное меню, создание персонажа, создание и присоединение к кампании 2.mp3 | C15: 0x2996A9B7 | D15: 3.0394058 | E15: MENU | F15: N/A | G15: MENU | H15: ANY | J15: POOL_MENU | K15: SHUFFLE_POOL | L15: YES | O15: =IF(AND(A15<>"",B15<>"",E15<>"",J15<>""),"OK","ERROR") -> OK
A16: MUS-012 | B16: Города вольных - Арена в Чедо.mp3 | C16: 0xC603260B | D16: 1.9572992 | E16: AMBIENT | F16: FREE | G16: CITY | H16: DAY | I16: Чэдо | J16: POOL_FREE_CITY_DAY | K16: LOCAL_ENTRY_OR_POOL | L16: YES | N16: No sublocation flag. One of two random daytime Chado entry tracks. | O16: =IF(AND(A16<>"",B16<>"",E16<>"",J16<>""),"OK","ERROR") -> OK
A17: MUS-013 | B17: Города вольных - Асгана.mp3 | C17: 0x007C0BAE | D17: 1.5529823 | E17: AMBIENT | F17: FREE | G17: CITY | H17: DAY | I17: Асгана | J17: POOL_FREE_CITY_DAY | K17: LOCAL_ENTRY_OR_POOL | L17: YES | O17: =IF(AND(A17<>"",B17<>"",E17<>"",J17<>""),"OK","ERROR") -> OK
A18: MUS-014 | B18: Города вольных - Болота вокруг Ураханты.mp3 | C18: 0x66C8A814 | D18: 6.2469759 | E18: AMBIENT | F18: FREE | G18: CITY | H18: DAY | I18: Ураханта | J18: POOL_FREE_CITY_DAY | K18: LOCAL_ENTRY_OR_POOL | L18: YES | N18: No sublocation flag. One of two random daytime Urahanta entry tracks. | O18: =IF(AND(A18<>"",B18<>"",E18<>"",J18<>""),"OK","ERROR") -> OK
A19: MUS-015 | B19: Города вольных - все имеет цену.mp3 | C19: 0xC4390B84 | D19: 3.0726585 | E19: AMBIENT | F19: FREE | G19: CITY | H19: DAY | J19: POOL_FREE_CITY_DAY | K19: FALLBACK_ENTRY_OR_POOL | L19: YES | O19: =IF(AND(A19<>"",B19<>"",E19<>"",J19<>""),"OK","ERROR") -> OK
A20: MUS-016 | B20: Города вольных - Джасмеберг.mp3 | C20: 0x589AD983 | D20: 2.6936131 | E20: AMBIENT | F20: FREE | G20: CITY | H20: DAY | I20: Джасмеберг | J20: POOL_FREE_CITY_DAY | K20: LOCAL_ENTRY_OR_POOL | L20: YES | O20: =IF(AND(A20<>"",B20<>"",E20<>"",J20<>""),"OK","ERROR") -> OK
A21: MUS-017 | B21: Города вольных - Иншаност.mp3 | C21: 0x61690754 | D21: 1.9955635 | E21: AMBIENT | F21: FREE | G21: CITY | H21: DAY | I21: Иншаност | J21: POOL_FREE_CITY_DAY | K21: LOCAL_ENTRY_OR_POOL | L21: YES | O21: =IF(AND(A21<>"",B21<>"",E21<>"",J21<>""),"OK","ERROR") -> OK
A22: MUS-018 | B22: Города вольных - Нелес.mp3 | C22: 0x5A3EAAAE | D22: 2.6312437 | E22: AMBIENT | F22: FREE | G22: CITY | H22: DAY | I22: Нелес | J22: POOL_FREE_CITY_DAY | K22: LOCAL_ENTRY_OR_POOL | L22: YES | O22: =IF(AND(A22<>"",B22<>"",E22<>"",J22<>""),"OK","ERROR") -> OK
A23: MUS-019 | B23: Города вольных - ночные предместья.mp3 | C23: 0x8715AD46 | D23: 3.3264647 | E23: AMBIENT | F23: FREE | G23: CITY | H23: NIGHT | J23: POOL_FREE_CITY_NIGHT_NORTH; POOL_FREE_CITY_NIGHT_SOUTH | K23: SHUFFLE_POOL | L23: YES | N23: Generic Free-city night track; no separate outskirts marker. | O23: =IF(AND(A23<>"",B23<>"",E23<>"",J23<>""),"OK","ERROR") -> OK
A24: MUS-020 | B24: Города вольных - Ураханта.mp3 | C24: 0x22EFECDD | D24: 3.2370224 | E24: AMBIENT | F24: FREE | G24: CITY | H24: DAY | I24: Ураханта | J24: POOL_FREE_CITY_DAY | K24: LOCAL_ENTRY_OR_POOL | L24: YES | O24: =IF(AND(A24<>"",B24<>"",E24<>"",J24<>""),"OK","ERROR") -> OK
A25: MUS-021 | B25: Города вольных - Чэдо.mp3 | C25: 0x5A4AE731 | D25: 6.9366112 | E25: AMBIENT | F25: FREE | G25: CITY | H25: DAY | I25: Чэдо | J25: POOL_FREE_CITY_DAY | K25: LOCAL_ENTRY_OR_POOL | L25: YES | O25: =IF(AND(A25<>"",B25<>"",E25<>"",J25<>""),"OK","ERROR") -> OK
A26: MUS-022 | B26: Города вольных 5.mp3 | C26: 0xB151C1F4 | D26: 2.621913 | E26: AMBIENT | F26: FREE | G26: CITY | H26: DAY | J26: POOL_FREE_CITY_DAY | K26: SHUFFLE_POOL | L26: YES | O26: =IF(AND(A26<>"",B26<>"",E26<>"",J26<>""),"OK","ERROR") -> OK
A27: MUS-023 | B27: Города Единых - Агремонд.mp3 | C27: 0xFA0B7447 | D27: 6.5199156 | E27: AMBIENT | F27: UNITED | G27: CITY | H27: DAY | I27: Агремонд | J27: POOL_UNITED_CITY_DAY | K27: LOCAL_ENTRY_OR_POOL | L27: YES | O27: =IF(AND(A27<>"",B27<>"",E27<>"",J27<>""),"OK","ERROR") -> OK
A28: MUS-024 | B28: Города Единых - Бреаблего.mp3 | C28: 0x93AC151B | D28: 2.0930672 | E28: AMBIENT | F28: UNITED | G28: CITY | H28: DAY | I28: Бреаблего | J28: POOL_UNITED_CITY_DAY | K28: LOCAL_ENTRY_OR_POOL | L28: YES | O28: =IF(AND(A28<>"",B28<>"",E28<>"",J28<>""),"OK","ERROR") -> OK
A29: MUS-025 | B29: Города Единых - Брул.mp3 | C29: 0xC812EA37 | D29: 2.6786432 | E29: AMBIENT | F29: UNITED | G29: CITY | H29: DAY | I29: Брул | J29: POOL_UNITED_CITY_DAY | K29: LOCAL_ENTRY_OR_POOL | L29: YES | O29: =IF(AND(A29<>"",B29<>"",E29<>"",J29<>""),"OK","ERROR") -> OK
A30: MUS-026 | B30: Города Единых - Грагос.mp3 | C30: 0x2ED71B62 | D30: 2.9416599 | E30: AMBIENT | F30: UNITED | G30: CITY | H30: DAY | I30: Грагос | J30: POOL_UNITED_CITY_DAY | K30: LOCAL_ENTRY_OR_POOL | L30: YES | O30: =IF(AND(A30<>"",B30<>"",E30<>"",J30<>""),"OK","ERROR") -> OK
A31: MUS-027 | B31: Города Единых - Йошиган.mp3 | C31: 0x23E16569 | D31: 6.5757694 | E31: AMBIENT | F31: UNITED | G31: CITY | H31: DAY | I31: Йошиган | J31: POOL_UNITED_CITY_DAY | K31: LOCAL_ENTRY_OR_POOL | L31: YES | O31: =IF(AND(A31<>"",B31<>"",E31<>"",J31<>""),"OK","ERROR") -> OK
A32: MUS-028 | B32: Города Единых - Огранта.mp3 | C32: 0x45608E14 | D32: 5.1582003 | E32: AMBIENT | F32: UNITED | G32: CITY | H32: DAY | I32: Огранта | J32: POOL_UNITED_CITY_DAY | K32: LOCAL_ENTRY_OR_POOL | L32: YES | O32: =IF(AND(A32<>"",B32<>"",E32<>"",J32<>""),"OK","ERROR") -> OK
A33: MUS-029 | B33: Города Единых - Садена.mp3 | C33: 0x4AC972FF | D33: 5.0225945 | E33: AMBIENT | F33: UNITED | G33: CITY | H33: DAY | I33: Садена | J33: POOL_UNITED_CITY_DAY | K33: LOCAL_ENTRY_OR_POOL | L33: YES | O33: =IF(AND(A33<>"",B33<>"",E33<>"",J33<>""),"OK","ERROR") -> OK
A34: MUS-030 | B34: Города Единых - Строра.mp3 | C34: 0x9DDF9826 | D34: 2.1171093 | E34: AMBIENT | F34: UNITED | G34: CITY | H34: DAY | I34: Строра | J34: POOL_UNITED_CITY_DAY | K34: LOCAL_ENTRY_OR_POOL | L34: YES | O34: =IF(AND(A34<>"",B34<>"",E34<>"",J34<>""),"OK","ERROR") -> OK
A35: MUS-031 | B35: Города Единых - Хэйдерон.mp3 | C35: 0x35377F67 | D35: 5.0739508 | E35: AMBIENT | F35: UNITED | G35: CITY | H35: DAY | I35: Хэйдерон | J35: POOL_UNITED_CITY_DAY | K35: LOCAL_ENTRY_OR_POOL | L35: YES | O35: =IF(AND(A35<>"",B35<>"",E35<>"",J35<>""),"OK","ERROR") -> OK
A36: MUS-032 | B36: Города Единых - Центр Садены.mp3 | C36: 0xF805FBDC | D36: 2.3526726 | E36: AMBIENT | F36: UNITED | G36: CITY | H36: DAY | I36: Садена | J36: POOL_UNITED_CITY_DAY | K36: LOCAL_ENTRY_OR_POOL | L36: YES | N36: No sublocation flag. One of two random daytime Sadena entry tracks. | O36: =IF(AND(A36<>"",B36<>"",E36<>"",J36<>""),"OK","ERROR") -> OK
A37: MUS-033 | B37: Города Чистых - Айнцберн.mp3 | C37: 0x14ED8734 | D37: 2.88486 | E37: AMBIENT | F37: PURE | G37: CITY | H37: DAY | I37: Айнцберн | J37: POOL_PURE_CITY_DAY | K37: LOCAL_ENTRY_OR_POOL | L37: YES | O37: =IF(AND(A37<>"",B37<>"",E37<>"",J37<>""),"OK","ERROR") -> OK
A38: MUS-034 | B38: Города Чистых - Бларадэ.mp3 | C38: 0x9FBC0DA0 | D38: 5.2487917 | E38: AMBIENT | F38: PURE | G38: CITY | H38: DAY | I38: Бларадэ | J38: POOL_PURE_CITY_DAY | K38: LOCAL_ENTRY_OR_POOL | L38: YES | O38: =IF(AND(A38<>"",B38<>"",E38<>"",J38<>""),"OK","ERROR") -> OK
A39: MUS-035 | B39: Города Чистых - Гленхейм.mp3 | C39: 0xC63D4C95 | D39: 4.4059162 | E39: AMBIENT | F39: PURE | G39: CITY | H39: DAY | I39: Гленхейм | J39: POOL_PURE_CITY_DAY | K39: LOCAL_ENTRY_OR_POOL | L39: YES | O39: =IF(AND(A39<>"",B39<>"",E39<>"",J39<>""),"OK","ERROR") -> OK
A40: MUS-036 | B40: Города Чистых - Кастелькросс.mp3 | C40: 0xD7C07D05 | D40: 3.0705805 | E40: AMBIENT | F40: PURE | G40: CITY | H40: DAY | I40: Кастелькросс | J40: POOL_PURE_CITY_DAY | K40: LOCAL_ENTRY_OR_POOL | L40: YES | O40: =IF(AND(A40<>"",B40<>"",E40<>"",J40<>""),"OK","ERROR") -> OK
A41: MUS-037 | B41: Города Чистых - Кенси.mp3 | C41: 0xCEF8684D | D41: 2.576046 | E41: AMBIENT | F41: PURE | G41: CITY | H41: DAY | I41: Кенси | J41: POOL_PURE_CITY_DAY | K41: LOCAL_ENTRY_OR_POOL | L41: YES | O41: =IF(AND(A41<>"",B41<>"",E41<>"",J41<>""),"OK","ERROR") -> OK
...

Sheet 04_Локации
A1: 04 — Settlements and entry rules
A2: City/garrison circles have the highest geographic priority. Coordinates are normalized to the page-7 playable crop.
A4: Location_ID | B4: Display_Name | C4: Type | D4: Faction | E4: Subregion | F4: U | G4: V | H4: Radius_UV | I4: Day_Entry_Mode | J4: Day_Entry_Track_IDs | K4: Day_Pool_ID | L4: Night_Entry_Mode | M4: Night_Entry_Track_IDs | N4: Night_Pool_ID | O4: Notes | P4: QC
A5: CITY_FREE_SIRRINH | B5: Сирринх | C5: CITY | D5: FREE | E5: FREE_NORTH | F5: 0.331 | G5: 0.07 | H5: 0.018 | I5: FIXED_TRACK | J5: MUS-015 | K5: POOL_FREE_CITY_DAY | L5: RANDOM_FROM_POOL | N5: POOL_FREE_CITY_NIGHT_NORTH | P5: =IF(AND(E5<>"",F5>=0,F5<=1,G5>=0,G5<=1,H5>0),"OK","ERROR") -> OK
A6: CITY_FREE_BRANTA | B6: Бранта | C6: CITY | D6: FREE | E6: FREE_NORTH | F6: 0.289 | G6: 0.136 | H6: 0.018 | I6: FIXED_TRACK | J6: MUS-015 | K6: POOL_FREE_CITY_DAY | L6: RANDOM_FROM_POOL | N6: POOL_FREE_CITY_NIGHT_NORTH | P6: =IF(AND(E6<>"",F6>=0,F6<=1,G6>=0,G6<=1,H6>0),"OK","ERROR") -> OK
A7: CITY_FREE_INSHANOST | B7: Иншаност | C7: CITY | D7: FREE | E7: FREE_NORTH | F7: 0.236 | G7: 0.235 | H7: 0.018 | I7: FIXED_TRACK | J7: MUS-017 | K7: POOL_FREE_CITY_DAY | L7: RANDOM_FROM_POOL | N7: POOL_FREE_CITY_NIGHT_NORTH | P7: =IF(AND(E7<>"",F7>=0,F7<=1,G7>=0,G7<=1,H7>0),"OK","ERROR") -> OK
A8: CITY_FREE_NELES | B8: Нелес | C8: CITY | D8: FREE | E8: FREE_NORTH | F8: 0.14 | G8: 0.278 | H8: 0.018 | I8: FIXED_TRACK | J8: MUS-018 | K8: POOL_FREE_CITY_DAY | L8: RANDOM_FROM_POOL | N8: POOL_FREE_CITY_NIGHT_NORTH | P8: =IF(AND(E8<>"",F8>=0,F8<=1,G8>=0,G8<=1,H8>0),"OK","ERROR") -> OK
A9: CITY_FREE_KISHKA | B9: Кишка | C9: CITY | D9: FREE | E9: FREE_NORTH | F9: 0.331 | G9: 0.262 | H9: 0.018 | I9: FIXED_TRACK | J9: MUS-015 | K9: POOL_FREE_CITY_DAY | L9: RANDOM_FROM_POOL | N9: POOL_FREE_CITY_NIGHT_NORTH | P9: =IF(AND(E9<>"",F9>=0,F9<=1,G9>=0,G9<=1,H9>0),"OK","ERROR") -> OK
A10: CITY_FREE_DANMUR | B10: Данмур | C10: CITY | D10: FREE | E10: FREE_NORTH | F10: 0.224 | G10: 0.335 | H10: 0.018 | I10: FIXED_TRACK | J10: MUS-015 | K10: POOL_FREE_CITY_DAY | L10: RANDOM_FROM_POOL | N10: POOL_FREE_CITY_NIGHT_NORTH | P10: =IF(AND(E10<>"",F10>=0,F10<=1,G10>=0,G10<=1,H10>0),"OK","ERROR") -> OK
A11: CITY_FREE_URAHANTA | B11: Ураханта | C11: CITY | D11: FREE | E11: FREE_SOUTH | F11: 0.059 | G11: 0.46 | H11: 0.018 | I11: RANDOM_LOCAL_TRACKS | J11: MUS-020; MUS-014 | K11: POOL_FREE_CITY_DAY | L11: RANDOM_FROM_POOL | N11: POOL_FREE_CITY_NIGHT_SOUTH | P11: =IF(AND(E11<>"",F11>=0,F11<=1,G11>=0,G11<=1,H11>0),"OK","ERROR") -> OK
A12: CITY_FREE_ASGANA | B12: Асгана | C12: CITY | D12: FREE | E12: FREE_SOUTH | F12: 0.059 | G12: 0.561 | H12: 0.018 | I12: FIXED_TRACK | J12: MUS-013 | K12: POOL_FREE_CITY_DAY | L12: RANDOM_FROM_POOL | N12: POOL_FREE_CITY_NIGHT_SOUTH | P12: =IF(AND(E12<>"",F12>=0,F12<=1,G12>=0,G12<=1,H12>0),"OK","ERROR") -> OK
A13: CITY_FREE_CHADO | B13: Чэдо | C13: CITY | D13: FREE | E13: FREE_SOUTH | F13: 0.23 | G13: 0.6 | H13: 0.018 | I13: RANDOM_LOCAL_TRACKS | J13: MUS-021; MUS-012 | K13: POOL_FREE_CITY_DAY | L13: RANDOM_FROM_POOL | N13: POOL_FREE_CITY_NIGHT_SOUTH | P13: =IF(AND(E13<>"",F13>=0,F13<=1,G13>=0,G13<=1,H13>0),"OK","ERROR") -> OK
A14: CITY_FREE_JASMEBERG | B14: Джасмеберг | C14: CITY | D14: FREE | E14: FREE_SOUTH | F14: 0.154 | G14: 0.691 | H14: 0.018 | I14: FIXED_TRACK | J14: MUS-016 | K14: POOL_FREE_CITY_DAY | L14: RANDOM_FROM_POOL | N14: POOL_FREE_CITY_NIGHT_SOUTH | P14: =IF(AND(E14<>"",F14>=0,F14<=1,G14>=0,G14<=1,H14>0),"OK","ERROR") -> OK
A15: CITY_FREE_KERIGATE | B15: Керигейт | C15: CITY | D15: FREE | E15: FREE_SOUTH | F15: 0.19 | G15: 0.814 | H15: 0.018 | I15: FIXED_TRACK | J15: MUS-015 | K15: POOL_FREE_CITY_DAY | L15: RANDOM_FROM_POOL | N15: POOL_FREE_CITY_NIGHT_SOUTH | P15: =IF(AND(E15<>"",F15>=0,F15<=1,G15>=0,G15<=1,H15>0),"OK","ERROR") -> OK
A16: CITY_UNITED_BREABLEGO | B16: Бреаблего | C16: CITY | D16: UNITED | E16: UNITED_NORTH | F16: 0.434 | G16: 0.084 | H16: 0.018 | I16: FIXED_TRACK | J16: MUS-024 | K16: POOL_UNITED_CITY_DAY | L16: RANDOM_FROM_POOL | N16: POOL_UNITED_CITY_NIGHT | P16: =IF(AND(E16<>"",F16>=0,F16<=1,G16>=0,G16<=1,H16>0),"OK","ERROR") -> OK
... A24: CITY_UNITED_OGRANTA | B24: Огранта | C24: CITY | D24: UNITED | E24: UNITED_GENERAL | F24: 0.477 | G24: 0.449 | H24: 0.018 | I24: FIXED_TRACK | J24: MUS-028 | K24: POOL_UNITED_CITY_DAY | L24: RANDOM_FROM_POOL | N24: POOL_UNITED_CITY_NIGHT | P24: =IF(AND(E24<>"",F24>=0,F24<=1,G24>=0,G24<=1,H24>0),"OK","ERROR") -> OK
A25: CITY_PURE_NEIT | B25: Нэйт | C25: CITY | D25: PURE | E25: PURE | F25: 0.442 | G25: 0.64 | H25: 0.018 | I25: RANDOM_FROM_POOL | K25: POOL_PURE_CITY_DAY | L25: RANDOM_FROM_POOL | N25: POOL_PURE_CITY_NIGHT | O25: City override: treated as Pure even though its marker lies inside No-Man's Lands. No named day track: choose randomly from POOL_PURE_CITY_DAY. | P25: =IF(AND(E25<>"",F25>=0,F25<=1,G25>=0,G25<=1,H25>0),"OK","ERROR") -> OK
A26: CITY_PURE_KENSI | B26: Кенси | C26: CITY | D26: PURE | E26: PURE | F26: 0.588 | G26: 0.692 | H26: 0.018 | I26: FIXED_TRACK | J26: MUS-037 | K26: POOL_PURE_CITY_DAY | L26: RANDOM_FROM_POOL | N26: POOL_PURE_CITY_NIGHT | P26: =IF(AND(E26<>"",F26>=0,F26<=1,G26>=0,G26<=1,H26>0),"OK","ERROR") -> OK
A27: CITY_PURE_CESMOR | B27: Цесмор | C27: CITY | D27: PURE | E27: PURE | F27: 0.734 | G27: 0.684 | H27: 0.018 | I27: FIXED_TRACK | J27: MUS-040 | K27: POOL_PURE_CITY_DAY | L27: RANDOM_FROM_POOL | N27: POOL_PURE_CITY_NIGHT | P27: =IF(AND(E27<>"",F27>=0,F27<=1,G27>=0,G27<=1,H27>0),"OK","ERROR") -> OK
A28: CITY_PURE_KASTELCROSS | B28: Кастелькросс | C28: CITY | D28: PURE | E28: PURE | F28: 0.804 | G28: 0.736 | H28: 0.018 | I28: FIXED_TRACK | J28: MUS-036 | K28: POOL_PURE_CITY_DAY | L28: RANDOM_FROM_POOL | N28: POOL_PURE_CITY_NIGHT | P28: =IF(AND(E28<>"",F28>=0,F28<=1,G28>=0,G28<=1,H28>0),"OK","ERROR") -> OK
A29: CITY_PURE_GLENHEIM | B29: Гленхейм | C29: CITY | D29: PURE | E29: PURE | F29: 0.64 | G29: 0.76 | H29: 0.018 | I29: FIXED_TRACK | J29: MUS-035 | K29: POOL_PURE_CITY_DAY | L29: RANDOM_FROM_POOL | N29: POOL_PURE_CITY_NIGHT | P29: =IF(AND(E29<>"",F29>=0,F29<=1,G29>=0,G29<=1,H29>0),"OK","ERROR") -> OK
A30: CITY_PURE_KORNADORA | B30: Корнадора | C30: CITY | D30: PURE | E30: PURE | F30: 0.529 | G30: 0.755 | H30: 0.018 | I30: FIXED_TRACK | J30: MUS-038 | K30: POOL_PURE_CITY_DAY | L30: RANDOM_FROM_POOL | N30: POOL_PURE_CITY_NIGHT | P30: =IF(AND(E30<>"",F30>=0,F30<=1,G30>=0,G30<=1,H30>0),"OK","ERROR") -> OK
A31: CITY_PURE_BLARADE | B31: Бларадэ | C31: CITY | D31: PURE | E31: PURE | F31: 0.439 | G31: 0.772 | H31: 0.018 | I31: FIXED_TRACK | J31: MUS-034 | K31: POOL_PURE_CITY_DAY | L31: RANDOM_FROM_POOL | N31: POOL_PURE_CITY_NIGHT | O31: Fixed opener is MUS-034. MUS-001 is continuation/general Pure-city music. | P31: =IF(AND(E31<>"",F31>=0,F31<=1,G31>=0,G31<=1,H31>0),"OK","ERROR") -> OK
A32: CITY_PURE_ERIVEL | B32: Эривел | C32: CITY | D32: PURE | E32: PURE | F32: 0.434 | G32: 0.876 | H32: 0.018 | I32: RANDOM_FROM_POOL | K32: POOL_PURE_CITY_DAY | L32: RANDOM_FROM_POOL | N32: POOL_PURE_CITY_NIGHT | O32: No named day track: choose randomly from POOL_PURE_CITY_DAY. | P32: =IF(AND(E32<>"",F32>=0,F32<=1,G32>=0,G32<=1,H32>0),"OK","ERROR") -> OK
A33: CITY_PURE_AINZBERN | B33: Айнцберн | C33: CITY | D33: PURE | E33: PURE | F33: 0.682 | G33: 0.883 | H33: 0.018 | I33: FIXED_TRACK | J33: MUS-033 | K33: POOL_PURE_CITY_DAY | L33: FIXED_TRACK | M33: MUS-062 | N33: POOL_PURE_CITY_NIGHT | P33: =IF(AND(E33<>"",F33>=0,F33<=1,G33>=0,G33<=1,H33>0),"OK","ERROR") -> OK
A34: CITY_PURE_ESTREFORD | B34: Эстрефорд | C34: CITY | D34: PURE | E34: PURE | F34: 0.355 | G34: 0.934 | H34: 0.018 | I34: RANDOM_FROM_POOL | K34: POOL_PURE_CITY_DAY | L34: RANDOM_FROM_POOL | N34: POOL_PURE_CITY_NIGHT | O34: No named day track: choose randomly from POOL_PURE_CITY_DAY. | P34: =IF(AND(E34<>"",F34>=0,F34<=1,G34>=0,G34<=1,H34>0),"OK","ERROR") -> OK
A35: GARRISON_FREE_NW | B35: Северо-западный гарнизон | C35: GARRISON | D35: FREE | E35: FREE_NORTH | F35: 0.4 | G35: 0.071 | H35: 0.012 | I35: FIXED_TRACK | J35: MUS-015 | K35: POOL_FREE_CITY_DAY | L35: RANDOM_FROM_POOL | N35: POOL_FREE_CITY_NIGHT_NORTH | O35: Approved as a Free garrison; settlement rules override territory. | P35: =IF(AND(E35<>"",F35>=0,F35<=1,G35>=0,G35<=1,H35>0),"OK","ERROR") -> OK
A36: GARRISON_FREE_CENTRAL | B36: Центральный гарнизон | C36: GARRISON | D36: FREE | E36: FREE_NORTH | F36: 0.417 | G36: 0.429 | H36: 0.012 | I36: FIXED_TRACK | J36: MUS-015 | K36: POOL_FREE_CITY_DAY | L36: RANDOM_FROM_POOL | N36: POOL_FREE_CITY_NIGHT_NORTH | O36: Approved as a Free garrison; settlement rules override territory. | P36: =IF(AND(E36<>"",F36>=0,F36<=1,G36>=0,G36<=1,H36>0),"OK","ERROR") -> OK
A37: GARRISON_FREE_SW | B37: Юго-западный гарнизон | C37: GARRISON | D37: FREE | E37: FREE_SOUTH | F37: 0.273 | G37: 0.885 | H37: 0.012 | I37: FIXED_TRACK | J37: MUS-015 | K37: POOL_FREE_CITY_DAY | L37: RANDOM_FROM_POOL | N37: POOL_FREE_CITY_NIGHT_SOUTH | O37: Approved as a Free garrison; settlement rules override territory. | P37: =IF(AND(E37<>"",F37>=0,F37<=1,G37>=0,G37<=1,H37>0),"OK","ERROR") -> OK

Sheet 05_Карта
A1: 05 — Normalized map coordinates
A2: Red grid labels show normalized U/V. Translucent polygons and settlement rings visualize the implementation baseline; the image is not a runtime asset.
A4: Coordinate origin | B4: Top-left of playable crop | D4: Overlay legend: Free = red, United = blue, Pure = white, No-Man's Lands = green, coastal No-Man's overlay = gold. Debug requirement: render the same polygons and location radii over the map. A release candidate passes when every city star lies inside its ring, all three red marks lie inside Free garrison rings, and no boundary deviation exceeds 0.01 UV.
A5: U formula | B5: u = (sourcePixelX - 20) / 1397
A6: V formula | B6: v = (sourcePixelY - 170) / 1450
A7: Reverse X | B7: sourcePixelX = 20 + u × 1397
A8: Reverse Y | B8: sourcePixelY = 170 + v × 1450
A9: Settlement hit test | B9: distance((u,v), centre) <= Radius_UV
A10: Polygon hit test | B10: point-in-polygon; boundary is inside
A11: Evaluation | B11: Location circle → Sea/land → NML overlays → faction zone

Sheet 06_Геозоны
A1: 06 — Geographic zones
A2: Definitions and vertex rows form the runtime point-in-polygon baseline. U/V use the coordinate system on 05_Карта.
A4: Zone_ID | B4: Name | C4: Geometry | D4: Priority | E4: Parent | F4: Day_Pool_ID | G4: Night_Pool_ID | H4: Day_Entry_Track_IDs | I4: Night_Entry_Track_IDs | J4: Geometry_Params | K4: Notes
A5: PLAYABLE_AREA | B5: Playable map area | C5: ELLIPSE | D5: 10 | J5: {"cx":0.5,"cy":0.5,"rx":0.495,"ry":0.495} | K5: Points outside are invalid and cannot receive a group marker.
A6: LAND_MASK | B6: Continental land mask | C6: POLYGON | D6: 20 | E6: PLAYABLE_AREA | K6: Rivers and inland waters inherit the surrounding land. Outside this mask is the Sea of Solitude.
A7: SEA | B7: Sea of Solitude | C7: DERIVED | D7: 30 | E7: PLAYABLE_AREA | F7: POOL_SEA_DAY | G7: POOL_SEA_NIGHT_CONTINUATION | I7: MUS-047 | J7: PLAYABLE_AREA AND NOT LAND_MASK | K7: All external water. City/port circles override sea.
A8: NML_COASTAL | B8: Coastal No-Man's Lands overlay | C8: POLYGON | D8: 85 | E8: NML_CENTRAL_EAST | F8: POOL_NML_DAY | G8: POOL_NML_NIGHT | H8: MUS-048 | K8: Daytime entry uses the coastal anchor, then POOL_NML_DAY.
A9: NML_NORTH | B9: Northern No-Man's Lands | C9: POLYGON | D9: 80 | E9: LAND_MASK | F9: POOL_NML_DAY | G9: POOL_NML_NIGHT | K9: All No-Man's Lands share the same pools.
A10: NML_CENTRAL_WEST | B10: Central-west No-Man's Lands | C10: POLYGON | D10: 80 | E10: LAND_MASK | F10: POOL_NML_DAY | G10: POOL_NML_NIGHT | K10: All No-Man's Lands share the same pools.
A11: NML_CENTRAL_EAST | B11: Central-east No-Man's Lands | C11: POLYGON | D11: 80 | E11: LAND_MASK | F11: POOL_NML_DAY | G11: POOL_NML_NIGHT | K11: All No-Man's Lands share the same pools.
A12: NML_SOUTHWEST | B12: South-west No-Man's Lands | C12: POLYGON | D12: 80 | E12: LAND_MASK | F12: POOL_NML_DAY | G12: POOL_NML_NIGHT | K12: All No-Man's Lands share the same pools.
A13: FREE_NORTH | B13: Northern Free territory | C13: POLYGON | D13: 60 | E13: LAND_MASK | F13: POOL_FREE_OUTSIDE_DAY_NORTH | G13: POOL_FREE_OUTSIDE_NIGHT_NORTH
A14: FREE_SOUTH | B14: Southern Free territory | C14: POLYGON | D14: 60 | E14: LAND_MASK | F14: POOL_FREE_OUTSIDE_DAY_SOUTH | G14: POOL_FREE_OUTSIDE_NIGHT_SOUTH
A15: UNITED | B15: United territory | C15: POLYGON | D15: 60 | E15: LAND_MASK | F15: POOL_UNITED_OUTSIDE_DAY_GENERAL | G15: POOL_UNITED_OUTSIDE_NIGHT
A16: UNITED_NORTH | B16: Northern United overlay | C16: POLYGON | D16: 65 | E16: UNITED | F16: POOL_UNITED_OUTSIDE_DAY_NORTH | G16: POOL_UNITED_OUTSIDE_NIGHT | K16: Adds the northern daytime track.
A17: PURE | B17: Pure territory | C17: POLYGON | D17: 60 | E17: LAND_MASK | F17: POOL_PURE_OUTSIDE_DAY | G17: POOL_PURE_OUTSIDE_NIGHT | K17: At night, deliberately reuses Pure city-night tracks.
A20: Zone_ID | B20: Vertex_Order | C20: U | D20: V | E20: QC
A21: LAND_MASK | B21: 1 | C21: 0.31 | D21: 0.05 | E21: =IF(AND(C21>=0,C21<=1,D21>=0,D21<=1),"OK","ERROR") -> OK
A22: LAND_MASK | B22: 2 | C22: 0.36 | D22: 0.05 | E22: =IF(AND(C22>=0,C22<=1,D22>=0,D22<=1),"OK","ERROR") -> OK
A23: LAND_MASK | B23: 3 | C23: 0.4 | D23: 0.08 | E23: =IF(AND(C23>=0,C23<=1,D23>=0,D23<=1),"OK","ERROR") -> OK
A24: LAND_MASK | B24: 4 | C24: 0.43 | D24: 0.07 | E24: =IF(AND(C24>=0,C24<=1,D24>=0,D24<=1),"OK","ERROR") -> OK
A25: LAND_MASK | B25: 5 | C25: 0.47 | D25: 0.04 | E25: =IF(AND(C25>=0,C25<=1,D25>=0,D25<=1),"OK","ERROR") -> OK
A26: LAND_MASK | B26: 6 | C26: 0.55 | D26: 0.04 | E26: =IF(AND(C26>=0,C26<=1,D26>=0,D26<=1),"OK","ERROR") -> OK
A27: LAND_MASK | B27: 7 | C27: 0.58 | D27: 0.07 | E27: =IF(AND(C27>=0,C27<=1,D27>=0,D27<=1),"OK","ERROR") -> OK
A28: LAND_MASK | B28: 8 | C28: 0.62 | D28: 0.075 | E28: =IF(AND(C28>=0,C28<=1,D28>=0,D28<=1),"OK","ERROR") -> OK
A29: LAND_MASK | B29: 9 | C29: 0.67 | D29: 0.09 | E29: =IF(AND(C29>=0,C29<=1,D29>=0,D29<=1),"OK","ERROR") -> OK
A30: LAND_MASK | B30: 10 | C30: 0.72 | D30: 0.12 | E30: =IF(AND(C30>=0,C30<=1,D30>=0,D30<=1),"OK","ERROR") -> OK
A31: LAND_MASK | B31: 11 | C31: 0.76 | D31: 0.15 | E31: =IF(AND(C31>=0,C31<=1,D31>=0,D31<=1),"OK","ERROR") -> OK
A32: LAND_MASK | B32: 12 | C32: 0.79 | D32: 0.2 | E32: =IF(AND(C32>=0,C32<=1,D32>=0,D32<=1),"OK","ERROR") -> OK
... A188: PURE | B188: 10 | C188: 0.235 | D188: 0.72 | E188: =IF(AND(C188>=0,C188<=1,D188>=0,D188<=1),"OK","ERROR") -> OK

Sheet 07_QA
A1: 07 — Acceptance tests
A2: Minimum regression suite for soundtrack selection, synchronization, map classification and fallbacks.
A4: QA_ID | B4: Area | C4: Event | D4: Preconditions | E4: Expected result
A5: QA-001 | B5: MENU | C5: User opens main menu | D5: No campaign scene | E5: One of MUS-008..MUS-011 starts.
A6: QA-002 | B6: MENU | C6: User moves from main menu to character creation | D6: Menu track is playing | E6: Track continues; no restart because effective pool is unchanged.
A7: QA-003 | B7: FOCUS | C7: Campaign contains no eligible groups | D7: No battle | E7: Music fades to silence.
A8: QA-004 | B8: CITY | C8: Determining group enters Асгана at 12:00 | D8: No battle | E8: MUS-013 starts, then POOL_FREE_CITY_DAY.
A9: QA-005 | B9: CITY | C9: Determining group enters Чэдо at 12:00 | D9: No battle | E9: First track is randomly MUS-012 or MUS-021.
A10: QA-006 | B10: CITY | C10: Determining group enters Ураханта at 12:00 | D10: No battle | E10: First track is randomly MUS-014 or MUS-020.
A11: QA-007 | B11: CITY | C11: Determining group enters Садена at 12:00 | D11: No battle | E11: First track is randomly MUS-029 or MUS-032.
A12: QA-008 | B12: CITY | C12: Determining group enters Бларадэ at 12:00 | D12: No battle | E12: MUS-034 starts; MUS-001 is not selected as the opener.
A13: QA-009 | B13: CITY | C13: Blarade opener ends | D13: Context unchanged | E13: Continuation uses POOL_PURE_CITY_DAY and may later select MUS-001.
A14: QA-010 | B14: CITY | C14: Determining group enters Сирринх at 12:00 | D14: No battle | E14: Fallback MUS-015 starts.
A15: QA-011 | B15: CITY | C15: Determining group enters Нэйт at 12:00 | D15: Marker lies in No-Man's polygon | E15: City override wins; random track from POOL_PURE_CITY_DAY.
... A44: QA-040 | B44: PERSISTENCE | C44: Campaign is saved and reopened mid-track | D44: Assets unchanged | E44: Track, offset and remaining shuffle bag resume without reselection.

Sheet 08_Решения
A1: 08 — Decision traceability
A2: All proposals from the clarification table are approved except the explicit overrides recorded below.
A4: Decision_ID | B4: Status | C4: Final decision
A5: DEC-01 | B5: APPROVED | C5: Global synchronized playback; local volume and mute.
A6: DEC-02 | B6: APPROVED | C6: Battle overrides night; night overrides daytime territory music.
A7: DEC-03 | B7: APPROVED | C7: Any battle is global; determining battle uses largest group, then oldest.
A8: DEC-04 | B8: APPROVED | C8: Headcount includes living active PCs and allied NPCs in the group.
A9: DEC-05 | B9: APPROVED | C9: Immediate switch with about 2-second crossfade; unchanged pool stays playing.
A10: DEC-06 | B10: APPROVED | C10: Local entry music on every new entry; no restart inside one zone.
A11: DEC-07 | B11: APPROVED | C11: Shuffle-bag randomization without avoidable immediate repeats.
A12: DEC-08 | B12: APPROVED | C12: Night is [21:00,06:00); day is [06:00,21:00). The music phase follows campaign dayPhase, not localLighting.
A13: DEC-09 | B13: APPROVED | C13: Four menu tracks cover the main/creation/join flows.
A14: DEC-10 | B14: APPROVED | C14: Named city tracks may appear in other same-faction cities after the opener.
A15: DEC-11 | B15: APPROVED | C15: Fallbacks for cities without a named track; Nэйт is Pure.
... A25: DEC-21 | B25: APPROVED | C25: Artifact includes logic plus normalized map geometry.

Sheet 09_Изменения_v1.1
A1: SYMBIOSIS V7 — Soundtrack Playback Registry v1.1
A2: Night boundary synchronized with the game clock; external audio files remain outside this deliverable.
A4: ID | B4: Область | C4: Было | D4: Стало | E4: Основание | F4: Статус
A5: SND-V11-001 | B5: R-007 | C5: Night 18:00–06:00 | D5: Night 21:00–06:00 | E5: Q-SOUND-NIGHT-001 | F5: PASS
A6: SND-V11-002 | B6: NIGHT_START_HOUR | C6: 18 | D6: 21 | E6: Campaign dayPhase | F6: PASS
A7: SND-V11-003 | B7: EV-09 | C7: Clock reaches 18:00 | D7: Clock reaches 21:00 | E7: Q-SOUND-NIGHT-001 | F7: PASS
A8: SND-V11-004 | B8: QA | C8: 18:00 transition cases | D8: 21:00 transition cases | E8: Acceptance sync | F8: PASS
A9: SND-V11-005 | B9: localLighting | C9: Implicit | D9: Explicitly does not affect music | E9: Atlas TIM-004/MAP-009 | F9: PASS
