Workbook

Sheet Сводка
A1: СИМБИОЗ V7 — итоговый исполняемый реестр правил
A2: Версия 1.7 — неизменяемое мастерское XP, восстановленный генератор групп и исправленный формульный контроль
A4: Показатель | B4: Значение | C4: Назначение | E4: Модель применения правил
A5: Всего runtime-правил | B5: 739 | C5: Уникальные карточки игрового реестра | E5: 1. META-001: базовые поля остаются нормативными в непротиворечащей части.
A6: Активно | B6: 699 | C6: Включить в игровое ядро | E6: v1.7=110 > v1.6=100 > v1.5=90 > v1.4=80 > v1.3=70 > v1.2=60 > v1.1=50 > QA 2.0=40 > QA 1.0=30 > база=10
A7: Не автоматизируется | B7: 40 | C7: Tombstone: хранить для трассировки, не реализовывать | E7: 3. Локальное исключение сильнее общего порядка.
A8: Базовые правила | B8: 539 | C8: CORE / SYM / MON | E8: 4. Полное исключение возможно только при явном статусе «Не автоматизируется».
A9: QA-решения | B9: 139 | C9: CQA / AQA / AQ2 / AQ3 | E9: 5. В листе «Реестр правил» уже записана итоговая композиция; повторно накладывать ответы не нужно.
A10: Новые согласованные карточки | B10: 61 | C10: CORE-230..234 и синхронизированные карточки; generator patch v1.7 | E10: 6. Устаревший набор QA-тестов не использовался как источник правил.
A11: Новые предразработочные решения | B11: 18 | C11: Закрытый пакет Pre-development QA v1.4
A12: Нормализованные QA-карточки | B12: 139 | C12: Конкретные runtime-поля | E12: Как использовать книгу при разработке Windows-приложения
A13: Ответы пользователя | B13: 444 | C13: Q-GM-XP-001 и Q-SOUND-NIGHT-001 закрыты; Q&A v1.2 восстановлен до полного состава | E13: «Реестр правил» — нормативная строка на каждый Rule ID.
A14: Открытые вопросы | B14: 0 | C14: Должно оставаться 0 | E14: «Параметры» — нормализованные вычисления, ресурсы, сроки и ручные решения.
A15: Проверка | B15: Формула | C15: Ожидаемо | E15: «Связи» — зависимости и приоритетные уточнения для графа правил.
A16: Строк правил | B16: =COUNTA('Реестр правил'!B2:B740) -> 739 | C16: 739 | E16: «Источники» и «Решения QA» — трассировка к утверждённым ответам.
A17: Активных правил | B17: =COUNTIF('Реестр правил'!C2:C740,"Активно") -> 699 | C17: 699 | E17: Листы изменений сохраняют историю; v1.7 фиксирует GM_DIRECT, генератор 80–150% и честные проверки выпуска.
A18: Исключённых правил | B18: =COUNTIF('Реестр правил'!C2:C740,"Не автоматизируется") -> 40 | C18: 40 | E18: «Контроль» — формулы целостности перед импортом в кодовую базу.
A19: Дубликатов ID | B19: =COUNTIF('Реестр правил'!AI2:AI740,">1") -> 0 | C19: 0
A20: Открытых вопросов | B20: =COUNTIF('Решения QA'!F2:F445,"Открыт") -> 0 | C20: 0
A22: Контексты runtime-правил
A23: Контекст | B23: Правил
A24: Боевая ситуация | B24: =COUNTIF('Реестр правил'!$F$2:$F$740,A24) -> 264
A25: Болезни и состояния | B25: =COUNTIF('Реестр правил'!$F$2:$F$740,A25) -> 33
A26: Инвентарь и предметы | B26: =COUNTIF('Реестр правил'!$F$2:$F$740,A26) -> 4
A27: Кампания | B27: =COUNTIF('Реестр правил'!$F$2:$F$740,A27) -> 9
A28: Мастер и НПС | B28: =COUNTIF('Реестр правил'!$F$2:$F$740,A28) -> 18
A29: Отдых и дозор | B29: =COUNTIF('Реестр правил'!$F$2:$F$740,A29) -> 28
A30: Перемещение и карта | B30: =COUNTIF('Реестр правил'!$F$2:$F$740,A30) -> 13
A31: Симбионты | B31: =COUNTIF('Реестр правил'!$F$2:$F$740,A31) -> 89
A32: Смерть и мародерство | B32: =COUNTIF('Реестр правил'!$F$2:$F$740,A32) -> 4
A33: Создание персонажа | B33: =COUNTIF('Реестр правил'!$F$2:$F$740,A33) -> 277

Sheet Реестр правил
A1: № | B1: Rule ID | C1: Статус | D1: Режим реализации | E1: Тип правила | F1: Функциональный контекст | G1: Компонент приложения | H1: Нормативный раздел | I1: Подраздел | J1: Название | K1: Категория | L1: Логический актор | M1: Субъект | N1: Объект / цель | O1: Runtime-триггер | P1: Предусловия | Q1: Входы / параметры | R1: Итоговый алгоритм | S1: Изменения состояния / результат | T1: Исключения / приоритет | U1: Стоимость действия / времени | V1: Стоимость ресурсов | W1: Броски / формулы | X1: Недопустимый исход | Y1: Длительность / кулдаун | Z1: Ручной выбор мастера | AA1: Атомарность / аудит | AB1: Приоритет источника | AC1: Источник карточки | AD1: ID вопросов | AE1: Связанные правила | AF1: База + поздние дельты | AG1: QA-поля нормализованы | AH1: Финальная правка | AI1: Контроль уникальности ID
A2: 1 | B2: CORE-001 | C2: Активно | D2: Реализовать в игровом ядре | E2: Базовое правило | F2: Создание персонажа | G2: Персонажи | H2: 2. Персонаж, предметы и базовая механика | I2: Раса и класс | J2: Поправки Единого при создании | K2: раса / создание персонажа. | L2: Игрок / персонаж | M2: создаваемый персонаж расы Единый | N2: S, M, Z, C. | O2: выбор расы и способа выбора симбионтов. | P2: раса = Единый. | Q2: selectionMode ∈ {random, manual}, раса собеседника для C. | R2: random: S−=3, M−=6, Z−=6; manual: S−=7, M−=10, Z−=10; при проверке общения C_eff=C+5 против Единого, C_eff=C−15 против Чистого. | S2: постоянные расовые поправки; контекстный модификатор C. | T2: итоговые постоянные характеристики не ниже 1 по CORE-164; социальное разрешение проверки вне охвата. | W2: раса = Единый. random: S−=3, M−=6, Z−=6; manual: S−=7, M−=10, Z−=10; при проверке общения C_eff=C+5 против Единого, C_eff=C−15 против Чистого. | AB2: 10 | AC2: §3.2.6.1, стр. 48. | AE2: CORE-164 | AF2: Нет | AI2: =COUNTIF($B$2:$B$740,B2) -> 1
A3: 2 | B3: CORE-004 | C3: Активно | D3: Реализовать в игровом ядре | E3: Базовое правило | F3: Создание персонажа | G3: Персонажи | H3: 2. Персонаж, предметы и базовая механика | I3: Раса и класс | J3: Навык Единого «Идущий вслед за болью» | K3: раса / пассивный навык. | L3: Система / игровая сущность | M3: Единый | N3: проверки сопротивления пыткам и самообладания при горении. | O3: создание Единого; соответствующая проверка. | P3: раса = Единый, пассивный источник активен. | Q3: базовый результат проверки. | R3: навык добавляется автоматически, не занимает слот; к указанным проверкам +15. | S3: постоянный навык и модификатор. | T3: социальная механика пыток вне охвата; бонус к самообладанию при пожаре применяется по CORE-114. | W3: раса = Единый, пассивный источник активен. | AB3: 10 | AC3: §3.2.6.1.1, стр. 48. | AE3: CORE-114 | AF3: Нет | AI3: =COUNTIF($B$2:$B$740,B3) -> 1
A4: 3 | B4: CORE-005 | C4: Активно | D4: Реализовать в игровом ядре | E4: Базовое правило | F4: Создание персонажа | G4: Персонажи | H4: 2. Персонаж, предметы и базовая механика | I4: Раса и класс | J4: Слоты симбионтов Единого | K4: раса / симбионты. | L4: Система / игровая сущность | M4: Единый | N4: контейнер симбионтов. | O4: создание или изменение состава симбионтов. | P4: раса = Единый. | Q4: виды добавляемых симбионтов. | R4: вместимость = 4 слота; обычный симбионт занимает установленное его каталогом число слотов; «Симбиотическое чудовище» занимает все 4 и доступно только Единому. | S4: валидированный состав симбионтов. | T4: случайное получение чудовища — CORE-170. | W4: раса = Единый. вместимость = 4 слота; обычный симбионт занимает установленное его каталогом число слотов; «Симбиотическое чудовище» занимает все 4 и доступно только Единому. | AB4: 10 | AC4: §3.2.6.2, стр. 48. | AE4: CORE-170 | AF4: Нет | AI4: =COUNTIF($B$2:$B$740,B4) -> 1
A5: 4 | B5: CORE-006 | C5: Активно | D5: Реализовать в игровом ядре | E5: Базовое правило | F5: Создание персонажа | G5: Персонажи | H5: 2. Персонаж, предметы и базовая механика | I5: Раса и класс | J5: Поправки Вольного при создании | K5: раса / создание персонажа. | L5: Игрок / персонаж | M5: создаваемый Вольный | N5: S, M, Z. | O5: выбор способа выбора симбионта. | P5: раса = Вольный. | Q5: selectionMode. | R5: random: без расовой поправки; manual: S−=2, M−=2, Z−=2. | S5: постоянные расовые поправки. | T5: минимумы создания CORE-164. | W5: раса = Вольный. random: без расовой поправки; manual: S−=2, M−=2, Z−=2. | AB5: 10 | AC5: §3.3.6.1, стр. 55. | AE5: CORE-164 | AF5: Нет | AI5: =COUNTIF($B$2:$B$740,B5) -> 1
A6: 5 | B6: CORE-007 | C6: Активно | D6: Реализовать в игровом ядре | E6: Базовое правило | F6: Создание персонажа | G6: Персонажи | H6: 2. Персонаж, предметы и базовая механика | I6: Раса и класс | J6: Симбионт и опыт Вольного | K6: раса / симбионты. | L6: Система / игровая сущность | M6: Вольный | N6: симбионт и начисление его XP. | O6: создание; любое начисление XP симбионту. | P6: раса = Вольный. | Q6: awardSource=DIRECT_SYMBIONT|ALLOCATED_UNASSIGNED|PASSIVE_RULE|GM_DIRECT; baseXP; multiplierAlreadyApplied=false. | R6: Если XP фактически начисляется симбионту Вольного, применить multiplier=2 ровно один раз. Это включает прямое неизменяемое начисление мастером GM_DIRECT. Баллы symbiontXpProgressPoints и конвертация 3→1 не удваиваются и в GM_DIRECT не участвуют. | S6: directAward=baseXP×2; allocatedAward=allocatedUnits×2; gmDirectAward=baseXP×2; counterPoints и unallocatedSymbiontXp создаются только обычным игровым маршрутом в базовом размере. | T6: Не удваивать eventPoints до маршрутизации и не применять ×2 повторно после записи XP. | W6: effectiveSymbiontXP=baseXP×2; progressPointsMultiplier=1; conversionRate=3:1. | AA6: Записывать baseXP, awardSource, применённый multiplier и итог XP; один award — один множитель. GM_DIRECT дополнительно хранит мастера, обязательную причину и неизменяемый awardId. | AB6: 100 | AC6: §3.3.6.2, стр. 55. Прямое авторское решение Q-SYMBIONT-XP-001 — опыт симбионтов за natural 20/1, 2026-07-30 Q-GM-XP-001 — мастерское начисление XP, 2026-08-01 | AD6: Q-SYMBIONT-XP-001 Q-GM-XP-001 | AE6: CORE-171 CORE-230 CORE-231 CORE-232 SYM-021 SYM-055 | AF6: Нет | AG6: Да | AH6: Патч v1.7 (GM_DIRECT) | AI6: =COUNTIF($B$2:$B$740,B6) -> 1
A7: 6 | B7: CORE-009 | C7: Активно | D7: Реализовать в игровом ядре | E7: Базовое правило | F7: Создание персонажа | G7: Персонажи | H7: 2. Персонаж, предметы и базовая механика | I7: Раса и класс | J7: Чистый Искатель | K7: класс / характеристики и пассив. | L7: Игрок / система | M7: Чистый Искатель | N7: характеристики и проверки. | O7: выбор класса; соответствующая проверка. | P7: раса Чистый, класс Искатель. | Q7: базовые характеристики/проверка. | R7: Нормативная база (действует во всей непротиворечащей части): S+2, D+2, I+7, Z+5; контекстно C+5 с Чистыми, C−15 с Едиными; автоматически навык «Искатель Последнего Рассвета» (1 слот); +5 к изучению, поиску закономерности, крафту, ремонту, изобретательству, первой помощи, медицинским манипуляциям, выживанию в дикой природе и упреждающему удару. Приоритетные авторские дельты (заменяют только прямо пересекающиеся ветви): [Обязательная правка] Эта формулировка имеет приоритет над исходным текстом карточки. Бонус к «Крафту» хранится в листе персонажа, но приложение не предоставляет runtime-действие создания предмета по Q-CORE-059. | S7: постоянные поправки и навык. | T7: разрешение небоевых/социальных действий вне охвата; боевые модификаторы применяются. Поздние дельты применяются по приоритету AQ3 > AQ2 > AQA/CQA > базовая карточка; локальное исключение сильнее общего. | U7: Нормативная база (действует во всей непротиворечащей части): Бонус к «Крафту» хранится в листе персонажа, но приложение не предоставляет runtime-действие создания предмета по Q-CORE-059. разрешение небоевых/социальных действий вне охвата; боевые модификаторы применяются. | W7: [Обязательная правка] Эта формулировка имеет приоритет над исходным текстом карточки. | Y7: Нормативная база (действует во всей непротиворечащей части): | AB7: 10 | AC7: §3.4.7.1, стр. 65. | AE7: CORE-059 | AF7: Нет | AI7: =COUNTIF($B$2:$B$740,B7) -> 1
A8: 7 | B8: CORE-010 | C8: Активно | D8: Реализовать в игровом ядре | E8: Базовое правило | F8: Создание персонажа | G8: Персонажи | H8: 2. Персонаж, предметы и базовая механика | I8: Раса и класс | J8: Чистый Сталкер: характеристики и пассив | K8: класс / характеристики и пассив. | L8: Система / игровая сущность | M8: Чистый Сталкер. | O8: выбор класса; соответствующая проверка/экипировка. | P8: раса Чистый, класс Сталкер. | Q8: проверка, тип оружия/доспеха. | R8: S+2, D+5, M+5, Z+5; C+5 с Чистыми, C−10 с Едиными; навык «Сталкер Последнего Рассвета» занимает 1 слот и даёт +4 к прокладыванию маршрута, выслеживанию, обнаружению, скрытности, выживанию, осмотру, молниеносной реакции, уклонению, освобождению из пут; бесштрафное владение Кенси/Эривел/Эстрефорд/Айнцберн и Цесмором. | S8: постоянные поправки, бонусы и исключение штрафов владения. | T8: небоевые проверки хранятся как параметры, их разрешение вне охвата. | U8: C+5 с Чистыми, C−10 с Едиными; навык «Сталкер Последнего Рассвета» занимает 1 слот и даёт +4 к прокладыванию маршрута, выслеживанию, обнаружению, скрытности, выживанию, осмотру, молниеносной реакции, уклонению, освобождению из пут; бесштрафное владение Кенси/Эривел/Эстрефорд/Айнцберн и Цесмором. | AB8: 10 | AC8: §3.4.7.2.1–3.4.7.2.2, стр. 65. | AF8: Нет | AI8: =COUNTIF($B$2:$B$740,B8) -> 1
A9: 8 | B9: CORE-013 | C9: Активно | D9: Реализовать в игровом ядре | E9: Базовое правило | F9: Создание персонажа | G9: Персонажи | H9: 2. Персонаж, предметы и базовая механика | I9: Раса и класс | J9: Чистый Солдат | K9: класс / характеристики и пассив. | L9: Система / игровая сущность | M9: Чистый Солдат. | O9: выбор класса; соответствующее боевое действие. | P9: раса Чистый, класс Солдат. | Q9: проверка, оружие/броня, смена цели. | R9: S+5, D+2, M+5, Z+5; C+5 с Чистыми, C−20 с Едиными; навык «Солдат Последнего Рассвета» занимает 1 слот и даёт +3 к точности ударов руками/ногами, борьбе, точности одноручного/полуторного меча, блокированию и точности ударов щитом; бесштрафны Кастелькросс/Цесмор/Гленхейм, Корнадора/Бларадэ, Кенси/Эривел/Эстрефорд/Айнцберн; смена цели ближней атаки не расходует действие. | S9: постоянные поправки и боевые исключения. | T9: необходимое перемещение к новой цели оплачивается обычными действиями. | U9: выбор класса; соответствующее боевое действие. C+5 с Чистыми, C−20 с Едиными; навык «Солдат Последнего Рассвета» занимает 1 слот и даёт +3 к точности ударов руками/ногами, борьбе, точности одноручного/полуторного меча, блокированию и точности ударов щитом; бесштрафны Кастелькросс/Цесмор/Гленхейм, Корнадора/Бларадэ, Кенси/Эривел/Эстрефорд/Айнцберн; смена цели ближней атаки не расходует действие. необходимое перемещение к новой цели оплачивается обычными действиями. | AB9: 10 | AC9: §3.4.7.3, стр. 65–66. | AF9: Нет | AI9: =COUNTIF($B$2:$B$740,B9) -> 1
A10: 9 | B10: CORE-015 | C10: Не автоматизируется | D10: Не реализовывать в Windows-приложении | E10: Базовое правило | F10: Создание персонажа | G10: Персонажи | H10: 2. Персонаж, предметы и базовая механика | I10: Общие правила предметов и крафта | J10: Время, ресурсы и успех крафта | K10: предмет / крафт. | L10: Система / игровая сущность | M10: изготовитель | N10: материалы и время. | O10: подтверждение начала работы. | P10: требуемые материалы и инструменты доступны. | Q10: W изготовителя, отдельный срок из описания (если есть). | R10: Нормативная база (действует во всей непротиворечащей части): по умолчанию craftHours=max(1,50−W); материалы списать атомарно в начале; отдельной проверки успешности нет; по окончании создать предмет с параметрами CORE-014. Приоритетные авторские дельты (заменяют только прямо пересекающиеся ветви): [Исключение из реализации] Карточка сохранена как tombstone и не исполняется приложением. крафт как игровое действие исключён Q-CORE-059 | S10: материалы потрачены, таймер, затем предмет. | T10: иной явно заданный срок имеет приоритет. Поздние дельты применяются по приоритету AQ3 > AQ2 > AQA/CQA > базовая карточка; локальное исключение сильнее общего. Прямое уточнение 2026-07-28 не восстанавливает изготовление, время, материалы или проверку Крафта. | U10: Нормативная база (действует во всей непротиворечащей части): крафт как игровое действие исключён Q-CORE-059 | V10: требуемые материалы и инструменты доступны. по умолчанию craftHours=max(1,50−W); материалы списать атомарно в начале; отдельной проверки успешности нет; по окончании создать предмет с параметрами CORE-014. материалы потрачены, таймер, затем предмет. | W10: по умолчанию craftHours=max(1,50−W); материалы списать атомарно в начале; отдельной проверки успешности нет; по окончании создать предмет с параметрами CORE-014. | Y10: W изготовителя, отдельный срок из описания (если есть). Нормативная база (действует во всей непротиворечащей части): иной явно заданный срок имеет приоритет. | AA10: по умолчанию craftHours=max(1,50−W); материалы списать атомарно в начале; отдельной проверки успешности нет; по окончании создать предмет с параметрами CORE-014. | AB10: 60 | AC10: §4.1, стр. 67. Прямое уточнение пользователя 2026-07-28 | AD10: Q-CORE-059 | AE10: CORE-014 CORE-183 CORE-185 | AF10: Да | AH10: Патч v1.2 | AI10: =COUNTIF($B$2:$B$740,B10) -> 1
A11: 10 | B11: CORE-017 | C11: Активно | D11: Реализовать в игровом ядре | E11: Базовое правило | F11: Создание персонажа | G11: Персонажи | H11: 2. Персонаж, предметы и базовая механика | I11: Общие правила предметов и крафта | J11: Специальные серии ударов оружием | K11: оружие / стоимость действия. | L11: Система / игровая сущность | M11: атакующий | N11: оружие с двумя или тремя ударами. | O11: заявление специальной атаки. | P11: выполнен требуемый уровень навыка. | Q11: число ударов свойства, доступные действия, цели. | R11: формулировка «два/три удара за один ход» = одна особая атака за 1 боевое действие, не чаще 1 раза за личный ход; каждый удар полностью разрешается отдельно. Формулировка «за одно боевое действие» без «раз за ход» доступна за каждое имеющееся действие. | S11: списано действие, отдельно списаны боеприпасы/разрешены попадания. | T11: Кенси и парные кинжалы/кастеты используют лимит раз за ход. | U11: число ударов свойства, доступные действия, цели. формулировка «два/три удара за один ход» = одна особая атака за 1 боевое действие, не чаще 1 раза за личный ход; каждый удар полностью разрешается отдельно. Формулировка «за одно боевое действие» без «раз за ход» доступна за каждое имеющееся действие. списано действие, отдельно списаны боеприпасы/разрешены попадания. | W11: формулировка «два/три удара за один ход» = одна особая атака за 1 боевое действие, не чаще 1 раза за личный ход; каждый удар полностью разрешается отдельно. Формулировка «за одно боевое действие» без «раз за ход» доступна за каждое имеющееся действие. | Y11: формулировка «два/три удара за один ход» = одна особая атака за 1 боевое действие, не чаще 1 раза за личный ход; каждый удар полностью разрешается отдельно. Формулировка «за одно боевое действие» без «раз за ход» доступна за каждое имеющееся действие. Кенси и парные кинжалы/кастеты используют лимит раз за ход. | AB11: 10 | AC11: таблицы §4.2 и §4.4, стр. 69, 74, 76. | AF11: Нет | AI11: =COUNTIF($B$2:$B$740,B11) -> 1
A12: 11 | B12: CORE-018 | C12: Активно | D12: Реализовать в игровом ядре | E12: Базовое правило | F12: Создание персонажа | G12: Персонажи | H12: 2. Персонаж, предметы и базовая механика | I12: Общие правила предметов и крафта | J12: Общая работа щита | K12: щит / защита и прочность. | L12: Система / игровая сущность | M12: владелец щита | N12: щит. | O12: успешный блок щитом. | P12: щит в руках, HP щита >0. | Q12: обычный урон остановленной атаки, текущий HP щита. | R12: атака не достигает носителя; определить обычный урон атаки без отдельного спасброска брони щита; shieldHP=max(0,shieldHP−damage); избыточный урон при разрушении не переносить на носителя; при 0 HP щит уничтожен и не даёт бонусов до ремонта. | S12: изменена прочность/состояние щита. | T12: пассивная броня носителя не проверяется, поскольку атака его не достигает. | V12: щит в руках, HP щита >0. обычный урон остановленной атаки, текущий HP щита. атака не достигает носителя; определить обычный урон атаки без отдельного спасброска брони щита; shieldHP=max(0,shieldHP−damage); избыточный урон при разрушении не переносить на носителя; при 0 HP щит уничтожен и не даёт бонусов до ремонта. | W12: атака не достигает носителя; определить обычный урон атаки без отдельного спасброска брони щита; shieldHP=max(0,shieldHP−damage); избыточный урон при разрушении не переносить на носителя; при 0 HP щит уничтожен и не даёт бонусов до ремонта. | AB12: 10 | AC12: §4.4, стр. 77–80. | AF12: Нет | AI12: =COUNTIF($B$2:$B$740,B12) -> 1
A13: 12 | B13: CORE-019 | C13: Активно | D13: Реализовать в игровом ядре | E13: Базовое правило | F13: Создание персонажа | G13: Персонажи | H13: 2. Персонаж, предметы и базовая механика | I13: Общие правила предметов и крафта | J13: Владение щитом | K13: щит / модификаторы. | L13: Система / игровая сущность | M13: пользователь щита | N13: атака и блок. | O13: удар щитом или блок. | P13: щит в руках. | Q13: наличие/бонус навыка «Владение щитом», бонус щита. | R13: при навыке прибавить его бонус к атаке/блоку; без навыка применить −5 к атаке и один общий −5 к проверке блока; постоянный +3 самого щита сохраняется, отдельный −3 не добавлять. | S13: итоговая проверка. | T13: «Солдат Последнего Рассвета» добавляется там, где прямо указан. | AB13: 10 | AC13: §4.4, стр. 77–80; §6.2, стр. 106. | AF13: Нет | AI13: =COUNTIF($B$2:$B$740,B13) -> 1
A14: 13 | B14: CORE-021 | C14: Активно | D14: Реализовать в игровом ядре | E14: Базовое правило | F14: Создание персонажа | G14: Персонажи | H14: 2. Персонаж, предметы и базовая механика | I14: Каталог оружия | J14: Лёгкий арбалет | K14: оружие / арбалет. | L14: Система / игровая сущность | M14: изготовитель и стрелок | N14: экземпляр лёгкого арбалета. | O14: создание; выстрел; перезарядка. | P14: для бесштрафной точности — «Стрельба» либо классовый навык Сталкера/Солдата. | Q14: независимые дайсы, L,Lw; параметры пользователя. | R14: при создании: Dm=R12+L; затем Rn=R12+Dm+L; затем Rs=ceil(Dm×Rn/(R20+3×Lw)), минимум 1; затем Rd=ceil(2×Rn/Lw), минимум 1. На каждом выстреле Pr=R12, урон = созданный Dm, предел дальности = Rn; перезарядка = 1 боевое действие. Без указанного владения −5 к точности. | S14: созданные параметры; при выстреле разряжен, после действия снова заряжен. | T14: общие требования/стрельба/броня CORE-016, CORE-126, CORE-150. Формула создания используется только для точной проверки достижимости готового профиля игрока по CORE-185; крафт не автоматизируется. Боевые выражения активного профиля разрешаются по CORE-189. | U14: На каждом выстреле Pr=R12, урон = созданный Dm, предел дальности = Rn; перезарядка = 1 боевое действие. созданные параметры; при выстреле разряжен, после действия снова заряжен. | W14: при создании: Dm=R12+L; затем Rn=R12+Dm+L; затем Rs=ceil(Dm×Rn/(R20+3×Lw)), минимум 1; затем Rd=ceil(2×Rn/Lw), минимум 1. На каждом выстреле Pr=R12, урон = созданный Dm, предел дальности = Rn; перезарядка = 1 боевое действие. FORMULA_MODE=VALIDATION_ONLY; generationEnabled=false. Производственные дайсы не бросаются. | AB14: 60 | AC14: §4.2, таблица 1, стр. 68. Прямое уточнение пользователя 2026-07-28 | AE14: CORE-016 CORE-126 CORE-150 CORE-183 CORE-184 CORE-185 CORE-189 | AF14: Да | AH14: Патч v1.2 | AI14: =COUNTIF($B$2:$B$740,B14) -> 1
A15: 14 | B15: CORE-022 | C15: Активно | D15: Реализовать в игровом ядре | E15: Базовое правило | F15: Создание персонажа | G15: Персонажи | H15: 2. Персонаж, предметы и базовая механика | I15: Каталог оружия | J15: Тяжёлый арбалет | K15: оружие / арбалет. | L15: Система / игровая сущность | M15: изготовитель и стрелок | N15: тяжёлый арбалет. | O15: создание; выстрел; перезарядка. | P15: «Стрельба» или классовый навык Сталкера/Солдата для отсутствия штрафа. | Q15: независимые дайсы, L,Lw. | R15: Dm=R20+L; Rn=R12+Dm+L; Rs=ceil(Dm×Rn/(R20+2×Lw)), минимум 1; Rd=ceil(2×Rn/Lw), минимум 1; на выстреле Pr=R20, урон = Dm; перезарядка 1 действие; без владения −5 к точности. | S15: фиксированные Dm/Rn/Rs/Rd, динамическое пробитие и заряженность. | T15: общие правила стрельбы. Формула создания используется только для точной проверки достижимости готового профиля игрока по CORE-185; крафт не автоматизируется. Боевые выражения активного профиля разрешаются по CORE-189. | U15: Rd=ceil(2×Rn/Lw), минимум 1; на выстреле Pr=R20, урон = Dm; перезарядка 1 действие; без владения −5 к точности. | W15: Dm=R20+L Rn=R12+Dm+L Rs=ceil(Dm×Rn/(R20+2×Lw)), минимум 1 Rd=ceil(2×Rn/Lw), минимум 1; на выстреле Pr=R20, урон = Dm; перезарядка 1 действие; без владения −5 к точности. FORMULA_MODE=VALIDATION_ONLY; generationEnabled=false. Производственные дайсы не бросаются. | AB15: 60 | AC15: §4.2, таблица 1, стр. 69. Прямое уточнение пользователя 2026-07-28 | AE15: CORE-183 CORE-184 CORE-185 CORE-189 | AF15: Да | AH15: Патч v1.2 | AI15: =COUNTIF($B$2:$B$740,B15) -> 1
A16: 15 | B16: CORE-023 | C16: Активно | D16: Реализовать в игровом ядре | E16: Базовое правило | F16: Создание персонажа | G16: Персонажи | H16: 2. Персонаж, предметы и базовая механика | I16: Каталог оружия | J16: Кенси | K16: оружие / заводской арбалет. | L16: Система / игровая сущность | M16: стрелок | N16: Кенси. | O16: экипировка; выстрел; замена магазина. | P16: S≥8,D≥19; для отсутствия специального штрафа — навык Сталкера/Солдата. | Q16: магазин, цель, навык «Стрельба». | R16: имеет канонический шаблон, фиксированный для заявки игрока; мастер может изменить конкретный экземпляр по CORE-187/CORE-188. Вне такого override оружие создаётся только на конвейерной линии оружейного завода Кенси: магазин 8 болтов, дальность 20 м, урон 10, Pr=R12 на выстрел; замена магазина = 1 действие; без классового навыка −15 к точности. При «Стрельбе» высокого уровня можно один раз за личный ход за 1 действие выстрелить из двух Кенси (каждый выстрел отдельно); с совершенного уровня каждому назначается собственная цель. | S16: расход по 1 болту с каждого использованного арбалета; попадания разрешены независимо. | T16: особая серия CORE-017. PLAYER_REQUEST=TEMPLATE_FIXED: игрок не меняет характеристики оружия Чистых. MASTER_OVERRIDE конкретного экземпляра разрешён по CORE-187/CORE-188 и не изменяет глобальный шаблон. | U16: всегда имеет фиксированные параметры и создаётся только на конвейерной линии оружейного завода Кенси: магазин 8 болтов, дальность 20 м, урон 10, Pr=R12 на выстрел; замена магазина = 1 действие; без классового навыка −15 к точности. При «Стрельбе» высокого уровня можно один раз за личный ход за 1 действие выстрелить из двух Кенси (каждый выстрел отдельно); с совершенного уровня каждому назначается собственная цель. | W16: всегда имеет фиксированные параметры и создаётся только на конвейерной линии оружейного завода Кенси: магазин 8 болтов, дальность 20 м, урон 10, Pr=R12 на выстрел; замена магазина = 1 действие; без классового навыка −15 к точности. | Y16: При «Стрельбе» высокого уровня можно один раз за личный ход за 1 действие выстрелить из двух Кенси (каждый выстрел отдельно); с совершенного уровня каждому назначается собственная цель. | AA16: При «Стрельбе» высокого уровня можно один раз за личный ход за 1 действие выстрелить из двух Кенси (каждый выстрел отдельно); с совершенного уровня каждому назначается собственная цель. | AB16: 60 | AC16: §4.2, таблица 1, стр. 69. Прямое уточнение пользователя 2026-07-28 | AE16: CORE-017 CORE-186 CORE-187 CORE-188 CORE-189 CORE-190 | AF16: Да | AH16: Патч v1.2 | AI16: =COUNTIF($B$2:$B$740,B16) -> 1
A17: 16 | B17: CORE-024 | C17: Активно | D17: Реализовать в игровом ядре | E17: Базовое правило | F17: Создание персонажа | G17: Персонажи | H17: 2. Персонаж, предметы и базовая механика | I17: Каталог оружия | J17: Эривел | K17: оружие / заводской арбалет. | L17: Система / игровая сущность | M17: стрелок | N17: Эривел. | O17: выстрел или замена магазина. | P17: S≥16,D≥12; классовый навык Сталкера/Солдата для отсутствия −15. | Q17: магазин, отдельные R20 пробития и урона. | R17: имеет канонический шаблон, фиксированный для заявки игрока; мастер может изменить конкретный экземпляр по CORE-187/CORE-188. Вне такого override оружие создаётся только на конвейерной линии оружейного завода Эривела: магазин 4 болта; замена = 1 действие; дальность 30 м; на каждом выстреле Pr=R20, damage=2×R20; без классового навыка −15 к точности. | S17: расход 1 болта; динамические Pr/damage. | T17: каждый символ дайса независим. PLAYER_REQUEST=TEMPLATE_FIXED: игрок не меняет характеристики оружия Чистых. MASTER_OVERRIDE конкретного экземпляра разрешён по CORE-187/CORE-188 и не изменяет глобальный шаблон. | U17: всегда имеет фиксированные параметры и создаётся только на конвейерной линии оружейного завода Эривела: магазин 4 болта; замена = 1 действие; дальность 30 м; на каждом выстреле Pr=R20, damage=2×R20; без классового навыка −15 к точности. | W17: магазин, отдельные R20 пробития и урона. всегда имеет фиксированные параметры и создаётся только на конвейерной линии оружейного завода Эривела: магазин 4 болта; замена = 1 действие; дальность 30 м; на каждом выстреле Pr=R20, damage=2×R20; без классового навыка −15 к точности. | AB17: 60 | AC17: §4.2, таблица 1, стр. 69. Прямое уточнение пользователя 2026-07-28 | AE17: CORE-186 CORE-187 CORE-188 CORE-189 CORE-190 | AF17: Да | AH17: Патч v1.2 | AI17: =COUNTIF($B$2:$B$740,B17) -> 1
A18: 17 | B18: CORE-025 | C18: Активно | D18: Реализовать в игровом ядре | E18: Базовое правило | F18: Создание персонажа | G18: Персонажи | H18: 2. Персонаж, предметы и базовая механика | I18: Каталог оружия | J18: Эстрефорд | K18: оружие / заводской арбалет. | L18: Система / игровая сущность | M18: стрелок | N18: Эстрефорд. | O18: выстрел/перезарядка. | P18: S≥19,D≥14; классовый навык Сталкера/Солдата для отсутствия −15. | Q18: заряженность, цель. | R18: имеет канонический шаблон, фиксированный для заявки игрока; мастер может изменить конкретный экземпляр по CORE-187/CORE-188. Вне такого override оружие создаётся только на конвейерной линии оружейного завода Эстрефорда: дальность 30 м, Pr=16, damage=30, перезарядка 1 действие; без классового навыка −15 к точности. | S18: после выстрела разряжен. | T18: общие правила. PLAYER_REQUEST=TEMPLATE_FIXED: игрок не меняет характеристики оружия Чистых. MASTER_OVERRIDE конкретного экземпляра разрешён по CORE-187/CORE-188 и не изменяет глобальный шаблон. | U18: всегда имеет фиксированные параметры и создаётся только на конвейерной линии оружейного завода Эстрефорда: дальность 30 м, Pr=16, damage=30, перезарядка 1 действие; без классового навыка −15 к точности. | W18: всегда имеет фиксированные параметры и создаётся только на конвейерной линии оружейного завода Эстрефорда: дальность 30 м, Pr=16, damage=30, перезарядка 1 действие; без классового навыка −15 к точности. | AB18: 60 | AC18: §4.2, таблица 1, стр. 70. Прямое уточнение пользователя 2026-07-28 | AE18: CORE-186 CORE-187 CORE-188 CORE-189 CORE-190 | AF18: Да | AH18: Патч v1.2 | AI18: =COUNTIF($B$2:$B$740,B18) -> 1
A19: 18 | B19: CORE-032 | C19: Активно | D19: Реализовать в игровом ядре | E19: Базовое правило | F19: Создание персонажа | G19: Персонажи | H19: 2. Персонаж, предметы и базовая механика | I19: Каталог оружия | J19: Одноручный меч | K19: оружие / ближний бой. | L19: Система / игровая сущность | M19: изготовитель и атакующий | N19: одноручный меч. | O19: создание; атака. | P19: «Фехтование» либо −5. | Q19: L,Lw,Ls, S,D, дайсы атаки. | R19: Rs=max(9,ceil((80−(Lw+Ls)/2)/(R6+L))); Rd по той же формуле и минимуму; точность D, урон S, навык «Фехтование»; Pr=R12, базовый damage=R20. | S19: обычная оружейная атака. | T19: CORE-020. Формула создания используется только для точной проверки достижимости готового профиля игрока по CORE-185; крафт не автоматизируется. Боевые выражения активного профиля разрешаются по CORE-189. | W19: Rs=max(9,ceil((80−(Lw+Ls)/2)/(R6+L))) Rd по той же формуле и минимуму; точность D, урон S, навык «Фехтование» Pr=R12, базовый damage=R20. FORMULA_MODE=VALIDATION_ONLY; generationEnabled=false. Производственные дайсы не бросаются. | AB19: 60 | AC19: §4.4, таблица 3, стр. 73. Прямое уточнение пользователя 2026-07-28 | AE19: CORE-020 CORE-183 CORE-184 CORE-185 CORE-189 | AF19: Да | AH19: Патч v1.2 | AI19: =COUNTIF($B$2:$B$740,B19) -> 1
A20: 19 | B20: CORE-034 | C20: Активно | D20: Реализовать в игровом ядре | E20: Базовое правило | F20: Создание персонажа | G20: Персонажи | H20: 2. Персонаж, предметы и базовая механика | I20: Каталог оружия | J20: Двуручный меч | K20: оружие / ближний бой. | L20: Система / игровая сущность | M20: изготовитель и атакующий | N20: двуручный меч. | O20: создание; атака/метание. | P20: «Фехтование» либо −5. | Q20: L,Lw,Ls. | R20: Rs=max(12,ceil((100−(Lw+Ls)/2)/(R4+L))); Rd=max(9,ceil((80−(Lw+Ls)/2)/(R6+L))); Pr=R20+5, базовый damage=R20+5; S — урон, D — точность; при метании дополнительный −10 к проверкам метания. | S20: обычная атака. | T20: штрафы метания CORE-128/CORE-129 складываются. Формула создания используется только для точной проверки достижимости готового профиля игрока по CORE-185; крафт не автоматизируется. Боевые выражения активного профиля разрешаются по CORE-189. | W20: Rs=max(12,ceil((100−(Lw+Ls)/2)/(R4+L))) Rd=max(9,ceil((80−(Lw+Ls)/2)/(R6+L))) Pr=R20+5, базовый damage=R20+5 FORMULA_MODE=VALIDATION_ONLY; generationEnabled=false. Производственные дайсы не бросаются. | AB20: 60 | AC20: §4.4, таблица 3, стр. 74. Прямое уточнение пользователя 2026-07-28 | AE20: CORE-128 CORE-129 CORE-183 CORE-184 CORE-185 CORE-189 | AF20: Да | AH20: Патч v1.2 | AI20: =COUNTIF($B$2:$B$740,B20) -> 1
A21: 20 | B21: CORE-035 | C21: Активно | D21: Реализовать в игровом ядре | E21: Базовое правило | F21: Создание персонажа | G21: Персонажи | H21: 2. Персонаж, предметы и базовая механика | I21: Каталог оружия | J21: Шпага | K21: оружие / ближний бой. | L21: Система / игровая сущность | M21: изготовитель и атакующий | N21: шпага. | O21: создание; атака/парирование/метание. | P21: «Фехтование» либо −5. | Q21: L,Lw,Ls, D. | R21: Rs=max(5,ceil((50−(Lw+Ls)/2)/(R6+L))); Rd=max(12,ceil((100−(Lw+Ls)/2)/(R4+L))); +5 к парированию; Pr=R12, базовый damage=R12; D модифицирует точность и урон; метание получает −10. | S21: атака или защитный бонус. | T21: парирование CORE-147. Формула создания используется только для точной проверки достижимости готового профиля игрока по CORE-185; крафт не автоматизируется. Боевые выражения активного профиля разрешаются по CORE-189. | W21: Rs=max(5,ceil((50−(Lw+Ls)/2)/(R6+L))) Rd=max(12,ceil((100−(Lw+Ls)/2)/(R4+L))); +5 к парированию Pr=R12, базовый damage=R12 FORMULA_MODE=VALIDATION_ONLY; generationEnabled=false. Производственные дайсы не бросаются. | AB21: 60 | AC21: §4.4, таблица 3, стр. 74. Прямое уточнение пользователя 2026-07-28 | AE21: CORE-147 CORE-183 CORE-184 CORE-185 CORE-189 | AF21: Да | AH21: Патч v1.2 | AI21: =COUNTIF($B$2:$B$740,B21) -> 1
A22: 21 | B22: CORE-036 | C22: Активно | D22: Реализовать в игровом ядре | E22: Базовое правило | F22: Создание персонажа | G22: Персонажи | H22: 2. Персонаж, предметы и базовая механика | I22: Каталог оружия | J22: Копьё | K22: оружие / ближний бой. | L22: Система / игровая сущность | M22: изготовитель и атакующий | N22: копьё. | O22: создание; атака/упреждение. | P22: «Владение копьём» либо −2. | Q22: L,Lw,Ls, S,D. | R22: Rs=max(7,ceil((70−(Lw+Ls)/2)/(R6+L))); Rd=max(6,ceil((70−(Lw+Ls)/2)/(R6+L))); +3 к проверке упреждающего удара; Pr=R12, базовый damage=R12; D точность, S урон. | S22: атака/защитный бонус. | T22: упреждающий удар CORE-148. Формула создания используется только для точной проверки достижимости готового профиля игрока по CORE-185; крафт не автоматизируется. Боевые выражения активного профиля разрешаются по CORE-189. | W22: Rs=max(7,ceil((70−(Lw+Ls)/2)/(R6+L))) Rd=max(6,ceil((70−(Lw+Ls)/2)/(R6+L))); +3 к проверке упреждающего удара Pr=R12, базовый damage=R12 FORMULA_MODE=VALIDATION_ONLY; generationEnabled=false. Производственные дайсы не бросаются. | AB22: 60 | AC22: §4.4, таблица 3, стр. 74. Прямое уточнение пользователя 2026-07-28 | AE22: CORE-148 CORE-183 CORE-184 CORE-185 CORE-189 | AF22: Да | AH22: Патч v1.2 | AI22: =COUNTIF($B$2:$B$740,B22) -> 1
A23: 22 | B23: CORE-042 | C23: Активно | D23: Реализовать в игровом ядре | E23: Базовое правило | F23: Создание персонажа | G23: Персонажи | H23: 2. Персонаж, предметы и базовая механика | I23: Каталог оружия | J23: Кастет | K23: оружие / рукопашный бой. | L23: Система / игровая сущность | M23: изготовитель и атакующий | N23: кастет. | O23: создание; атака/метание. | P23: навык «Рукопашный бой» для специальной серии; без навыка применяется общий штраф рукопашного боя. | Q23: L,Lw,Ls, S,D, уровень навыка. | R23: Rs=max(9,ceil((60−(Lw+Ls)/2)/(R4+L))); Rd=max(12,ceil((80−(Lw+Ls)/2)/(R4+L))); Pr=R6, базовый damage=R6; S урон, D точность; высокий навык — два удара за одно действие не чаще раза за ход, абсолютный — добавить удар ногой без пробития; метание −10. | S23: до трёх независимо разрешаемых ударов. | T23: специальная серия CORE-017; обычные удары рукой/ногой CORE-136. Формула создания используется только для точной проверки достижимости готового профиля игрока по CORE-185; крафт не автоматизируется. Боевые выражения активного профиля разрешаются по CORE-189. | U23: S урон, D точность; высокий навык — два удара за одно действие не чаще раза за ход, абсолютный — добавить удар ногой без пробития; метание −10. | W23: Rs=max(9,ceil((60−(Lw+Ls)/2)/(R4+L))) Rd=max(12,ceil((80−(Lw+Ls)/2)/(R4+L))) Pr=R6, базовый damage=R6 FORMULA_MODE=VALIDATION_ONLY; generationEnabled=false. Производственные дайсы не бросаются. | Y23: S урон, D точность; высокий навык — два удара за одно действие не чаще раза за ход, абсолютный — добавить удар ногой без пробития; метание −10. | AB23: 60 | AC23: §4.4, таблица 3, стр. 76. Прямое уточнение пользователя 2026-07-28 | AE23: CORE-017 CORE-136 CORE-183 CORE-184 CORE-185 CORE-189 | AF23: Да | AH23: Патч v1.2 | AI23: =COUNTIF($B$2:$B$740,B23) -> 1
A24: 23 | B24: CORE-049 | C24: Активно | D24: Реализовать в игровом ядре | E24: Базовое правило | F24: Создание персонажа | G24: Персонажи | H24: 2. Персонаж, предметы и базовая механика | I24: Доспехи | J24: Кожаный доспех | K24: броня / элемент. | L24: Игрок / персонаж | M24: носитель | N24: элемент кожаного доспеха. | O24: экипировка; попадание в закрытую зону. | P24: на каждый элемент требуется S=2. | Q24: закрытая зона, R6 брони. | R24: Нормативная база (действует во всей непротиворечащей части): каждый слой/элемент даёт R6 к общей броне зоны; шлем не закрывает лицо и не даёт иммунитет к болевым приёмам на лице/выдавливанию глаз. Приоритетные авторские дельты (заменяют только прямо пересекающиеся ветви): [Обязательная правка] Эта формулировка имеет приоритет над исходным текстом карточки. удалить неисполняемую оговорку о выдавливании глаз; оставить защиту лица/болевых приёмов | S24: слой брони зоны. | T24: наслаивание CORE-151. Поздние дельты применяются по приоритету AQ3 > AQ2 > AQA/CQA > базовая карточка; локальное исключение сильнее общего. | U24: Нормативная база (действует во всей непротиворечащей части): | W24: на каждый элемент требуется S=2. закрытая зона, R6 брони. каждый слой/элемент даёт R6 к общей броне зоны; шлем не закрывает лицо и не даёт иммунитет к болевым приёмам на лице/выдавливанию глаз. [Обязательная правка] Эта формулировка имеет приоритет над исходным текстом карточки. | Y24: Нормативная база (действует во всей непротиворечащей части): | AB24: 10 | AC24: §4.5, таблица 4, стр. 81. | AE24: CORE-151 | AF24: Нет | AI24: =COUNTIF($B$2:$B$740,B24) -> 1
A25: 24 | B25: CORE-052 | C25: Активно | D25: Реализовать в игровом ядре | E25: Базовое правило | F25: Создание персонажа | G25: Персонажи | H25: 2. Персонаж, предметы и базовая механика | I25: Доспехи | J25: Латы | K25: броня / элементы. | L25: Игрок / персонаж | M25: носитель | N25: латы. | O25: экипировка, попадание, удушение, бег/акробатика. | P25: S=4 за элемент. | Q25: зоны и число элементов. | R25: каждый слой зоны armor+=R20; голова+корпус дают иммунитет к удушающему приёму; −2 к бегу/акробатике за элемент; если элементов >2, M−=5 один раз. | S25: броня, штрафы, иммунитет. | T25: наслаивание CORE-151. | W25: S=4 за элемент. каждый слой зоны armor+=R20; голова+корпус дают иммунитет к удушающему приёму; −2 к бегу/акробатике за элемент; если элементов >2, M−=5 один раз. | AA25: каждый слой зоны armor+=R20; голова+корпус дают иммунитет к удушающему приёму; −2 к бегу/акробатике за элемент; если элементов >2, M−=5 один раз. | AB25: 10 | AC25: §4.5, таблица 4, стр. 82. | AE25: CORE-151 | AF25: Нет | AI25: =COUNTIF($B$2:$B$740,B25) -> 1
A26: 25 | B26: CORE-054 | C26: Активно | D26: Реализовать в игровом ядре | E26: Базовое правило | F26: Создание персонажа | G26: Персонажи | H26: 2. Персонаж, предметы и базовая механика | I26: Доспехи | J26: Кастелькросс | K26: броня / цельный костюм. | L26: Игрок / персонаж | M26: носитель | N26: Кастелькросс. | O26: экипировка, попадание, псионика, перемещение. | P26: S≥20; цельный; без «Солдата Последнего Рассвета» −15 к перемещениям. | Q26: R20 брони, вид воздействия. | R26: armor=R20; псионический урон уменьшить на 5 и к встречным проверкам против псионического контроля/чтения/иллюзий +5; иммунитет к удушающему приёму; −6 к бегу/акробатике; M−=3; псионическая защита не защищает от химических феромонов. | S26: броня/сопротивление/штрафы. | T26: конкретная способность может устанавливать иммунитет или не действовать при любой защите. | W26: R20 брони, вид воздействия. armor=R20; псионический урон уменьшить на 5 и к встречным проверкам против псионического контроля/чтения/иллюзий +5; иммунитет к удушающему приёму; −6 к бегу/акробатике M−=3; псионическая защита не защищает от химических феромонов. | AB26: 10 | AC26: §4.5, таблица 4, стр. 82; §5.4.3.6, стр. 97–98. | AF26: Нет | AI26: =COUNTIF($B$2:$B$740,B26) -> 1
A27: 26 | B27: CORE-055 | C27: Активно | D27: Реализовать в игровом ядре | E27: Базовое правило | F27: Создание персонажа | G27: Персонажи | H27: 2. Персонаж, предметы и базовая механика | I27: Доспехи | J27: Цесмор | K27: броня / цельный костюм. | L27: Игрок / персонаж | M27: носитель | N27: Цесмор. | O27: экипировка, попадание, перемещение. | P27: S≥14; цельный; без навыка Сталкера/Солдата −15 к перемещениям. | Q27: R20 брони. | R27: закрытые зоны получают armor=R20; применить специальный штраф при отсутствии класса. | S27: броня и модификатор движения. | T27: классы CORE-010/013 отменяют специальный штраф. | W27: R20 брони. закрытые зоны получают armor=R20; применить специальный штраф при отсутствии класса. | AB27: 10 | AC27: §4.5, таблица 4, стр. 82. | AE27: CORE-010 | AF27: Нет | AI27: =COUNTIF($B$2:$B$740,B27) -> 1
A28: 27 | B28: CORE-056 | C28: Активно | D28: Реализовать в игровом ядре | E28: Базовое правило | F28: Создание персонажа | G28: Персонажи | H28: 2. Персонаж, предметы и базовая механика | I28: Доспехи | J28: Гленхейм | K28: броня / цельный костюм. | L28: Игрок / персонаж | M28: носитель | N28: Гленхейм. | O28: экипировка, попадание, движение, попытка борьбы. | P28: S≥24; цельный; без «Солдата Последнего Рассвета» −15 к перемещениям. | Q28: один R20 брони. | R28: armor=2×R20+5; −12 к бегу/акробатике, −6 к уклонению, M−=5; «фиксированный ход суставов» даёт иммунитет к попыткам травмирующего и удушающего приёма. | S28: высокая броня, штрафы, иммунитеты. | T28: обычная травма от пробившей атаки не отменяется. | W28: один R20 брони. armor=2×R20+5; −12 к бегу/акробатике, −6 к уклонению, M−=5; «фиксированный ход суставов» даёт иммунитет к попыткам травмирующего и удушающего приёма. | Y28: armor=2×R20+5; −12 к бегу/акробатике, −6 к уклонению, M−=5; «фиксированный ход суставов» даёт иммунитет к попыткам травмирующего и удушающего приёма. | AB28: 10 | AC28: §4.5, таблица 4, стр. 83. | AF28: Нет | AI28: =COUNTIF($B$2:$B$740,B28) -> 1
A29: 28 | B29: CORE-060 | C29: Активно | D29: Реализовать в игровом ядре | E29: Базовое правило | F29: Создание персонажа | G29: Персонажи | H29: 2. Персонаж, предметы и базовая механика | I29: Фармацевтика | J29: Отвар, приводящий в сознание | K29: фармацевтика / реанимация. | L29: Система / игровая сущность | M29: цель | N29: тяжёлое ранение, сон, паралич. | O29: допустимый приём дозы. | P29: не более 3 доз за скользящие 24 часа. | Q29: состояния цели. | R29: снять тяжёлое ранение и установить HP=1; прекратить снотворное и паралитик без проверок; остановить таймер смерти. | S29: цель в сознании, HP 1 при реанимации. | T29: окончательную смерть не отменяет. | U29: не более 3 доз за скользящие 24 часа. | V29: допустимый приём дозы. не более 3 доз за скользящие 24 часа. снять тяжёлое ранение и установить HP=1; прекратить снотворное и паралитик без проверок; остановить таймер смерти. цель в сознании, HP 1 при реанимации. | W29: снять тяжёлое ранение и установить HP=1; прекратить снотворное и паралитик без проверок; остановить таймер смерти. | Y29: не более 3 доз за скользящие 24 часа. | AB29: 10 | AC29: §4.6, таблица 5, стр. 83–84; §5.5, стр. 104. | AF29: Нет | AI29: =COUNTIF($B$2:$B$740,B29) -> 1
A30: 29 | B30: CORE-064 | C30: Активно | D30: Реализовать в игровом ядре | E30: Базовое правило | F30: Создание персонажа | G30: Персонажи | H30: 2. Персонаж, предметы и базовая механика | I30: Фармацевтика | J30: Восстанавливающий отвар | K30: фармацевтика / лечение. | L30: Система / игровая сущность | M30: цель | N30: HP. | O30: допустимый приём. | P30: ≤2 доз/24ч; цель не в тяжёлом ранении либо эффект прямо выводит — здесь не выводит. | Q30: текущие/максимальные HP. | R30: HP=min(maxHP,HP+25). | S30: восстановление HP. | T30: не реанимирует CORE-156. | V30: ≤2 доз/24ч; цель не в тяжёлом ранении либо эффект прямо выводит — здесь не выводит. текущие/максимальные HP. HP=min(maxHP,HP+25). восстановление HP. | W30: HP=min(maxHP,HP+25). | AB30: 10 | AC30: §4.6, таблица 5, стр. 84. | AE30: CORE-156 | AF30: Нет | AI30: =COUNTIF($B$2:$B$740,B30) -> 1
A31: 30 | B31: CORE-066 | C31: Активно | D31: Реализовать в игровом ядре | E31: Базовое правило | F31: Создание персонажа | G31: Персонажи | H31: 2. Персонаж, предметы и базовая механика | I31: Фармацевтика | J31: Таблетка ночного зрения | K31: фармацевтика / восприятие. | L31: Система / игровая сущность | M31: Чистый | N31: зрение. | O31: приём. | P31: раса Чистый; ≤2 доз/24ч. | Q31: время. | R31: на 2 часа видеть в темноте как днём; повтор обновляет 2 часа. | S31: временный флаг зрения. | T31: числовые штрафы темноты в анализируемых разделах не заданы. | U31: на 2 часа видеть в темноте как днём; повтор обновляет 2 часа. | V31: раса Чистый; ≤2 доз/24ч. | Y31: на 2 часа видеть в темноте как днём; повтор обновляет 2 часа. | AB31: 10 | AC31: §4.6, таблица 5, стр. 84. | AF31: Нет | AI31: =COUNTIF($B$2:$B$740,B31) -> 1
A32: 31 | B32: CORE-067 | C32: Активно | D32: Реализовать в игровом ядре | E32: Базовое правило | F32: Создание персонажа | G32: Персонажи | H32: 2. Персонаж, предметы и базовая механика | I32: Фармацевтика | J32: Таблетка бритвенных рефлексов | K32: фармацевтика / бой. | L32: Система / игровая сущность | M32: Чистый | N32: уклонение и парирование. | O32: приём. | P32: раса Чистый; ≤3 доз/24ч. | Q32: независимый R20 длительности. | R32: длительность max(1,round_math(R20/3)) личных ходов; на срок +3 к уклонению и парированию; повтор не складывает, обновляет срок. | S32: временный эффект. | T32: общая длительность CORE-101. | V32: раса Чистый; ≤3 доз/24ч. | W32: независимый R20 длительности. длительность max(1,round_math(R20/3)) личных ходов; на срок +3 к уклонению и парированию; повтор не складывает, обновляет срок. | Y32: длительность max(1,round_math(R20/3)) личных ходов; на срок +3 к уклонению и парированию; повтор не складывает, обновляет срок. | AB32: 10 | AC32: §4.6, таблица 5, стр. 84. | AE32: CORE-101 | AF32: Нет | AI32: =COUNTIF($B$2:$B$740,B32) -> 1
A33: 32 | B33: CORE-070 | C33: Активно | D33: Реализовать в игровом ядре | E33: Базовое правило | F33: Создание персонажа | G33: Персонажи | H33: 2. Персонаж, предметы и базовая механика | I33: Фармацевтика | J33: Таблетка куража | K33: фармацевтика / серия. | L33: Система / игровая сущность | M33: Чистый | N33: серия приёмов. | O33: приём в существующей боевой ситуации. | P33: раса Чистый; ≤4 доз/24ч. | Q33: текущий бой. | R33: seriesBonus=+1 до конца боя; если первая доза принята в собственный текущий ход после расчёта серии, немедленно увеличить combatActionsRemaining на 1; повтор не увеличивает бонус/остаток, лишь обновляет эффект (практически до того же конца боя). | S33: +1 боевое действие в текущем и каждом следующем личном ходу этого боя. | T33: может увеличить серию выше 5. | U33: +1 боевое действие в текущем и каждом следующем личном ходу этого боя. | V33: раса Чистый; ≤4 доз/24ч. seriesBonus=+1 до конца боя; если первая доза принята в собственный текущий ход после расчёта серии, немедленно увеличить combatActionsRemaining на 1; повтор не увеличивает бонус/остаток, лишь обновляет эффект (практически до того же конца боя). | W33: seriesBonus=+1 до конца боя; если первая доза принята в собственный текущий ход после расчёта серии, немедленно увеличить combatActionsRemaining на 1; повтор не увеличивает бонус/остаток, лишь обновляет эффект (практически до того же конца боя). | Y33: seriesBonus=+1 до конца боя; если первая доза принята в собственный текущий ход после расчёта серии, немедленно увеличить combatActionsRemaining на 1; повтор не увеличивает бонус/остаток, лишь обновляет эффект (практически до того же конца боя). +1 боевое действие в текущем и каждом следующем личном ходу этого боя. | AB33: 10 | AC33: §4.6, таблица 5, стр. 84. | AF33: Нет | AI33: =COUNTIF($B$2:$B$740,B33) -> 1
A34: 33 | B34: CORE-071 | C34: Активно | D34: Реализовать в игровом ядре | E34: Базовое правило | F34: Создание персонажа | G34: Персонажи | H34: 2. Персонаж, предметы и базовая механика | I34: Фармацевтика | J34: Восстанавливающая таблетка | K34: фармацевтика / периодическое лечение. | L34: Система / игровая сущность | M34: Чистый | N34: HP. | O34: приём; конец каждого личного хода цели. | P34: раса Чистый; ≤5 доз/24ч; существующий бой. | Q34: HP/maxHP. | R34: до конца боя в конце каждого хода HP=min(maxHP,HP+5); повтор не складывает. | S34: периодический эффект. | T34: обычное лечение не действует в тяжёлом ранении. | V34: раса Чистый; ≤5 доз/24ч; существующий бой. HP/maxHP. до конца боя в конце каждого хода HP=min(maxHP,HP+5); повтор не складывает. | W34: до конца боя в конце каждого хода HP=min(maxHP,HP+5); повтор не складывает. | Y34: приём; конец каждого личного хода цели. до конца боя в конце каждого хода HP=min(maxHP,HP+5); повтор не складывает. | AB34: 10 | AC34: §4.6, таблица 5, стр. 84; §5.4.2.5, стр. 95. | AF34: Нет | AI34: =COUNTIF($B$2:$B$740,B34) -> 1
A35: 34 | B35: CORE-073 | C35: Активно | D35: Реализовать в игровом ядре | E35: Базовое правило | F35: Создание персонажа | G35: Персонажи | H35: 2. Персонаж, предметы и базовая механика | I35: Базовые проверки, значения и критичность | J35: Проверка характеристики | K35: базовая механика / проверка. | L35: Мастер / игрок / система | M35: действующий персонаж | N35: заявленное действие. | O35: мастер назначил проверку. | P35: игрок до броска заявил намерение и способ; мастер назвал характеристику, навык, сложность и очевидные последствия провала. | Q35: R20, значение характеристики, применимые навыки/эффекты. [Боевой override] combat.active, allowCritical, rawFace, criticalPolarity, criticalGrade и снимок разрешённых модификаторов. originRollId, rollSource, dieType, rawFace, rollKind, actorType. | R35: Сначала зафиксировать ordinaryTotal=R20+characteristic+allowedModifiers. Если combat.active=true и проверка допускает критичность, сырая грань R20 проходит CORE-082–084 и CORE-229 до сравнения с difficulty: подтверждённый критический успех автоматически успешно разрешает текущую проверку независимо от ordinaryTotal; подтверждённый критический провал автоматически проваливает её. При grade=0 применяется обычное result≥difficulty. Вне боевой ситуации действует прежнее математическое сравнение; критическая градация сама по себе не меняет обычный исход. После фиксации исходной натуральной грани передать оригинальный D20 в CORE-230; итог формулы 1/20 без rawFace не является событием прогрессии. | S35: finalCheckSuccess, ordinaryTotal, criticalPolarity, criticalGrade и причина разрешения. Создаётся не более одного symbiontXpEvent на originRollId. | T35: чистые проверки CORE-074; критическая процедура CORE-082–CORE-085. Боевой override применяется только к допускающей критичность проверке по CORE-229; исключённые виды бросков CORE-074/082 остаются исключёнными. Manual и Auto используют одну серверную ветвь; броски подтверждения и подстановки исключены. | W35: R20, значение характеристики, применимые навыки/эффекты. result=R20+characteristic+allowedModifiers; против фиксированной сложности result≥difficulty = успех. | X35: Шкала по умолчанию: 10 простое, 15 обычное, 20 трудное, 25 очень трудное, 30 исключительное, 35 почти невозможное; мастер может назначить иное. В бою сначала сравнить ordinaryTotal с difficulty и из-за этого не запустить подтверждение натуральной 20/1. | AB35: 100 | AC35: §5.1, стр. 85–86. Прямое уточнение пользователя 2026-07-29 — боевой приоритет критов Прямое авторское решение Q-SYMBIONT-XP-001 — опыт симбионтов за natural 20/1, 2026-07-30 | AD35: Q-COMBAT-CRIT-001 Q-SYMBIONT-XP-001 | AE35: CORE-074 CORE-082 CORE-085 CORE-229 CORE-083 CORE-084 CORE-230 | AF35: Да | AG35: Да | AH35: Патч v1.6 (опыт симбионтов) | AI35: =COUNTIF($B$2:$B$740,B35) -> 1
A36: 35 | B36: CORE-074 | C36: Активно | D36: Реализовать в игровом ядре | E36: Базовое правило | F36: Создание персонажа | G36: Персонажи | H36: 2. Персонаж, предметы и базовая механика | I36: Базовые проверки, значения и критичность | J36: Чистый результат и чистая проверка | K36: базовая механика / тип броска. | L36: Система / игровая сущность | M36: любой бросающий | N36: результат. | O36: правило требует «чистый» бросок/результат. | P36: нет. | Q36: дайс, явно записанные фиксированные числа/множители. | R36: чистый результат = грань дайса до модификаторов; чистая проверка не прибавляет характеристику/навык, но сохраняет числа и множители формулы (R20+5 остаётся чистой). Чистый математический итог не создаёт прогрессию; только rawFace оригинального D20 передаётся CORE-230. | S36: числовой результат. | T36: броски урона/пробития/брони/длительности/зоны/таблиц не являются проверками действия без прямого указания. Формульное значение 1 или 20 не заменяет натуральную грань. | U36: броски урона/пробития/брони/длительности/зоны/таблиц не являются проверками действия без прямого указания. | W36: чистый результат = грань дайса до модификаторов; чистая проверка не прибавляет характеристику/навык, но сохраняет числа и множители формулы (R20+5 остаётся чистой). | AA36: Сохранять rawFace отдельно от ordinaryTotal. | AB36: 100 | AC36: §5.1, стр. 86. Прямое авторское решение Q-SYMBIONT-XP-001 — опыт симбионтов за natural 20/1, 2026-07-30 | AD36: Q-SYMBIONT-XP-001 | AE36: CORE-230 | AF36: Нет | AG36: Да | AH36: Патч v1.6 (опыт симбионтов) | AI36: =COUNTIF($B$2:$B$740,B36) -> 1
A37: 36 | B37: CORE-075 | C37: Активно | D37: Реализовать в игровом ядре | E37: Базовое правило | F37: Создание персонажа | G37: Персонажи | H37: 2. Персонаж, предметы и базовая механика | I37: Базовые проверки, значения и критичность | J37: Встречная проверка и равенство | K37: базовая механика / сравнение. | L37: Система / игровая сущность | M37: инициатор и противодействующая цель. | O37: действие требует превысить результат цели. | P37: цель может и желает выполнять встречную проверку. | Q37: ordinaryTotal и снимок модификаторов каждой стороны; rawFace, criticalPolarity и criticalGrade каждой стороны; DefenseChoice. originRollId и собственная rawFace каждого участника. | R37: Вне боевой ситуации изменение по-прежнему происходит только при строгом initiatorTotal>opponentTotal; равенство сохраняет положение. В боевой встречной проверке сначала применить CORE-229. Порядок: (1) единственный подтверждённый критический успех выигрывает текущую проверку независимо от итогов и критического провала другой стороны; (2) при двух критических успехах сравниваются только градации; (3) при равных положительных градациях без нового броска пересчитать оба ordinaryTotal из исходных снимков так, как если бы rawFace каждой стороны был равен 20, criticalGrade=0 и подтверждения не было, затем применить строгое сравнение, причём равенство сохраняет защиту/status quo; (4) если положительных критов нет, проверка с подтверждённым критическим провалом автоматически провалена; при критическом провале обеих сторон обе проверки провалены и инициирующее изменение не происходит; (5) если подтверждённых критов нет, применяется обычное строгое сравнение. DefenseChoice=NONE разрешается по CORE-217. Прогрессия определяется отдельно по собственной грани участника до выбора победителя; проигрыш встречной проверки событие не отменяет. | S37: winner=INITIATOR|OPPONENT|STATUS_QUO, resolutionMode, ordinaryTotals, criticalGrades. | T37: конкретное правило может задать фиксированную сложность/автоматический успех. Локальный прямой автоматический исход конкретной способности сильнее общего порядка; SYM-066 отражает допустимую атаку независимо от её критичности. | U37: действие требует превысить результат цели. | W37: equalPositiveGrade: replayRoll=false; comparisonFaceInitiator=20; comparisonFaceOpponent=20; затем initiatorTotal>opponentTotal. | X37: Если цель не выполняет встречную проверку, её броска нет; атака попадает после остальных условий, пассивная броня остаётся. Сравнить обычные суммы раньше критических градаций; выполнить новый бросок при равных градациях; объявить успешной проверку с подтверждённым критическим провалом. | AA37: Не объединять originRollId противостоящих сторон. | AB37: 100 | AC37: §5.1, стр. 86; §5.4.6, стр. 102. Предразработочный QA и прямые ответы пользователя 2026-07-29 Прямое уточнение пользователя 2026-07-29 — боевой приоритет критов Прямое авторское решение Q-SYMBIONT-XP-001 — опыт симбионтов за natural 20/1, 2026-07-30 | AD37: Q-PREDEV-002 Q-COMBAT-CRIT-001 Q-SYMBIONT-XP-001 | AE37: CORE-217 CORE-229 SYM-066 CORE-230 | AF37: Да | AG37: Да | AH37: Патч v1.6 (опыт симбионтов) | AI37: =COUNTIF($B$2:$B$740,B37) -> 1
A38: 37 | B38: CORE-076 | C38: Активно | D38: Реализовать в игровом ядре | E38: Базовое правило | F38: Создание персонажа | G38: Персонажи | H38: 2. Персонаж, предметы и базовая механика | I38: Базовые проверки, значения и критичность | J38: Общие правила округления и нижних границ | K38: вычисления. | L38: Система / игровая сущность | M38: любая формула. | O38: формула даёт дробный/отрицательный результат. | P38: свой способ округления не указан. | Q38: конечный результат формулы. | R38: округлять только конечный результат математически (<.5 вниз, ≥.5 вверх); положительная длительность/число ходов/действий/целей/объектов после деления минимум 1; явно рассчитанные ≤0 расстояние, урон, штраф или бонус =0; проценты числа существ округлять вверх. | S38: нормализованное число. | T38: требования предметов всегда округляются вверх; формула, где эффект при ≤0 «не возникает», имеет приоритет. | U38: округлять только конечный результат математически (<.5 вниз, ≥.5 вверх); положительная длительность/число ходов/действий/целей/объектов после деления минимум 1; явно рассчитанные ≤0 расстояние, урон, штраф или бонус =0; проценты числа существ округлять вверх. | W38: формула даёт дробный/отрицательный результат. конечный результат формулы. округлять только конечный результат математически (<.5 вниз, ≥.5 вверх); положительная длительность/число ходов/действий/целей/объектов после деления минимум 1; явно рассчитанные ≤0 расстояние, урон, штраф или бонус =0; проценты числа существ округлять вверх. требования предметов всегда округляются вверх; формула, где эффект при ≤0 «не возникает», имеет приоритет. | X38: требования предметов всегда округляются вверх; формула, где эффект при ≤0 «не возникает», имеет приоритет. | Y38: округлять только конечный результат математически (<.5 вниз, ≥.5 вверх); положительная длительность/число ходов/действий/целей/объектов после деления минимум 1; явно рассчитанные ≤0 расстояние, урон, штраф или бонус =0; проценты числа существ округлять вверх. | AB38: 10 | AC38: §5.1, стр. 86. | AF38: Нет | AI38: =COUNTIF($B$2:$B$740,B38) -> 1
